<?xml version="1.0" encoding="utf-8"?>
<!-- =================================================================================== -->
<!-- |    This document was autogenerated by xacro from ouzel_base.xacro               | -->
<!-- |    EDITING THIS FILE BY HAND IS NOT RECOMMENDED                                 | -->
<!-- =================================================================================== -->
<!--
  Copyright 2015 Fadri Furrer, ASL, ETH Zurich, Switzerland
  Copyright 2015 Michael Burri, ASL, ETH Zurich, Switzerland
  Copyright 2015 Mina Kamel, ASL, ETH Zurich, Switzerland
  Copyright 2015 Janosch Nikolic, ASL, ETH Zurich, Switzerland
  Copyright 2015 Markus Achtelik, ASL, ETH Zurich, Switzerland

  Licensed under the Apache License, Version 2.0 (the "License");
  you may not use this file except in compliance with the License.
  You may obtain a copy of the License at

  http://www.apache.org/licenses/LICENSE-2.0

  Unless required by applicable law or agreed to in writing, software
  distributed under the License is distributed on an "AS IS" BASIS,
  WITHOUT WARRANTIES OR CONDITIONS OF ANY KIND, either express or implied.
  See the License for the specific language governing permissions and
  limitations under the License.
-->
<robot name="ouzel">
  <!-- =============================================================== -->
  <!-- ==================== ROS INTERFACE MACRO ====================== -->
  <!-- =============================================================== -->
  <!-- <xacro:macro 
      name="ros_interface_plugin_macro"
      params="namespace">
    <gazebo>
      <plugin name="ros_interface_plugin" filename="librotors_gazebo_ros_interface_plugin.so">
        <robotNamespace>${namespace}</robotNamespace>
      </plugin>
    </gazebo>
  </xacro:macro>-->

  <link name="ouzel/base_link"/>
  <joint name="ouzel/base_joint" type="fixed">
    <origin rpy="0 0 0" xyz="0 0 0"/>
    <parent link="ouzel/base_link"/>
    <child link="ouzel/base_link_inertia"/>
  </joint>
  <link name="ouzel/base_link_inertia">
    <inertial>
      <mass value="3.13"/>
      <!-- [kg] -->
      <origin xyz="0.00 0 0.0"/>
      <inertia ixx="0.0075" ixy="-3.4208e-05" ixz="2.4695e-05" iyy="0.010939" iyz="-3.8826e-06" izz="0.01369"/>
    </inertial>
    <visual>
      <origin rpy="0 0 0" xyz="0 0 0"/>
      <geometry>
        <mesh filename="ouzel_inspection.stl" scale="1 1 1"/>
      </geometry>
    </visual>
    <collision>
      <origin rpy="0 0 0" xyz="0 0 0"/>
      <geometry>
        <box size="0.22 0.22 0.45"/>
        <!-- [m] [m] [m] -->
      </geometry>
      <material name="">
                <contact name="omav"/>
      </material>
    </collision>
  </link>
  <!-- attach multirotor_base_plugin to the base_link -->
<!--   <gazebo>
    <plugin filename="librotors_gazebo_multirotor_base_plugin.so" name="multirotor_base_plugin">
      <robotNamespace>ouzel</robotNamespace>
      <linkName>ouzel/base_link</linkName>
      <rotorVelocitySlowdownSim>10</rotorVelocitySlowdownSim>
    </plugin>
  </gazebo> -->
  <!-- Rotor tilt_unit -->
  <joint name="ouzel/tilt_unit_0_revolutejoint" type="revolute">
    <origin rpy="0 0 4.71238898038" xyz="0 -0.3 0"/>
    <axis xyz="1 0 0"/>
    <parent link="ouzel/base_link"/>
    <child link="ouzel/tilt_unit_0"/>
  </joint>
  <link name="ouzel/tilt_unit_0">
    <inertial>
      <mass value="0.277"/>
      <!-- [kg] -->
      <inertia ixx="0.00034257" ixy="0" ixz="0" iyy="0.0013205" iyz="0" izz="0.0010037"/>
      <!-- [kg m^2] [kg m^2] [kg m^2] [kg m^2] [kg m^2] [kg m^2] -->
    </inertial>
    <visual>
      <geometry>
        <mesh filename="omav_tiltarm.dae" scale="1 1 1"/>
      </geometry>
    </visual>
    <collision>
      <geometry>
        <box size="0.005 0.005 0.005"/>
        <!-- [m] -->
      </geometry>
    </collision>
  </link>
  <!-- <gazebo>
    <plugin filename="librotors_gazebo_motor_model.so" name="right_tilt_unit_model">
      <robotNamespace>ouzel</robotNamespace>
      <jointName>ouzel/tilt_unit_0_revolutejoint</jointName>
      <linkName>ouzel/tilt_unit_0</linkName>
      <turningDirection>ccw</turningDirection>
      <motorType>position</motorType>
      <commandSubTopic>/gazebo/command/motor_speed</commandSubTopic>
      <motorNumber>12</motorNumber>
      <motorSpeedPubTopic>/tilt_motor_0/velocity</motorSpeedPubTopic>
      <motorPositionPubTopic>/tilt_motor_0/position</motorPositionPubTopic>
      <joint_control_pid>
        <p>0.11</p>
        <i>0.0</i>
        <d>0.01</d>
        <iMax>1.0</iMax>
        <iMin>-1.0</iMin>
        <cmdMax>2.0</cmdMax>
        <cmdMin>-2.0</cmdMin>
      </joint_control_pid>
    </plugin>
  </gazebo> -->
<!--   <gazebo reference="ouzel/tilt_unit_0">
    <material>Gazebo/White</material>
  </gazebo> -->
  <!-- Upper Rotor -->
  <joint name="rotor_0_joint" type="continuous">
    <origin rpy="0 0 0" xyz="0 0 0.06"/>
    <axis xyz="0 0 1"/>
    <parent link="ouzel/tilt_unit_0"/>
    <child link="rotor_0"/>
  </joint>
  <link name="rotor_0">
    <inertial>
      <mass value="0.0065"/>
      <!-- [kg] -->
      <inertia ixx="2.2154157805e-06" ixy="0.0" ixz="0.0" iyy="7.08147091741e-05" iyz="0.0" izz="7.29326249936e-05"/>
    </inertial>
    <visual>
      <geometry>
        <mesh filename="propeller_ccw.dae" scale="0.1143 0.1143 0.1143"/>
      </geometry>
    </visual>
    <collision>
      <geometry>
        <cylinder length="0.005" radius="0.1143"/>
        <!-- [m] -->
      </geometry>
    </collision>
  </link>
<!--   <gazebo>
    <plugin filename="librotors_gazebo_motor_model.so" name="right_upper_motor_model">
      <robotNamespace>ouzel</robotNamespace>
      <jointName>rotor_0_joint</jointName>
      <linkName>rotor_0</linkName>
      <turningDirection>ccw</turningDirection>
      <timeConstantUp>0.0125</timeConstantUp>
      <timeConstantDown>0.025</timeConstantDown>
      <maxRotVelocity>1700</maxRotVelocity>
      <motorConstant>7.2e-06</motorConstant>
      <momentConstant>0.015</momentConstant>
      <commandSubTopic>/gazebo/command/motor_speed</commandSubTopic>
      <motorNumber>0</motorNumber>
      <rotorDragCoefficient>8.06428e-05</rotorDragCoefficient>
      <rollingMomentCoefficient>1e-06</rollingMomentCoefficient>
      <motorSpeedPubTopic>/motor_speed/0_upper</motorSpeedPubTopic>
      <rotorVelocitySlowdownSim>10</rotorVelocitySlowdownSim>
    </plugin>
  </gazebo> -->
<!--   <gazebo reference="rotor_0">
    <material>Gazebo/Black</material>
  </gazebo> -->
  <!-- Lower Rotor -->
  <joint name="rotor_6_joint" type="continuous">
    <origin rpy="0 0 0" xyz="0 0 -0.06"/>
    <axis xyz="0 0 1"/>
    <parent link="ouzel/tilt_unit_0"/>
    <child link="rotor_6"/>
  </joint>
  <link name="rotor_6">
    <inertial>
      <mass value="0.0065"/>
      <!-- [kg] -->
      <inertia ixx="2.2154157805e-06" ixy="0.0" ixz="0.0" iyy="7.08147091741e-05" iyz="0.0" izz="7.29326249936e-05"/>
    </inertial>
    <visual>
      <geometry>
        <mesh filename="propeller_cw.dae" scale="0.1143 0.1143 0.1143"/>
      </geometry>
    </visual>
    <collision>
      <geometry>
        <cylinder length="0.005" radius="0.1143"/>
        <!-- [m] -->
      </geometry>
    </collision>
  </link>
  <!--   <gazebo>
    <plugin filename="librotors_gazebo_motor_model.so" name="right_lower_motor_model">
      <robotNamespace>ouzel</robotNamespace>
      <jointName>rotor_6_joint</jointName>
      <linkName>rotor_6</linkName>
      <turningDirection>cw</turningDirection>
      <timeConstantUp>0.0125</timeConstantUp>
      <timeConstantDown>0.025</timeConstantDown>
      <maxRotVelocity>1700</maxRotVelocity>
      <motorConstant>7.2e-06</motorConstant>
      <momentConstant>0.005</momentConstant>
      <commandSubTopic>/gazebo/command/motor_speed</commandSubTopic>
      <motorNumber>6</motorNumber>
      <rotorDragCoefficient>8.06428e-05</rotorDragCoefficient>
      <rollingMomentCoefficient>1e-06</rollingMomentCoefficient>
      <motorSpeedPubTopic>/motor_speed/0_lower</motorSpeedPubTopic>
      <rotorVelocitySlowdownSim>10</rotorVelocitySlowdownSim>
    </plugin>
  </gazebo>
  <gazebo reference="rotor_6">
    <material>Gazebo/Black</material>
  </gazebo> -->
  <!-- Rotor tilt_unit -->
  <joint name="ouzel/tilt_unit_1_revolutejoint" type="continuous">
    <origin rpy="0 0 1.57079632679" xyz="0 0.3 0"/>
    <axis xyz="1 0 0"/>
    <parent link="ouzel/base_link"/>
    <child link="ouzel/tilt_unit_1"/>
  </joint>
  <link name="ouzel/tilt_unit_1">
    <inertial>
      <mass value="0.277"/>
      <!-- [kg] -->
      <inertia ixx="0.00034257" ixy="0" ixz="0" iyy="0.0013205" iyz="0" izz="0.0010037"/>
      <!-- [kg m^2] [kg m^2] [kg m^2] [kg m^2] [kg m^2] [kg m^2] -->
    </inertial>
    <visual>
      <geometry>
        <mesh filename="omav_tiltarm.dae" scale="1 1 1"/>
      </geometry>
    </visual>
    <collision>
      <geometry>
        <box size="0.005 0.005 0.005"/>
        <!-- [m] -->
      </geometry>
    </collision>
  </link>
  <!-- <gazebo>
    <plugin filename="librotors_gazebo_motor_model.so" name="left_tilt_unit_model">
      <robotNamespace>ouzel</robotNamespace>
      <jointName>ouzel/tilt_unit_1_revolutejoint</jointName>
      <linkName>ouzel/tilt_unit_1</linkName>
      <turningDirection>ccw</turningDirection>
      <motorType>position</motorType>
      <commandSubTopic>/gazebo/command/motor_speed</commandSubTopic>
      <motorNumber>13</motorNumber>
      <motorSpeedPubTopic>/tilt_motor_1/velocity</motorSpeedPubTopic>
      <motorPositionPubTopic>/tilt_motor_1/position</motorPositionPubTopic>
      <joint_control_pid>
        <p>0.11</p>
        <i>0.0</i>
        <d>0.01</d>
        <iMax>1.0</iMax>
        <iMin>-1.0</iMin>
        <cmdMax>2.0</cmdMax>
        <cmdMin>-2.0</cmdMin>
      </joint_control_pid>
    </plugin>
  </gazebo>
  <gazebo reference="ouzel/tilt_unit_1">
    <material>Gazebo/White</material>
  </gazebo> -->
  <!-- Upper Rotor -->
  <joint name="rotor_1_joint" type="continuous">
    <origin rpy="0 0 0" xyz="0 0 0.06"/>
    <axis xyz="0 0 1"/>
    <parent link="ouzel/tilt_unit_1"/>
    <child link="rotor_1"/>
  </joint>
  <link name="rotor_1">
    <inertial>
      <mass value="0.0065"/>
      <!-- [kg] -->
      <inertia ixx="2.2154157805e-06" ixy="0.0" ixz="0.0" iyy="7.08147091741e-05" iyz="0.0" izz="7.29326249936e-05"/>
    </inertial>
    <visual>
      <geometry>
        <mesh filename="propeller_cw.dae" scale="0.1143 0.1143 0.1143"/>
      </geometry>
    </visual>
    <collision>
      <geometry>
        <cylinder length="0.005" radius="0.1143"/>
        <!-- [m] -->
      </geometry>
    </collision>
  </link>
  <!-- <gazebo>
    <plugin filename="librotors_gazebo_motor_model.so" name="left_upper_motor_model">
      <robotNamespace>ouzel</robotNamespace>
      <jointName>rotor_1_joint</jointName>
      <linkName>rotor_1</linkName>
      <turningDirection>cw</turningDirection>
      <timeConstantUp>0.0125</timeConstantUp>
      <timeConstantDown>0.025</timeConstantDown>
      <maxRotVelocity>1700</maxRotVelocity>
      <motorConstant>7.2e-06</motorConstant>
      <momentConstant>0.015</momentConstant>
      <commandSubTopic>/gazebo/command/motor_speed</commandSubTopic>
      <motorNumber>1</motorNumber>
      <rotorDragCoefficient>8.06428e-05</rotorDragCoefficient>
      <rollingMomentCoefficient>1e-06</rollingMomentCoefficient>
      <motorSpeedPubTopic>/motor_speed/1_upper</motorSpeedPubTopic>
      <rotorVelocitySlowdownSim>10</rotorVelocitySlowdownSim>
    </plugin>
  </gazebo>
  <gazebo reference="rotor_1">
    <material>Gazebo/Black</material>
  </gazebo> -->
  <!-- Lower Rotor -->
  <joint name="rotor_7_joint" type="continuous">
    <origin rpy="0 0 0" xyz="0 0 -0.06"/>
    <axis xyz="0 0 1"/>
    <parent link="ouzel/tilt_unit_1"/>
    <child link="rotor_7"/>
  </joint>
  <link name="rotor_7">
    <inertial>
      <mass value="0.0065"/>
      <!-- [kg] -->
      <inertia ixx="2.2154157805e-06" ixy="0.0" ixz="0.0" iyy="7.08147091741e-05" iyz="0.0" izz="7.29326249936e-05"/>
    </inertial>
    <visual>
      <geometry>
        <mesh filename="propeller_ccw.dae" scale="0.1143 0.1143 0.1143"/>
      </geometry>
    </visual>
    <collision>
      <geometry>
        <cylinder length="0.005" radius="0.1143"/>
        <!-- [m] -->
      </geometry>
    </collision>
  </link>
  <!-- <gazebo>
    <plugin filename="librotors_gazebo_motor_model.so" name="left_lower_motor_model">
      <robotNamespace>ouzel</robotNamespace>
      <jointName>rotor_7_joint</jointName>
      <linkName>rotor_7</linkName>
      <turningDirection>ccw</turningDirection>
      <timeConstantUp>0.0125</timeConstantUp>
      <timeConstantDown>0.025</timeConstantDown>
      <maxRotVelocity>1700</maxRotVelocity>
      <motorConstant>7.2e-06</motorConstant>
      <momentConstant>0.005</momentConstant>
      <commandSubTopic>/gazebo/command/motor_speed</commandSubTopic>
      <motorNumber>7</motorNumber>
      <rotorDragCoefficient>8.06428e-05</rotorDragCoefficient>
      <rollingMomentCoefficient>1e-06</rollingMomentCoefficient>
      <motorSpeedPubTopic>/motor_speed/1_lower</motorSpeedPubTopic>
      <rotorVelocitySlowdownSim>10</rotorVelocitySlowdownSim>
    </plugin>
  </gazebo>
  <gazebo reference="rotor_7">
    <material>Gazebo/Black</material>
  </gazebo> -->
  <!-- Rotor tilt_unit -->
  <joint name="ouzel/tilt_unit_2_revolutejoint" type="continuous">
    <origin rpy="0 0 0.52359877559" xyz="0.259807621135 0.15 0"/>
    <axis xyz="1 0 0"/>
    <parent link="ouzel/base_link"/>
    <child link="ouzel/tilt_unit_2"/>
  </joint>
  <link name="ouzel/tilt_unit_2">
    <inertial>
      <mass value="0.277"/>
      <!-- [kg] -->
      <inertia ixx="0.00034257" ixy="0" ixz="0" iyy="0.0013205" iyz="0" izz="0.0010037"/>
      <!-- [kg m^2] [kg m^2] [kg m^2] [kg m^2] [kg m^2] [kg m^2] -->
    </inertial>
    <visual>
      <geometry>
        <mesh filename="omav_tiltarm.dae" scale="1 1 1"/>
      </geometry>
    </visual>
    <collision>
      <geometry>
        <box size="0.005 0.005 0.005"/>
        <!-- [m] -->
      </geometry>
    </collision>
  </link>
  <!-- <gazebo>
    <plugin filename="librotors_gazebo_motor_model.so" name="front_left_tilt_unit_model">
      <robotNamespace>ouzel</robotNamespace>
      <jointName>ouzel/tilt_unit_2_revolutejoint</jointName>
      <linkName>ouzel/tilt_unit_2</linkName>
      <turningDirection>ccw</turningDirection>
      <motorType>position</motorType>
      <commandSubTopic>/gazebo/command/motor_speed</commandSubTopic>
      <motorNumber>14</motorNumber>
      <motorSpeedPubTopic>/tilt_motor_2/velocity</motorSpeedPubTopic>
      <motorPositionPubTopic>/tilt_motor_2/position</motorPositionPubTopic>
      <joint_control_pid>
        <p>0.11</p>
        <i>0.0</i>
        <d>0.01</d>
        <iMax>1.0</iMax>
        <iMin>-1.0</iMin>
        <cmdMax>2.0</cmdMax>
        <cmdMin>-2.0</cmdMin>
      </joint_control_pid>
    </plugin>
  </gazebo>
  <gazebo reference="ouzel/tilt_unit_2">
    <material>Gazebo/White</material>
  </gazebo> -->
  <!-- Upper Rotor -->
  <joint name="rotor_2_joint" type="continuous">
    <origin rpy="0 0 0" xyz="0 0 0.06"/>
    <axis xyz="0 0 1"/>
    <parent link="ouzel/tilt_unit_2"/>
    <child link="rotor_2"/>
  </joint>
  <link name="rotor_2">
    <inertial>
      <mass value="0.0065"/>
      <!-- [kg] -->
      <inertia ixx="2.2154157805e-06" ixy="0.0" ixz="0.0" iyy="7.08147091741e-05" iyz="0.0" izz="7.29326249936e-05"/>
    </inertial>
    <visual>
      <geometry>
        <mesh filename="propeller_ccw.dae" scale="0.1143 0.1143 0.1143"/>
      </geometry>
    </visual>
    <collision>
      <geometry>
        <cylinder length="0.005" radius="0.1143"/>
        <!-- [m] -->
      </geometry>
    </collision>
  </link>
  <!-- <gazebo>
    <plugin filename="librotors_gazebo_motor_model.so" name="front_left_upper_motor_model">
      <robotNamespace>ouzel</robotNamespace>
      <jointName>rotor_2_joint</jointName>
      <linkName>rotor_2</linkName>
      <turningDirection>ccw</turningDirection>
      <timeConstantUp>0.0125</timeConstantUp>
      <timeConstantDown>0.025</timeConstantDown>
      <maxRotVelocity>1700</maxRotVelocity>
      <motorConstant>7.2e-06</motorConstant>
      <momentConstant>0.015</momentConstant>
      <commandSubTopic>/gazebo/command/motor_speed</commandSubTopic>
      <motorNumber>2</motorNumber>
      <rotorDragCoefficient>8.06428e-05</rotorDragCoefficient>
      <rollingMomentCoefficient>1e-06</rollingMomentCoefficient>
      <motorSpeedPubTopic>/motor_speed/2_upper</motorSpeedPubTopic>
      <rotorVelocitySlowdownSim>10</rotorVelocitySlowdownSim>
    </plugin>
  </gazebo>
  <gazebo reference="rotor_2">
    <material>Gazebo/Orange</material>
  </gazebo> -->
  <!-- Lower Rotor -->
  <joint name="rotor_8_joint" type="continuous">
    <origin rpy="0 0 0" xyz="0 0 -0.06"/>
    <axis xyz="0 0 1"/>
    <parent link="ouzel/tilt_unit_2"/>
    <child link="rotor_8"/>
  </joint>
  <link name="rotor_8">
    <inertial>
      <mass value="0.0065"/>
      <!-- [kg] -->
      <inertia ixx="2.2154157805e-06" ixy="0.0" ixz="0.0" iyy="7.08147091741e-05" iyz="0.0" izz="7.29326249936e-05"/>
    </inertial>
    <visual>
      <geometry>
        <mesh filename="propeller_cw.dae" scale="0.1143 0.1143 0.1143"/>
      </geometry>
    </visual>
    <collision>
      <geometry>
        <cylinder length="0.005" radius="0.1143"/>
        <!-- [m] -->
      </geometry>
    </collision>
  </link>
  <!-- <gazebo>
    <plugin filename="librotors_gazebo_motor_model.so" name="front_left_lower_motor_model">
      <robotNamespace>ouzel</robotNamespace>
      <jointName>rotor_8_joint</jointName>
      <linkName>rotor_8</linkName>
      <turningDirection>cw</turningDirection>
      <timeConstantUp>0.0125</timeConstantUp>
      <timeConstantDown>0.025</timeConstantDown>
      <maxRotVelocity>1700</maxRotVelocity>
      <motorConstant>7.2e-06</motorConstant>
      <momentConstant>0.005</momentConstant>
      <commandSubTopic>/gazebo/command/motor_speed</commandSubTopic>
      <motorNumber>8</motorNumber>
      <rotorDragCoefficient>8.06428e-05</rotorDragCoefficient>
      <rollingMomentCoefficient>1e-06</rollingMomentCoefficient>
      <motorSpeedPubTopic>/motor_speed/2_lower</motorSpeedPubTopic>
      <rotorVelocitySlowdownSim>10</rotorVelocitySlowdownSim>
    </plugin>
  </gazebo>
  <gazebo reference="rotor_8">
    <material>Gazebo/Orange</material>
  </gazebo> -->
  <!-- Rotor tilt_unit -->
  <joint name="ouzel/tilt_unit_3_revolutejoint" type="continuous">
    <origin rpy="0 0 3.66519142919" xyz="-0.259807621135 -0.15 0"/>
    <axis xyz="1 0 0"/>
    <parent link="ouzel/base_link"/>
    <child link="ouzel/tilt_unit_3"/>
  </joint>
  <link name="ouzel/tilt_unit_3">
    <inertial>
      <mass value="0.277"/>
      <!-- [kg] -->
      <inertia ixx="0.00034257" ixy="0" ixz="0" iyy="0.0013205" iyz="0" izz="0.0010037"/>
      <!-- [kg m^2] [kg m^2] [kg m^2] [kg m^2] [kg m^2] [kg m^2] -->
    </inertial>
    <visual>
      <geometry>
        <mesh filename="omav_tiltarm.dae" scale="1 1 1"/>
      </geometry>
    </visual>
    <collision>
      <geometry>
        <box size="0.005 0.005 0.005"/>
        <!-- [m] -->
      </geometry>
    </collision>
  </link>
  <!-- <gazebo>
    <plugin filename="librotors_gazebo_motor_model.so" name="back_right_tilt_unit_model">
      <robotNamespace>ouzel</robotNamespace>
      <jointName>ouzel/tilt_unit_3_revolutejoint</jointName>
      <linkName>ouzel/tilt_unit_3</linkName>
      <turningDirection>ccw</turningDirection>
      <motorType>position</motorType>
      <commandSubTopic>/gazebo/command/motor_speed</commandSubTopic>
      <motorNumber>15</motorNumber>
      <motorSpeedPubTopic>/tilt_motor_3/velocity</motorSpeedPubTopic>
      <motorPositionPubTopic>/tilt_motor_3/position</motorPositionPubTopic>
      <joint_control_pid>
        <p>0.11</p>
        <i>0.0</i>
        <d>0.01</d>
        <iMax>1.0</iMax>
        <iMin>-1.0</iMin>
        <cmdMax>2.0</cmdMax>
        <cmdMin>-2.0</cmdMin>
      </joint_control_pid>
    </plugin>
  </gazebo>
  <gazebo reference="ouzel/tilt_unit_3">
    <material>Gazebo/White</material>
  </gazebo> -->
  <!-- Upper Rotor -->
  <joint name="rotor_3_joint" type="continuous">
    <origin rpy="0 0 0" xyz="0 0 0.06"/>
    <axis xyz="0 0 1"/>
    <parent link="ouzel/tilt_unit_3"/>
    <child link="rotor_3"/>
  </joint>
  <link name="rotor_3">
    <inertial>
      <mass value="0.0065"/>
      <!-- [kg] -->
      <inertia ixx="2.2154157805e-06" ixy="0.0" ixz="0.0" iyy="7.08147091741e-05" iyz="0.0" izz="7.29326249936e-05"/>
    </inertial>
    <visual>
      <geometry>
        <mesh filename="propeller_cw.dae" scale="0.1143 0.1143 0.1143"/>
      </geometry>
    </visual>
    <collision>
      <geometry>
        <cylinder length="0.005" radius="0.1143"/>
        <!-- [m] -->
      </geometry>
    </collision>
  </link>
  <!-- <gazebo>
    <plugin filename="librotors_gazebo_motor_model.so" name="back_right_upper_motor_model">
      <robotNamespace>ouzel</robotNamespace>
      <jointName>rotor_3_joint</jointName>
      <linkName>rotor_3</linkName>
      <turningDirection>cw</turningDirection>
      <timeConstantUp>0.0125</timeConstantUp>
      <timeConstantDown>0.025</timeConstantDown>
      <maxRotVelocity>1700</maxRotVelocity>
      <motorConstant>7.2e-06</motorConstant>
      <momentConstant>0.015</momentConstant>
      <commandSubTopic>/gazebo/command/motor_speed</commandSubTopic>
      <motorNumber>3</motorNumber>
      <rotorDragCoefficient>8.06428e-05</rotorDragCoefficient>
      <rollingMomentCoefficient>1e-06</rollingMomentCoefficient>
      <motorSpeedPubTopic>/motor_speed/3_upper</motorSpeedPubTopic>
      <rotorVelocitySlowdownSim>10</rotorVelocitySlowdownSim>
    </plugin>
  </gazebo>
  <gazebo reference="rotor_3">
    <material>Gazebo/DarkGrey</material>
  </gazebo> -->
  <!-- Lower Rotor -->
  <joint name="rotor_9_joint" type="continuous">
    <origin rpy="0 0 0" xyz="0 0 -0.06"/>
    <axis xyz="0 0 1"/>
    <parent link="ouzel/tilt_unit_3"/>
    <child link="rotor_9"/>
  </joint>
  <link name="rotor_9">
    <inertial>
      <mass value="0.0065"/>
      <!-- [kg] -->
      <inertia ixx="2.2154157805e-06" ixy="0.0" ixz="0.0" iyy="7.08147091741e-05" iyz="0.0" izz="7.29326249936e-05"/>
    </inertial>
    <visual>
      <geometry>
        <mesh filename="propeller_ccw.dae" scale="0.1143 0.1143 0.1143"/>
      </geometry>
    </visual>
    <collision>
      <geometry>
        <cylinder length="0.005" radius="0.1143"/>
        <!-- [m] -->
      </geometry>
    </collision>
  </link>
 <!--  <gazebo>
    <plugin filename="librotors_gazebo_motor_model.so" name="back_right_lower_motor_model">
      <robotNamespace>ouzel</robotNamespace>
      <jointName>rotor_9_joint</jointName>
      <linkName>rotor_9</linkName>
      <turningDirection>ccw</turningDirection>
      <timeConstantUp>0.0125</timeConstantUp>
      <timeConstantDown>0.025</timeConstantDown>
      <maxRotVelocity>1700</maxRotVelocity>
      <motorConstant>7.2e-06</motorConstant>
      <momentConstant>0.005</momentConstant>
      <commandSubTopic>/gazebo/command/motor_speed</commandSubTopic>
      <motorNumber>9</motorNumber>
      <rotorDragCoefficient>8.06428e-05</rotorDragCoefficient>
      <rollingMomentCoefficient>1e-06</rollingMomentCoefficient>
      <motorSpeedPubTopic>/motor_speed/3_lower</motorSpeedPubTopic>
      <rotorVelocitySlowdownSim>10</rotorVelocitySlowdownSim>
    </plugin>
  </gazebo>
  <gazebo reference="rotor_9">
    <material>Gazebo/DarkGrey</material>
  </gazebo> -->
  <!-- Rotor tilt_unit -->
  <joint name="ouzel/tilt_unit_4_revolutejoint" type="continuous">
    <origin rpy="0 0 5.75958653158" xyz="0.259807621135 -0.15 0"/>
    <axis xyz="1 0 0"/>
    <parent link="ouzel/base_link"/>
    <child link="ouzel/tilt_unit_4"/>
  </joint>
  <link name="ouzel/tilt_unit_4">
    <inertial>
      <mass value="0.277"/>
      <!-- [kg] -->
      <inertia ixx="0.00034257" ixy="0" ixz="0" iyy="0.0013205" iyz="0" izz="0.0010037"/>
      <!-- [kg m^2] [kg m^2] [kg m^2] [kg m^2] [kg m^2] [kg m^2] -->
    </inertial>
    <visual>
      <geometry>
        <mesh filename="omav_tiltarm.dae" scale="1 1 1"/>
      </geometry>
    </visual>
    <collision>
      <geometry>
        <box size="0.005 0.005 0.005"/>
        <!-- [m] -->
      </geometry>
    </collision>
  </link>
  <!-- <gazebo>
    <plugin filename="librotors_gazebo_motor_model.so" name="front_right_tilt_unit_model">
      <robotNamespace>ouzel</robotNamespace>
      <jointName>ouzel/tilt_unit_4_revolutejoint</jointName>
      <linkName>ouzel/tilt_unit_4</linkName>
      <turningDirection>ccw</turningDirection>
      <motorType>position</motorType>
      <commandSubTopic>/gazebo/command/motor_speed</commandSubTopic>
      <motorNumber>16</motorNumber>
      <motorSpeedPubTopic>/tilt_motor_4/velocity</motorSpeedPubTopic>
      <motorPositionPubTopic>/tilt_motor_4/position</motorPositionPubTopic>
      <joint_control_pid>
        <p>0.11</p>
        <i>0.0</i>
        <d>0.01</d>
        <iMax>1.0</iMax>
        <iMin>-1.0</iMin>
        <cmdMax>2.0</cmdMax>
        <cmdMin>-2.0</cmdMin>
      </joint_control_pid>
    </plugin>
  </gazebo>
  <gazebo reference="ouzel/tilt_unit_4">
    <material>Gazebo/White</material>
  </gazebo> -->
  <!-- Upper Rotor -->
  <joint name="rotor_4_joint" type="continuous">
    <origin rpy="0 0 0" xyz="0 0 0.06"/>
    <axis xyz="0 0 1"/>
    <parent link="ouzel/tilt_unit_4"/>
    <child link="rotor_4"/>
  </joint>
  <link name="rotor_4">
    <inertial>
      <mass value="0.0065"/>
      <!-- [kg] -->
      <inertia ixx="2.2154157805e-06" ixy="0.0" ixz="0.0" iyy="7.08147091741e-05" iyz="0.0" izz="7.29326249936e-05"/>
    </inertial>
    <visual>
      <geometry>
        <mesh filename="propeller_cw.dae" scale="0.1143 0.1143 0.1143"/>
      </geometry>
    </visual>
    <collision>
      <geometry>
        <cylinder length="0.005" radius="0.1143"/>
        <!-- [m] -->
      </geometry>
    </collision>
  </link>
  <!-- <gazebo>
    <plugin filename="librotors_gazebo_motor_model.so" name="front_right_upper_motor_model">
      <robotNamespace>ouzel</robotNamespace>
      <jointName>rotor_4_joint</jointName>
      <linkName>rotor_4</linkName>
      <turningDirection>cw</turningDirection>
      <timeConstantUp>0.0125</timeConstantUp>
      <timeConstantDown>0.025</timeConstantDown>
      <maxRotVelocity>1700</maxRotVelocity>
      <motorConstant>7.2e-06</motorConstant>
      <momentConstant>0.015</momentConstant>
      <commandSubTopic>/gazebo/command/motor_speed</commandSubTopic>
      <motorNumber>4</motorNumber>
      <rotorDragCoefficient>8.06428e-05</rotorDragCoefficient>
      <rollingMomentCoefficient>1e-06</rollingMomentCoefficient>
      <motorSpeedPubTopic>/motor_speed/4_upper</motorSpeedPubTopic>
      <rotorVelocitySlowdownSim>10</rotorVelocitySlowdownSim>
    </plugin>
  </gazebo>
  <gazebo reference="rotor_4">
    <material>Gazebo/Orange</material>
  </gazebo> -->
  <!-- Lower Rotor -->
  <joint name="rotor_10_joint" type="continuous">
    <origin rpy="0 0 0" xyz="0 0 -0.06"/>
    <axis xyz="0 0 1"/>
    <parent link="ouzel/tilt_unit_4"/>
    <child link="rotor_10"/>
  </joint>
  <link name="rotor_10">
    <inertial>
      <mass value="0.0065"/>
      <!-- [kg] -->
      <inertia ixx="2.2154157805e-06" ixy="0.0" ixz="0.0" iyy="7.08147091741e-05" iyz="0.0" izz="7.29326249936e-05"/>
    </inertial>
    <visual>
      <geometry>
        <mesh filename="propeller_ccw.dae" scale="0.1143 0.1143 0.1143"/>
      </geometry>
    </visual>
    <collision>
      <geometry>
        <cylinder length="0.005" radius="0.1143"/>
        <!-- [m] -->
      </geometry>
    </collision>
  </link>
  <!-- <gazebo>
    <plugin filename="librotors_gazebo_motor_model.so" name="front_right_lower_motor_model">
      <robotNamespace>ouzel</robotNamespace>
      <jointName>rotor_10_joint</jointName>
      <linkName>rotor_10</linkName>
      <turningDirection>ccw</turningDirection>
      <timeConstantUp>0.0125</timeConstantUp>
      <timeConstantDown>0.025</timeConstantDown>
      <maxRotVelocity>1700</maxRotVelocity>
      <motorConstant>7.2e-06</motorConstant>
      <momentConstant>0.005</momentConstant>
      <commandSubTopic>/gazebo/command/motor_speed</commandSubTopic>
      <motorNumber>10</motorNumber>
      <rotorDragCoefficient>8.06428e-05</rotorDragCoefficient>
      <rollingMomentCoefficient>1e-06</rollingMomentCoefficient>
      <motorSpeedPubTopic>/motor_speed/4_lower</motorSpeedPubTopic>
      <rotorVelocitySlowdownSim>10</rotorVelocitySlowdownSim>
    </plugin>
  </gazebo>
  <gazebo reference="rotor_10">
    <material>Gazebo/Orange</material>
  </gazebo> -->
  <!-- Rotor tilt_unit -->
  <joint name="ouzel/tilt_unit_5_revolutejoint" type="continuous">
    <origin rpy="0 0 2.61799387799" xyz="-0.259807621135 0.15 0"/>
    <axis xyz="1 0 0"/>
    <parent link="ouzel/base_link"/>
    <child link="ouzel/tilt_unit_5"/>
  </joint>
  <link name="ouzel/tilt_unit_5">
    <inertial>
      <mass value="0.277"/>
      <!-- [kg] -->
      <inertia ixx="0.00034257" ixy="0" ixz="0" iyy="0.0013205" iyz="0" izz="0.0010037"/>
      <!-- [kg m^2] [kg m^2] [kg m^2] [kg m^2] [kg m^2] [kg m^2] -->
    </inertial>
    <visual>
      <geometry>
        <mesh filename="omav_tiltarm.dae" scale="1 1 1"/>
      </geometry>
    </visual>
    <collision>
      <geometry>
        <box size="0.005 0.005 0.005"/>
        <!-- [m] -->
      </geometry>
    </collision>
  </link>
 <!--  <gazebo>
    <plugin filename="librotors_gazebo_motor_model.so" name="back_left_tilt_unit_model">
      <robotNamespace>ouzel</robotNamespace>
      <jointName>ouzel/tilt_unit_5_revolutejoint</jointName>
      <linkName>ouzel/tilt_unit_5</linkName>
      <turningDirection>ccw</turningDirection>
      <motorType>position</motorType>
      <commandSubTopic>/gazebo/command/motor_speed</commandSubTopic>
      <motorNumber>17</motorNumber>
      <motorSpeedPubTopic>/tilt_motor_5/velocity</motorSpeedPubTopic>
      <motorPositionPubTopic>/tilt_motor_5/position</motorPositionPubTopic>
      <joint_control_pid>
        <p>0.11</p>
        <i>0.0</i>
        <d>0.01</d>
        <iMax>1.0</iMax>
        <iMin>-1.0</iMin>
        <cmdMax>2.0</cmdMax>
        <cmdMin>-2.0</cmdMin>
      </joint_control_pid>
    </plugin>
  </gazebo>
  <gazebo reference="ouzel/tilt_unit_5">
    <material>Gazebo/White</material>
  </gazebo> -->
  <!-- Upper Rotor -->
  <joint name="rotor_5_joint" type="continuous">
    <origin rpy="0 0 0" xyz="0 0 0.06"/>
    <axis xyz="0 0 1"/>
    <parent link="ouzel/tilt_unit_5"/>
    <child link="rotor_5"/>
  </joint>
  <link name="rotor_5">
    <inertial>
      <mass value="0.0065"/>
      <!-- [kg] -->
      <inertia ixx="2.2154157805e-06" ixy="0.0" ixz="0.0" iyy="7.08147091741e-05" iyz="0.0" izz="7.29326249936e-05"/>
    </inertial>
    <visual>
      <geometry>
        <mesh filename="propeller_ccw.dae" scale="0.1143 0.1143 0.1143"/>
      </geometry>
    </visual>
    <collision>
      <geometry>
        <cylinder length="0.005" radius="0.1143"/>
        <!-- [m] -->
      </geometry>
    </collision>
  </link>
  <!-- <gazebo>
    <plugin filename="librotors_gazebo_motor_model.so" name="back_left_upper_motor_model">
      <robotNamespace>ouzel</robotNamespace>
      <jointName>rotor_5_joint</jointName>
      <linkName>rotor_5</linkName>
      <turningDirection>ccw</turningDirection>
      <timeConstantUp>0.0125</timeConstantUp>
      <timeConstantDown>0.025</timeConstantDown>
      <maxRotVelocity>1700</maxRotVelocity>
      <motorConstant>7.2e-06</motorConstant>
      <momentConstant>0.015</momentConstant>
      <commandSubTopic>/gazebo/command/motor_speed</commandSubTopic>
      <motorNumber>5</motorNumber>
      <rotorDragCoefficient>8.06428e-05</rotorDragCoefficient>
      <rollingMomentCoefficient>1e-06</rollingMomentCoefficient>
      <motorSpeedPubTopic>/motor_speed/5_upper</motorSpeedPubTopic>
      <rotorVelocitySlowdownSim>10</rotorVelocitySlowdownSim>
    </plugin>
  </gazebo>
  <gazebo reference="rotor_5">
    <material>Gazebo/DarkGrey</material>
  </gazebo> -->
  <!-- Lower Rotor -->
  <joint name="rotor_11_joint" type="continuous">
    <origin rpy="0 0 0" xyz="0 0 -0.06"/>
    <axis xyz="0 0 1"/>
    <parent link="ouzel/tilt_unit_5"/>
    <child link="rotor_11"/>
  </joint>
  <link name="rotor_11">
    <inertial>
      <mass value="0.0065"/>
      <!-- [kg] -->
      <inertia ixx="2.2154157805e-06" ixy="0.0" ixz="0.0" iyy="7.08147091741e-05" iyz="0.0" izz="7.29326249936e-05"/>
    </inertial>
    <visual>
      <geometry>
        <mesh filename="propeller_cw.dae" scale="0.1143 0.1143 0.1143"/>
      </geometry>
    </visual>
    <collision>
      <geometry>
        <cylinder length="0.005" radius="0.1143"/>
        <!-- [m] -->
      </geometry>
    </collision>
  </link>

  <joint name="ouzel/manipulator_joint" type="fixed">
    <axis xyz="0 0 1"/>
    <origin rpy="0 1.5708 0" xyz="0 0 0"/>
    <parent link="ouzel/base_link"/>
    <child link="ouzel/manipulator"/>
  </joint>
  <link name="ouzel/manipulator">
    <visual>
      <origin rpy="0 0 0" xyz="0 0 0.25"/>
      <geometry>
        <cylinder length="0.5" radius="0.01"/>
      </geometry>
    </visual>
    <collision>
      <origin rpy="0 0 0" xyz="0 0 0.25"/>
      <geometry>
        <cylinder length="0.5" radius="0.01"/>
      </geometry>
    </collision>
    <inertial>
      <mass value="0.18"/>
      <inertia ixx="0.000807" ixy="0" ixz="0" iyy="0.000807" iyz="0" izz="2e-6"/>
    </inertial>
  </link>

  <joint name="ouzel/force_sensor_tool" type="fixed">
    <parent link="ouzel/manipulator"/>
    <origin rpy="0.0 0.0 0.0" xyz="0.0 0.0 0.5"/>
    <child link="ouzel/force_sensor_tool"/>
  </joint>

  <link name="ouzel/force_sensor_tool">
    <visual>
      <origin rpy="0 0 0" xyz="0 0 0"/>
      <geometry>
        <cylinder length="0.05" radius="0.01"/>
      </geometry>
    </visual>
    <collision>
      <origin rpy="0 0 0" xyz="0 0 0"/>
      <geometry>
        <cylinder length="0.05" radius="0.01"/>
      </geometry>
    </collision>
    <inertial>
      <inertia ixx="0.001" ixy="0.0" ixz="0.0" iyy="0.001" iyz="0.0" izz="0.001"/>
      <mass value="0.1"/>
      <!-- [kg] -->
    </inertial>
  </link>

  <joint name="ouzel/tool_joint" type="fixed">
    <axis xyz="0 0 1"/>
    <origin rpy="0.0 0.0 0.0" xyz="0 0 0"/>
    <parent link="ouzel/force_sensor_tool"/>
    <child link="ouzel/tool"/>
  </joint>
  <link name="ouzel/tool">
    <visual>
      <origin rpy="0 0 0" xyz="0 0 0.02"/>
      <geometry>
        <cylinder length="0.04" radius="0.01"/>
      </geometry>
    </visual>
    <collision>
      <origin rpy="0 0 0" xyz="0 0 0.02"/>
      <geometry>
        <cylinder length="0.04" radius="0.01"/>
      </geometry>
      <material name="">
        <contact name="omav"/>
      </material>
    </collision>
    <inertial>
      <mass value="0.03"/>
      <inertia ixx="0.000807" ixy="0" ixz="0" iyy="0.000807" iyz="0" izz="2e-6"/>
    </inertial>
  </link>

</robot>
  