<?xml version="1.0" ?><!-- =================================================================================== --><!-- |    This document was autogenerated by xacro from /home/vincent/rl_4_aerial_manipulator/catkin_ws/src/mav_tools/mav_description/urdf/ouzel_base.xacro | --><!-- |    EDITING THIS FILE BY HAND IS NOT RECOMMENDED                                 | --><!-- =================================================================================== --><!--
  Copyright 2015 Fadri Furrer, ASL, ETH Zurich, Switzerland
  Copyright 2015 Michael Burri, ASL, ETH Zurich, Switzerland
  Copyright 2015 Mina Kamel, ASL, ETH Zurich, Switzerland
  Copyright 2015 Janosch Nikolic, ASL, ETH Zurich, Switzerland
  Copyright 2015 Markus Achtelik, ASL, ETH Zurich, Switzerland

  Licensed under the Apache License, Version 2.0 (the "License");
  you may not use this file except in compliance with the License.
  You may obtain a copy of the License at

  http://www.apache.org/licenses/LICENSE-2.0

  Unless required by applicable law or agreed to in writing, software
  distributed under the License is distributed on an "AS IS" BASIS,
  WITHOUT WARRANTIES OR CONDITIONS OF ANY KIND, either express or implied.
  See the License for the specific language governing permissions and
  limitations under the License.
--><robot name="ouzel"><!-- =============================================================== --><!-- ==================== ROS INTERFACE MACRO ====================== --><!-- =============================================================== --><!-- <xacro:macro 
  		name="ros_interface_plugin_macro"
  		params="namespace">
    <gazebo>
      <plugin name="ros_interface_plugin" filename="librotors_gazebo_ros_interface_plugin.so">
        <robotNamespace>${namespace}</robotNamespace>
      </plugin>
    </gazebo>
  </xacro:macro>--><link name="ouzel/base_link" /><joint name="ouzel/base_joint" type="fixed"><origin rpy="0.0 0 0" xyz="0 0 0" /><parent link="ouzel/base_link" /><child link="ouzel/base_link_inertia" /></joint><link name="ouzel/base_link_inertia"><inertial><mass value="2.53" /><!-- [kg] --><origin xyz="0.0 0.0 0.03" /><inertia ixx="0.0075" ixy="-3.4208e-05" ixz="2.4695e-05" iyy="0.010939" iyz="-3.8826e-06" izz="0.01369" /></inertial><visual><origin rpy="0 0 0" xyz="0 0 0" /><geometry><mesh filename="/ouzel_simple.obj" scale="1 1 1" /></geometry></visual><collision><origin rpy="0 0 0" xyz="0 0 0" /><geometry><mesh filename="/ouzel_simple.obj" scale="1 1 1" /></geometry></collision><surface><friction><ode><mu>0.5</mu><mu2>0.5</mu2></ode></friction><bounce><restitution_coefficient>0.01</restitution_coefficient><threshold>0.01</threshold></bounce><contact><ode><max_vel>0.1</max_vel><soft_cfm>0.8</soft_cfm><soft_erp>0.8</soft_erp><kd>2500</kd><kp>10</kp><min_depth>0.001</min_depth></ode></contact></surface></link><!-- attach multirotor_base_plugin to the base_link --><!-- Rotor tilt_unit --><joint name="ouzel/tilt_unit_0_revolutejoint" type="continuous"><origin rpy="0 0 4.71238898038" xyz="0 -0.3 0" /><axis xyz="1 0 0" /><parent link="ouzel/base_link_inertia" /><child link="ouzel/tilt_unit_0" /></joint><link name="ouzel/tilt_unit_0"><inertial><mass value="0.277" /><!-- [kg] --><inertia ixx="0.00034257" ixy="0" ixz="0" iyy="0.0013205" iyz="0" izz="0.0010037" /><!-- [kg m^2] [kg m^2] [kg m^2] [kg m^2] [kg m^2] [kg m^2] --></inertial><visual><geometry><mesh filename="/home/vincent/rl_4_aerial_manipulator/catkin_ws/src/rotors_simulator/rotors_description/meshes/omav/omav_tiltarm.dae" scale="1 1 1" /></geometry></visual><collision><geometry><box size="0.005 0.005 0.005" /><!-- [m] --></geometry></collision></link><!-- Upper Rotor --><joint name="rotor_0_joint" type="continuous"><origin rpy="0 0 0" xyz="0 0 0.06" /><axis xyz="0 0 1" /><parent link="ouzel/tilt_unit_0" /><child link="rotor_0" /></joint><link name="rotor_0"><inertial><mass value="0.0065" /><!-- [kg] --><inertia ixx="2.2154157805000002e-06" ixy="0.0" ixz="0.0" iyy="7.081470917410501e-05" iyz="0.0" izz="7.2932624993605e-05" /></inertial><visual><geometry><mesh filename="/home/vincent/rl_4_aerial_manipulator/catkin_ws/src/rotors_simulator/rotors_description/meshes/propeller_ccw.dae" scale="0.1143 0.1143 0.1143" /></geometry></visual><collision><geometry><cylinder length="0.005" radius="0.1143" /><!-- [m] --></geometry></collision></link><!-- Lower Rotor --><joint name="rotor_6_joint" type="continuous"><origin rpy="0 0 0" xyz="0 0 -0.06" /><axis xyz="0 0 1" /><parent link="ouzel/tilt_unit_0" /><child link="rotor_6" /></joint><link name="rotor_6"><inertial><mass value="0.0065" /><!-- [kg] --><inertia ixx="2.2154157805000002e-06" ixy="0.0" ixz="0.0" iyy="7.081470917410501e-05" iyz="0.0" izz="7.2932624993605e-05" /></inertial><visual><geometry><mesh filename="/home/vincent/rl_4_aerial_manipulator/catkin_ws/src/rotors_simulator/rotors_description/meshes/propeller_cw.dae" scale="0.1143 0.1143 0.1143" /></geometry></visual><collision><geometry><cylinder length="0.005" radius="0.1143" /><!-- [m] --></geometry></collision></link><!-- Rotor tilt_unit --><joint name="ouzel/tilt_unit_1_revolutejoint" type="continuous"><origin rpy="0 0 1.57079632679" xyz="0 0.3 0" /><axis xyz="1 0 0" /><parent link="ouzel/base_link_inertia" /><child link="ouzel/tilt_unit_1" /></joint><link name="ouzel/tilt_unit_1"><inertial><mass value="0.277" /><!-- [kg] --><inertia ixx="0.00034257" ixy="0" ixz="0" iyy="0.0013205" iyz="0" izz="0.0010037" /><!-- [kg m^2] [kg m^2] [kg m^2] [kg m^2] [kg m^2] [kg m^2] --></inertial><visual><geometry><mesh filename="/home/vincent/rl_4_aerial_manipulator/catkin_ws/src/rotors_simulator/rotors_description/meshes/omav/omav_tiltarm.dae" scale="1 1 1" /></geometry></visual><collision><geometry><box size="0.005 0.005 0.005" /><!-- [m] --></geometry></collision></link><!-- Upper Rotor --><joint name="rotor_1_joint" type="continuous"><origin rpy="0 0 0" xyz="0 0 0.06" /><axis xyz="0 0 1" /><parent link="ouzel/tilt_unit_1" /><child link="rotor_1" /></joint><link name="rotor_1"><inertial><mass value="0.0065" /><!-- [kg] --><inertia ixx="2.2154157805000002e-06" ixy="0.0" ixz="0.0" iyy="7.081470917410501e-05" iyz="0.0" izz="7.2932624993605e-05" /></inertial><visual><geometry><mesh filename="/home/vincent/rl_4_aerial_manipulator/catkin_ws/src/rotors_simulator/rotors_description/meshes/propeller_cw.dae" scale="0.1143 0.1143 0.1143" /></geometry></visual><collision><geometry><cylinder length="0.005" radius="0.1143" /><!-- [m] --></geometry></collision></link><!-- Lower Rotor --><joint name="rotor_7_joint" type="continuous"><origin rpy="0 0 0" xyz="0 0 -0.06" /><axis xyz="0 0 1" /><parent link="ouzel/tilt_unit_1" /><child link="rotor_7" /></joint><link name="rotor_7"><inertial><mass value="0.0065" /><!-- [kg] --><inertia ixx="2.2154157805000002e-06" ixy="0.0" ixz="0.0" iyy="7.081470917410501e-05" iyz="0.0" izz="7.2932624993605e-05" /></inertial><visual><geometry><mesh filename="/home/vincent/rl_4_aerial_manipulator/catkin_ws/src/rotors_simulator/rotors_description/meshes/propeller_ccw.dae" scale="0.1143 0.1143 0.1143" /></geometry></visual><collision><geometry><cylinder length="0.005" radius="0.1143" /><!-- [m] --></geometry></collision></link><!-- Rotor tilt_unit --><joint name="ouzel/tilt_unit_2_revolutejoint" type="continuous"><origin rpy="0 0 0.52359877559" xyz="0.25980762113519995 0.15 0" /><axis xyz="1 0 0" /><parent link="ouzel/base_link_inertia" /><child link="ouzel/tilt_unit_2" /></joint><link name="ouzel/tilt_unit_2"><inertial><mass value="0.277" /><!-- [kg] --><inertia ixx="0.00034257" ixy="0" ixz="0" iyy="0.0013205" iyz="0" izz="0.0010037" /><!-- [kg m^2] [kg m^2] [kg m^2] [kg m^2] [kg m^2] [kg m^2] --></inertial><visual><geometry><mesh filename="/home/vincent/rl_4_aerial_manipulator/catkin_ws/src/rotors_simulator/rotors_description/meshes/omav/omav_tiltarm.dae" scale="1 1 1" /></geometry></visual><collision><geometry><box size="0.005 0.005 0.005" /><!-- [m] --></geometry></collision></link><!-- Upper Rotor --><joint name="rotor_2_joint" type="continuous"><origin rpy="0 0 0" xyz="0 0 0.06" /><axis xyz="0 0 1" /><parent link="ouzel/tilt_unit_2" /><child link="rotor_2" /></joint><link name="rotor_2"><inertial><mass value="0.0065" /><!-- [kg] --><inertia ixx="2.2154157805000002e-06" ixy="0.0" ixz="0.0" iyy="7.081470917410501e-05" iyz="0.0" izz="7.2932624993605e-05" /></inertial><visual><geometry><mesh filename="/home/vincent/rl_4_aerial_manipulator/catkin_ws/src/rotors_simulator/rotors_description/meshes/propeller_ccw.dae" scale="0.1143 0.1143 0.1143" /></geometry></visual><collision><geometry><cylinder length="0.005" radius="0.1143" /><!-- [m] --></geometry></collision></link><!-- Lower Rotor --><joint name="rotor_8_joint" type="continuous"><origin rpy="0 0 0" xyz="0 0 -0.06" /><axis xyz="0 0 1" /><parent link="ouzel/tilt_unit_2" /><child link="rotor_8" /></joint><link name="rotor_8"><inertial><mass value="0.0065" /><!-- [kg] --><inertia ixx="2.2154157805000002e-06" ixy="0.0" ixz="0.0" iyy="7.081470917410501e-05" iyz="0.0" izz="7.2932624993605e-05" /></inertial><visual><geometry><mesh filename="/home/vincent/rl_4_aerial_manipulator/catkin_ws/src/rotors_simulator/rotors_description/meshes/propeller_cw.dae" scale="0.1143 0.1143 0.1143" /></geometry></visual><collision><geometry><cylinder length="0.005" radius="0.1143" /><!-- [m] --></geometry></collision></link><!-- Rotor tilt_unit --><joint name="ouzel/tilt_unit_3_revolutejoint" type="continuous"><origin rpy="0 0 3.66519142919" xyz="-0.25980762113519995 -0.15 0" /><axis xyz="1 0 0" /><parent link="ouzel/base_link_inertia" /><child link="ouzel/tilt_unit_3" /></joint><link name="ouzel/tilt_unit_3"><inertial><mass value="0.277" /><!-- [kg] --><inertia ixx="0.00034257" ixy="0" ixz="0" iyy="0.0013205" iyz="0" izz="0.0010037" /><!-- [kg m^2] [kg m^2] [kg m^2] [kg m^2] [kg m^2] [kg m^2] --></inertial><visual><geometry><mesh filename="/home/vincent/rl_4_aerial_manipulator/catkin_ws/src/rotors_simulator/rotors_description/meshes/omav/omav_tiltarm.dae" scale="1 1 1" /></geometry></visual><collision><geometry><box size="0.005 0.005 0.005" /><!-- [m] --></geometry></collision></link><!-- Upper Rotor --><joint name="rotor_3_joint" type="continuous"><origin rpy="0 0 0" xyz="0 0 0.06" /><axis xyz="0 0 1" /><parent link="ouzel/tilt_unit_3" /><child link="rotor_3" /></joint><link name="rotor_3"><inertial><mass value="0.0065" /><!-- [kg] --><inertia ixx="2.2154157805000002e-06" ixy="0.0" ixz="0.0" iyy="7.081470917410501e-05" iyz="0.0" izz="7.2932624993605e-05" /></inertial><visual><geometry><mesh filename="/home/vincent/rl_4_aerial_manipulator/catkin_ws/src/rotors_simulator/rotors_description/meshes/propeller_cw.dae" scale="0.1143 0.1143 0.1143" /></geometry></visual><collision><geometry><cylinder length="0.005" radius="0.1143" /><!-- [m] --></geometry></collision></link><!-- Lower Rotor --><joint name="rotor_9_joint" type="continuous"><origin rpy="0 0 0" xyz="0 0 -0.06" /><axis xyz="0 0 1" /><parent link="ouzel/tilt_unit_3" /><child link="rotor_9" /></joint><link name="rotor_9"><inertial><mass value="0.0065" /><!-- [kg] --><inertia ixx="2.2154157805000002e-06" ixy="0.0" ixz="0.0" iyy="7.081470917410501e-05" iyz="0.0" izz="7.2932624993605e-05" /></inertial><visual><geometry><mesh filename="/home/vincent/rl_4_aerial_manipulator/catkin_ws/src/rotors_simulator/rotors_description/meshes/propeller_ccw.dae" scale="0.1143 0.1143 0.1143" /></geometry></visual><collision><geometry><cylinder length="0.005" radius="0.1143" /><!-- [m] --></geometry></collision></link><!-- Rotor tilt_unit --><joint name="ouzel/tilt_unit_4_revolutejoint" type="continuous"><origin rpy="0 0 5.75958653158" xyz="0.25980762113519995 -0.15 0" /><axis xyz="1 0 0" /><parent link="ouzel/base_link_inertia" /><child link="ouzel/tilt_unit_4" /></joint><link name="ouzel/tilt_unit_4"><inertial><mass value="0.277" /><!-- [kg] --><inertia ixx="0.00034257" ixy="0" ixz="0" iyy="0.0013205" iyz="0" izz="0.0010037" /><!-- [kg m^2] [kg m^2] [kg m^2] [kg m^2] [kg m^2] [kg m^2] --></inertial><visual><geometry><mesh filename="/home/vincent/rl_4_aerial_manipulator/catkin_ws/src/rotors_simulator/rotors_description/meshes/omav/omav_tiltarm.dae" scale="1 1 1" /></geometry></visual><collision><geometry><box size="0.005 0.005 0.005" /><!-- [m] --></geometry></collision></link><!-- Upper Rotor --><joint name="rotor_4_joint" type="continuous"><origin rpy="0 0 0" xyz="0 0 0.06" /><axis xyz="0 0 1" /><parent link="ouzel/tilt_unit_4" /><child link="rotor_4" /></joint><link name="rotor_4"><inertial><mass value="0.0065" /><!-- [kg] --><inertia ixx="2.2154157805000002e-06" ixy="0.0" ixz="0.0" iyy="7.081470917410501e-05" iyz="0.0" izz="7.2932624993605e-05" /></inertial><visual><geometry><mesh filename="/home/vincent/rl_4_aerial_manipulator/catkin_ws/src/rotors_simulator/rotors_description/meshes/propeller_cw.dae" scale="0.1143 0.1143 0.1143" /></geometry></visual><collision><geometry><cylinder length="0.005" radius="0.1143" /><!-- [m] --></geometry></collision></link><!-- Lower Rotor --><joint name="rotor_10_joint" type="continuous"><origin rpy="0 0 0" xyz="0 0 -0.06" /><axis xyz="0 0 1" /><parent link="ouzel/tilt_unit_4" /><child link="rotor_10" /></joint><link name="rotor_10"><inertial><mass value="0.0065" /><!-- [kg] --><inertia ixx="2.2154157805000002e-06" ixy="0.0" ixz="0.0" iyy="7.081470917410501e-05" iyz="0.0" izz="7.2932624993605e-05" /></inertial><visual><geometry><mesh filename="/home/vincent/rl_4_aerial_manipulator/catkin_ws/src/rotors_simulator/rotors_description/meshes/propeller_ccw.dae" scale="0.1143 0.1143 0.1143" /></geometry></visual><collision><geometry><cylinder length="0.005" radius="0.1143" /><!-- [m] --></geometry></collision></link><!-- Rotor tilt_unit --><joint name="ouzel/tilt_unit_5_revolutejoint" type="continuous"><origin rpy="0 0 2.61799387799" xyz="-0.25980762113519995 0.15 0" /><axis xyz="1 0 0" /><parent link="ouzel/base_link_inertia" /><child link="ouzel/tilt_unit_5" /></joint><link name="ouzel/tilt_unit_5"><inertial><mass value="0.277" /><!-- [kg] --><inertia ixx="0.00034257" ixy="0" ixz="0" iyy="0.0013205" iyz="0" izz="0.0010037" /><!-- [kg m^2] [kg m^2] [kg m^2] [kg m^2] [kg m^2] [kg m^2] --></inertial><visual><geometry><mesh filename="/home/vincent/rl_4_aerial_manipulator/catkin_ws/src/rotors_simulator/rotors_description/meshes/omav/omav_tiltarm.dae" scale="1 1 1" /></geometry></visual><collision><geometry><box size="0.005 0.005 0.005" /><!-- [m] --></geometry></collision></link><!-- Upper Rotor --><joint name="rotor_5_joint" type="continuous"><origin rpy="0 0 0" xyz="0 0 0.06" /><axis xyz="0 0 1" /><parent link="ouzel/tilt_unit_5" /><child link="rotor_5" /></joint><link name="rotor_5"><inertial><mass value="0.0065" /><!-- [kg] --><inertia ixx="2.2154157805000002e-06" ixy="0.0" ixz="0.0" iyy="7.081470917410501e-05" iyz="0.0" izz="7.2932624993605e-05" /></inertial><visual><geometry><mesh filename="/home/vincent/rl_4_aerial_manipulator/catkin_ws/src/rotors_simulator/rotors_description/meshes/propeller_ccw.dae" scale="0.1143 0.1143 0.1143" /></geometry></visual><collision><geometry><cylinder length="0.005" radius="0.1143" /><!-- [m] --></geometry></collision></link><!-- Lower Rotor --><joint name="rotor_11_joint" type="continuous"><origin rpy="0 0 0" xyz="0 0 -0.06" /><axis xyz="0 0 1" /><parent link="ouzel/tilt_unit_5" /><child link="rotor_11" /></joint><link name="rotor_11"><inertial><mass value="0.0065" /><!-- [kg] --><inertia ixx="2.2154157805000002e-06" ixy="0.0" ixz="0.0" iyy="7.081470917410501e-05" iyz="0.0" izz="7.2932624993605e-05" /></inertial><visual><geometry><mesh filename="/home/vincent/rl_4_aerial_manipulator/catkin_ws/src/rotors_simulator/rotors_description/meshes/propeller_cw.dae" scale="0.1143 0.1143 0.1143" /></geometry></visual><collision><geometry><cylinder length="0.005" radius="0.1143" /><!-- [m] --></geometry></collision></link><!-- IMU link --><link name="ouzel/imu_link"><inertial><inertia ixx="0.00001" ixy="0.0" ixz="0.0" iyy="0.00001" iyz="0.0" izz="0.00001" /><mass value="0.015" /><!-- [kg] --><origin rpy="0 0 0" xyz="0 0 0" /></inertial></link><!-- IMU joint --><joint name="ouzel/imu_joint" type="fixed"><origin rpy="0 0 0" xyz="0 0 0" /><parent link="ouzel/base_link" /><child link="ouzel/imu_link" /><limit effort="0" lower="0" upper="0" velocity="0" /></joint><!-- IMU link --><link name="ouzel/imugt_link"><inertial><inertia ixx="0.00001" ixy="0.0" ixz="0.0" iyy="0.00001" iyz="0.0" izz="0.00001" /><mass value="1e-05" /><!-- [kg] --><origin rpy="0 0 0" xyz="0 0 0" /></inertial></link><!-- IMU joint --><joint name="ouzel/imugt_joint" type="fixed"><origin rpy="0 0 0" xyz="0 0 0" /><parent link="ouzel/base_link" /><child link="ouzel/imugt_link" /><limit effort="0" lower="0" upper="0" velocity="0" /></joint><!-- odometry link --><link name="ouzel/odometry_sensorgt_link"><inertial><inertia ixx="0.00001" ixy="0.0" ixz="0.0" iyy="0.00001" iyz="0.0" izz="0.00001" /><mass value="1e-05" /><!-- [kg] --></inertial></link><!-- odometry joint --><joint name="ouzel/odometry_sensorgt_joint" type="fixed"><parent link="ouzel/base_link" /><origin rpy="0.0 0.0 0.0" xyz="0.0 0.0 0.0" /><child link="ouzel/odometry_sensorgt_link" /><limit effort="0" lower="0" upper="0" velocity="0" /></joint><!-- odometry link --><link name="ouzel/odometry_sensor1_link"><inertial><inertia ixx="0.00001" ixy="0.0" ixz="0.0" iyy="0.00001" iyz="0.0" izz="0.00001" /><mass value="1e-05" /><!-- [kg] --></inertial></link><!-- odometry joint --><joint name="ouzel/odometry_sensor1_joint" type="fixed"><parent link="ouzel/base_link_inertia" /><origin rpy="0.0 0.0 0.0" xyz="0.0 0.0 0.0" /><child link="ouzel/odometry_sensor1_link" /><limit effort="0" lower="0" upper="0" velocity="0" /></joint><!-- Add tether
  <xacro:if value="$(arg add_tether)">
    <xacro:include filename="$(find mav_description)/urdf/ouzel_tether.xacro"/>
    <xacro:cable_add />
  </xacro:if>   --></robot>