<sdf version='1.6'>
  <model name='ouzel'>
    <link name='ouzel/base_link'>
      <pose frame=''>0 0 0 0 -0 0</pose>
      <inertial>
        <pose frame=''>0 0 0 0 -0 0</pose>
        <mass>3.13</mass>
        <inertia>
          <ixx>0.0075</ixx>
          <ixy>-3.4208e-05</ixy>
          <ixz>2.4695e-05</ixz>
          <iyy>0.010939</iyy>
          <iyz>-3.8826e-06</iyz>
          <izz>0.01369</izz>
        </inertia>
      </inertial>
      <collision name='ouzel/base_link_inertia_collision'>
        <pose frame=''>0 0 0 0 -0 0</pose>
        <geometry>
          <box>
            <size>0.22 0.22 0.45</size>
          </box>
        </geometry>
      </collision>
      <visual name='ouzel/base_link_inertia_visual'>
        <pose frame=''>0 0 0 0 -0 0</pose>
        <geometry>
          <mesh>
            <scale>1 1 1</scale>
            <uri>model://mav_description/meshes/ouzel_simple.stl</uri>
          </mesh>
        </geometry>
      </visual>
    </link>
    <link name='ouzel/imu_link'>
      <pose frame=''>0 0 0 0 -0 0</pose>
      <inertial>
        <pose frame=''>0 0 0 0 -0 0</pose>
        <mass>0.015</mass>
        <inertia>
          <ixx>1e-05</ixx>
          <ixy>0</ixy>
          <ixz>0</ixz>
          <iyy>1e-05</iyy>
          <iyz>0</iyz>
          <izz>1e-05</izz>
        </inertia>
      </inertial>
    </link>
    <joint name='ouzel/imu_joint' type='revolute'>
      <child>ouzel/imu_link</child>
      <parent>ouzel/base_link</parent>
      <axis>
        <xyz>1 0 0</xyz>
        <limit>
          <lower>0</lower>
          <upper>0</upper>
          <effort>0</effort>
          <velocity>0</velocity>
        </limit>
        <dynamics>
          <spring_reference>0</spring_reference>
          <spring_stiffness>0</spring_stiffness>
        </dynamics>
        <use_parent_model_frame>1</use_parent_model_frame>
      </axis>
    </joint>
    <link name='ouzel/odometry_sensor1_link'>
      <pose frame=''>0 0 0 0 -0 0</pose>
      <inertial>
        <pose frame=''>0 0 0 0 -0 0</pose>
        <mass>1e-05</mass>
        <inertia>
          <ixx>1e-05</ixx>
          <ixy>0</ixy>
          <ixz>0</ixz>
          <iyy>1e-05</iyy>
          <iyz>0</iyz>
          <izz>1e-05</izz>
        </inertia>
      </inertial>
    </link>
    <joint name='ouzel/odometry_sensor1_joint' type='revolute'>
      <child>ouzel/odometry_sensor1_link</child>
      <parent>ouzel/base_link</parent>
      <axis>
        <xyz>1 0 0</xyz>
        <limit>
          <lower>0</lower>
          <upper>0</upper>
          <effort>0</effort>
          <velocity>0</velocity>
        </limit>
        <dynamics>
          <spring_reference>0</spring_reference>
          <spring_stiffness>0</spring_stiffness>
        </dynamics>
        <use_parent_model_frame>1</use_parent_model_frame>
      </axis>
    </joint>
    <link name='ouzel/tilt_unit_0'>
      <pose frame=''>0 -0.3 0 0 -0 -1.5708</pose>
      <inertial>
        <pose frame=''>0 0 0 0 -0 0</pose>
        <mass>0.277</mass>
        <inertia>
          <ixx>0.00034257</ixx>
          <ixy>0</ixy>
          <ixz>0</ixz>
          <iyy>0.0013205</iyy>
          <iyz>0</iyz>
          <izz>0.0010037</izz>
        </inertia>
      </inertial>
      <collision name='ouzel/tilt_unit_0_collision'>
        <pose frame=''>0 0 0 0 -0 0</pose>
        <geometry>
          <box>
            <size>0.005 0.005 0.005</size>
          </box>
        </geometry>
        <surface>
          <contact>
            <ode/>
          </contact>
          <friction>
            <ode/>
          </friction>
        </surface>
      </collision>
      <visual name='ouzel/tilt_unit_0_visual'>
        <pose frame=''>0 0 0 0 -0 0</pose>
        <geometry>
          <mesh>
            <scale>1 1 1</scale>
            <uri>model://rotors_description/meshes/omav/omav_tiltarm.dae</uri>
          </mesh>
        </geometry>
        <material>
          <script>
            <name>Gazebo/White</name>
            <uri>file://media/materials/scripts/gazebo.material</uri>
          </script>
        </material>
      </visual>
      <gravity>1</gravity>
      <velocity_decay/>
    </link>
    <joint name='ouzel/tilt_unit_0_revolutejoint' type='revolute'>
      <child>ouzel/tilt_unit_0</child>
      <parent>ouzel/base_link</parent>
      <axis>
        <xyz>-0 -1 0</xyz>
        <limit>
          <lower>-1e+16</lower>
          <upper>1e+16</upper>
        </limit>
        <dynamics>
          <spring_reference>0</spring_reference>
          <spring_stiffness>0</spring_stiffness>
        </dynamics>
        <use_parent_model_frame>1</use_parent_model_frame>
      </axis>
    </joint>
    <link name='rotor_0'>
      <pose frame=''>0 -0.3 0.06 0 -0 -1.5708</pose>
      <inertial>
        <pose frame=''>0 0 0 0 -0 0</pose>
        <mass>0.0065</mass>
        <inertia>
          <ixx>2.21542e-06</ixx>
          <ixy>0</ixy>
          <ixz>0</ixz>
          <iyy>7.08147e-05</iyy>
          <iyz>0</iyz>
          <izz>7.29326e-05</izz>
        </inertia>
      </inertial>
      <collision name='rotor_0_collision'>
        <pose frame=''>0 0 0 0 -0 0</pose>
        <geometry>
          <cylinder>
            <length>0.005</length>
            <radius>0.1143</radius>
          </cylinder>
        </geometry>
        <surface>
          <contact>
            <ode/>
          </contact>
          <friction>
            <ode/>
          </friction>
        </surface>
      </collision>
      <visual name='rotor_0_visual'>
        <pose frame=''>0 0 0 0 -0 0</pose>
        <geometry>
          <mesh>
            <scale>0.1143 0.1143 0.1143</scale>
            <uri>model://rotors_description/meshes/propeller_ccw.dae</uri>
          </mesh>
        </geometry>
        <material>
          <script>
            <name>Gazebo/Black</name>
            <uri>file://media/materials/scripts/gazebo.material</uri>
          </script>
        </material>
      </visual>
      <gravity>1</gravity>
      <velocity_decay/>
    </link>
    <joint name='rotor_0_joint' type='revolute'>
      <child>rotor_0</child>
      <parent>ouzel/tilt_unit_0</parent>
      <axis>
        <xyz>0 0 1</xyz>
        <limit>
          <lower>-1e+16</lower>
          <upper>1e+16</upper>
        </limit>
        <dynamics>
          <spring_reference>0</spring_reference>
          <spring_stiffness>0</spring_stiffness>
        </dynamics>
        <use_parent_model_frame>1</use_parent_model_frame>
      </axis>
    </joint>
    <link name='rotor_6'>
      <pose frame=''>0 -0.3 -0.06 0 -0 -1.5708</pose>
      <inertial>
        <pose frame=''>0 0 0 0 -0 0</pose>
        <mass>0.0065</mass>
        <inertia>
          <ixx>2.21542e-06</ixx>
          <ixy>0</ixy>
          <ixz>0</ixz>
          <iyy>7.08147e-05</iyy>
          <iyz>0</iyz>
          <izz>7.29326e-05</izz>
        </inertia>
      </inertial>
      <collision name='rotor_6_collision'>
        <pose frame=''>0 0 0 0 -0 0</pose>
        <geometry>
          <cylinder>
            <length>0.005</length>
            <radius>0.1143</radius>
          </cylinder>
        </geometry>
        <surface>
          <contact>
            <ode/>
          </contact>
          <friction>
            <ode/>
          </friction>
        </surface>
      </collision>
      <visual name='rotor_6_visual'>
        <pose frame=''>0 0 0 0 -0 0</pose>
        <geometry>
          <mesh>
            <scale>0.1143 0.1143 0.1143</scale>
            <uri>model://rotors_description/meshes/propeller_cw.dae</uri>
          </mesh>
        </geometry>
        <material>
          <script>
            <name>Gazebo/Black</name>
            <uri>file://media/materials/scripts/gazebo.material</uri>
          </script>
        </material>
      </visual>
      <gravity>1</gravity>
      <velocity_decay/>
    </link>
    <joint name='rotor_6_joint' type='revolute'>
      <child>rotor_6</child>
      <parent>ouzel/tilt_unit_0</parent>
      <axis>
        <xyz>0 0 1</xyz>
        <limit>
          <lower>-1e+16</lower>
          <upper>1e+16</upper>
        </limit>
        <dynamics>
          <spring_reference>0</spring_reference>
          <spring_stiffness>0</spring_stiffness>
        </dynamics>
        <use_parent_model_frame>1</use_parent_model_frame>
      </axis>
    </joint>
    <link name='ouzel/tilt_unit_1'>
      <pose frame=''>0 0.3 0 0 -0 1.5708</pose>
      <inertial>
        <pose frame=''>0 0 0 0 -0 0</pose>
        <mass>0.277</mass>
        <inertia>
          <ixx>0.00034257</ixx>
          <ixy>0</ixy>
          <ixz>0</ixz>
          <iyy>0.0013205</iyy>
          <iyz>0</iyz>
          <izz>0.0010037</izz>
        </inertia>
      </inertial>
      <collision name='ouzel/tilt_unit_1_collision'>
        <pose frame=''>0 0 0 0 -0 0</pose>
        <geometry>
          <box>
            <size>0.005 0.005 0.005</size>
          </box>
        </geometry>
        <surface>
          <contact>
            <ode/>
          </contact>
          <friction>
            <ode/>
          </friction>
        </surface>
      </collision>
      <visual name='ouzel/tilt_unit_1_visual'>
        <pose frame=''>0 0 0 0 -0 0</pose>
        <geometry>
          <mesh>
            <scale>1 1 1</scale>
            <uri>model://rotors_description/meshes/omav/omav_tiltarm.dae</uri>
          </mesh>
        </geometry>
        <material>
          <script>
            <name>Gazebo/White</name>
            <uri>file://media/materials/scripts/gazebo.material</uri>
          </script>
        </material>
      </visual>
      <gravity>1</gravity>
      <velocity_decay/>
    </link>
    <joint name='ouzel/tilt_unit_1_revolutejoint' type='revolute'>
      <child>ouzel/tilt_unit_1</child>
      <parent>ouzel/base_link</parent>
      <axis>
        <xyz>0 1 0</xyz>
        <limit>
          <lower>-1e+16</lower>
          <upper>1e+16</upper>
        </limit>
        <dynamics>
          <spring_reference>0</spring_reference>
          <spring_stiffness>0</spring_stiffness>
        </dynamics>
        <use_parent_model_frame>1</use_parent_model_frame>
      </axis>
    </joint>
    <link name='rotor_1'>
      <pose frame=''>0 0.3 0.06 0 -0 1.5708</pose>
      <inertial>
        <pose frame=''>0 0 0 0 -0 0</pose>
        <mass>0.0065</mass>
        <inertia>
          <ixx>2.21542e-06</ixx>
          <ixy>0</ixy>
          <ixz>0</ixz>
          <iyy>7.08147e-05</iyy>
          <iyz>0</iyz>
          <izz>7.29326e-05</izz>
        </inertia>
      </inertial>
      <collision name='rotor_1_collision'>
        <pose frame=''>0 0 0 0 -0 0</pose>
        <geometry>
          <cylinder>
            <length>0.005</length>
            <radius>0.1143</radius>
          </cylinder>
        </geometry>
        <surface>
          <contact>
            <ode/>
          </contact>
          <friction>
            <ode/>
          </friction>
        </surface>
      </collision>
      <visual name='rotor_1_visual'>
        <pose frame=''>0 0 0 0 -0 0</pose>
        <geometry>
          <mesh>
            <scale>0.1143 0.1143 0.1143</scale>
            <uri>model://rotors_description/meshes/propeller_cw.dae</uri>
          </mesh>
        </geometry>
        <material>
          <script>
            <name>Gazebo/Black</name>
            <uri>file://media/materials/scripts/gazebo.material</uri>
          </script>
        </material>
      </visual>
      <gravity>1</gravity>
      <velocity_decay/>
    </link>
    <joint name='rotor_1_joint' type='revolute'>
      <child>rotor_1</child>
      <parent>ouzel/tilt_unit_1</parent>
      <axis>
        <xyz>0 0 1</xyz>
        <limit>
          <lower>-1e+16</lower>
          <upper>1e+16</upper>
        </limit>
        <dynamics>
          <spring_reference>0</spring_reference>
          <spring_stiffness>0</spring_stiffness>
        </dynamics>
        <use_parent_model_frame>1</use_parent_model_frame>
      </axis>
    </joint>
    <link name='rotor_7'>
      <pose frame=''>0 0.3 -0.06 0 -0 1.5708</pose>
      <inertial>
        <pose frame=''>0 0 0 0 -0 0</pose>
        <mass>0.0065</mass>
        <inertia>
          <ixx>2.21542e-06</ixx>
          <ixy>0</ixy>
          <ixz>0</ixz>
          <iyy>7.08147e-05</iyy>
          <iyz>0</iyz>
          <izz>7.29326e-05</izz>
        </inertia>
      </inertial>
      <collision name='rotor_7_collision'>
        <pose frame=''>0 0 0 0 -0 0</pose>
        <geometry>
          <cylinder>
            <length>0.005</length>
            <radius>0.1143</radius>
          </cylinder>
        </geometry>
        <surface>
          <contact>
            <ode/>
          </contact>
          <friction>
            <ode/>
          </friction>
        </surface>
      </collision>
      <visual name='rotor_7_visual'>
        <pose frame=''>0 0 0 0 -0 0</pose>
        <geometry>
          <mesh>
            <scale>0.1143 0.1143 0.1143</scale>
            <uri>model://rotors_description/meshes/propeller_ccw.dae</uri>
          </mesh>
        </geometry>
        <material>
          <script>
            <name>Gazebo/Black</name>
            <uri>file://media/materials/scripts/gazebo.material</uri>
          </script>
        </material>
      </visual>
      <gravity>1</gravity>
      <velocity_decay/>
    </link>
    <joint name='rotor_7_joint' type='revolute'>
      <child>rotor_7</child>
      <parent>ouzel/tilt_unit_1</parent>
      <axis>
        <xyz>0 0 1</xyz>
        <limit>
          <lower>-1e+16</lower>
          <upper>1e+16</upper>
        </limit>
        <dynamics>
          <spring_reference>0</spring_reference>
          <spring_stiffness>0</spring_stiffness>
        </dynamics>
        <use_parent_model_frame>1</use_parent_model_frame>
      </axis>
    </joint>
    <link name='ouzel/tilt_unit_2'>
      <pose frame=''>0.259808 0.15 0 0 -0 0.523599</pose>
      <inertial>
        <pose frame=''>0 0 0 0 -0 0</pose>
        <mass>0.277</mass>
        <inertia>
          <ixx>0.00034257</ixx>
          <ixy>0</ixy>
          <ixz>0</ixz>
          <iyy>0.0013205</iyy>
          <iyz>0</iyz>
          <izz>0.0010037</izz>
        </inertia>
      </inertial>
      <collision name='ouzel/tilt_unit_2_collision'>
        <pose frame=''>0 0 0 0 -0 0</pose>
        <geometry>
          <box>
            <size>0.005 0.005 0.005</size>
          </box>
        </geometry>
        <surface>
          <contact>
            <ode/>
          </contact>
          <friction>
            <ode/>
          </friction>
        </surface>
      </collision>
      <visual name='ouzel/tilt_unit_2_visual'>
        <pose frame=''>0 0 0 0 -0 0</pose>
        <geometry>
          <mesh>
            <scale>1 1 1</scale>
            <uri>model://rotors_description/meshes/omav/omav_tiltarm.dae</uri>
          </mesh>
        </geometry>
        <material>
          <script>
            <name>Gazebo/White</name>
            <uri>file://media/materials/scripts/gazebo.material</uri>
          </script>
        </material>
      </visual>
      <gravity>1</gravity>
      <velocity_decay/>
    </link>
    <joint name='ouzel/tilt_unit_2_revolutejoint' type='revolute'>
      <child>ouzel/tilt_unit_2</child>
      <parent>ouzel/base_link</parent>
      <axis>
        <xyz>0.866025 0.5 0</xyz>
        <limit>
          <lower>-1e+16</lower>
          <upper>1e+16</upper>
        </limit>
        <dynamics>
          <spring_reference>0</spring_reference>
          <spring_stiffness>0</spring_stiffness>
        </dynamics>
        <use_parent_model_frame>1</use_parent_model_frame>
      </axis>
    </joint>
    <link name='rotor_2'>
      <pose frame=''>0.259808 0.15 0.06 0 -0 0.523599</pose>
      <inertial>
        <pose frame=''>0 0 0 0 -0 0</pose>
        <mass>0.0065</mass>
        <inertia>
          <ixx>2.21542e-06</ixx>
          <ixy>0</ixy>
          <ixz>0</ixz>
          <iyy>7.08147e-05</iyy>
          <iyz>0</iyz>
          <izz>7.29326e-05</izz>
        </inertia>
      </inertial>
      <collision name='rotor_2_collision'>
        <pose frame=''>0 0 0 0 -0 0</pose>
        <geometry>
          <cylinder>
            <length>0.005</length>
            <radius>0.1143</radius>
          </cylinder>
        </geometry>
        <surface>
          <contact>
            <ode/>
          </contact>
          <friction>
            <ode/>
          </friction>
        </surface>
      </collision>
      <visual name='rotor_2_visual'>
        <pose frame=''>0 0 0 0 -0 0</pose>
        <geometry>
          <mesh>
            <scale>0.1143 0.1143 0.1143</scale>
            <uri>model://rotors_description/meshes/propeller_ccw.dae</uri>
          </mesh>
        </geometry>
        <material>
          <script>
            <name>Gazebo/Orange</name>
            <uri>file://media/materials/scripts/gazebo.material</uri>
          </script>
        </material>
      </visual>
      <gravity>1</gravity>
      <velocity_decay/>
    </link>
    <joint name='rotor_2_joint' type='revolute'>
      <child>rotor_2</child>
      <parent>ouzel/tilt_unit_2</parent>
      <axis>
        <xyz>0 0 1</xyz>
        <limit>
          <lower>-1e+16</lower>
          <upper>1e+16</upper>
        </limit>
        <dynamics>
          <spring_reference>0</spring_reference>
          <spring_stiffness>0</spring_stiffness>
        </dynamics>
        <use_parent_model_frame>1</use_parent_model_frame>
      </axis>
    </joint>
    <link name='rotor_8'>
      <pose frame=''>0.259808 0.15 -0.06 0 -0 0.523599</pose>
      <inertial>
        <pose frame=''>0 0 0 0 -0 0</pose>
        <mass>0.0065</mass>
        <inertia>
          <ixx>2.21542e-06</ixx>
          <ixy>0</ixy>
          <ixz>0</ixz>
          <iyy>7.08147e-05</iyy>
          <iyz>0</iyz>
          <izz>7.29326e-05</izz>
        </inertia>
      </inertial>
      <collision name='rotor_8_collision'>
        <pose frame=''>0 0 0 0 -0 0</pose>
        <geometry>
          <cylinder>
            <length>0.005</length>
            <radius>0.1143</radius>
          </cylinder>
        </geometry>
        <surface>
          <contact>
            <ode/>
          </contact>
          <friction>
            <ode/>
          </friction>
        </surface>
      </collision>
      <visual name='rotor_8_visual'>
        <pose frame=''>0 0 0 0 -0 0</pose>
        <geometry>
          <mesh>
            <scale>0.1143 0.1143 0.1143</scale>
            <uri>model://rotors_description/meshes/propeller_cw.dae</uri>
          </mesh>
        </geometry>
        <material>
          <script>
            <name>Gazebo/Orange</name>
            <uri>file://media/materials/scripts/gazebo.material</uri>
          </script>
        </material>
      </visual>
      <gravity>1</gravity>
      <velocity_decay/>
    </link>
    <joint name='rotor_8_joint' type='revolute'>
      <child>rotor_8</child>
      <parent>ouzel/tilt_unit_2</parent>
      <axis>
        <xyz>0 0 1</xyz>
        <limit>
          <lower>-1e+16</lower>
          <upper>1e+16</upper>
        </limit>
        <dynamics>
          <spring_reference>0</spring_reference>
          <spring_stiffness>0</spring_stiffness>
        </dynamics>
        <use_parent_model_frame>1</use_parent_model_frame>
      </axis>
    </joint>
    <link name='ouzel/tilt_unit_3'>
      <pose frame=''>-0.259808 -0.15 0 0 -0 -2.61799</pose>
      <inertial>
        <pose frame=''>0 0 0 0 -0 0</pose>
        <mass>0.277</mass>
        <inertia>
          <ixx>0.00034257</ixx>
          <ixy>0</ixy>
          <ixz>0</ixz>
          <iyy>0.0013205</iyy>
          <iyz>0</iyz>
          <izz>0.0010037</izz>
        </inertia>
      </inertial>
      <collision name='ouzel/tilt_unit_3_collision'>
        <pose frame=''>0 0 0 0 -0 0</pose>
        <geometry>
          <box>
            <size>0.005 0.005 0.005</size>
          </box>
        </geometry>
        <surface>
          <contact>
            <ode/>
          </contact>
          <friction>
            <ode/>
          </friction>
        </surface>
      </collision>
      <visual name='ouzel/tilt_unit_3_visual'>
        <pose frame=''>0 0 0 0 -0 0</pose>
        <geometry>
          <mesh>
            <scale>1 1 1</scale>
            <uri>model://rotors_description/meshes/omav/omav_tiltarm.dae</uri>
          </mesh>
        </geometry>
        <material>
          <script>
            <name>Gazebo/White</name>
            <uri>file://media/materials/scripts/gazebo.material</uri>
          </script>
        </material>
      </visual>
      <gravity>1</gravity>
      <velocity_decay/>
    </link>
    <joint name='ouzel/tilt_unit_3_revolutejoint' type='revolute'>
      <child>ouzel/tilt_unit_3</child>
      <parent>ouzel/base_link</parent>
      <axis>
        <xyz>-0.866025 -0.5 0</xyz>
        <limit>
          <lower>-1e+16</lower>
          <upper>1e+16</upper>
        </limit>
        <dynamics>
          <spring_reference>0</spring_reference>
          <spring_stiffness>0</spring_stiffness>
        </dynamics>
        <use_parent_model_frame>1</use_parent_model_frame>
      </axis>
    </joint>
    <link name='rotor_3'>
      <pose frame=''>-0.259808 -0.15 0.06 0 -0 -2.61799</pose>
      <inertial>
        <pose frame=''>0 0 0 0 -0 0</pose>
        <mass>0.0065</mass>
        <inertia>
          <ixx>2.21542e-06</ixx>
          <ixy>0</ixy>
          <ixz>0</ixz>
          <iyy>7.08147e-05</iyy>
          <iyz>0</iyz>
          <izz>7.29326e-05</izz>
        </inertia>
      </inertial>
      <collision name='rotor_3_collision'>
        <pose frame=''>0 0 0 0 -0 0</pose>
        <geometry>
          <cylinder>
            <length>0.005</length>
            <radius>0.1143</radius>
          </cylinder>
        </geometry>
        <surface>
          <contact>
            <ode/>
          </contact>
          <friction>
            <ode/>
          </friction>
        </surface>
      </collision>
      <visual name='rotor_3_visual'>
        <pose frame=''>0 0 0 0 -0 0</pose>
        <geometry>
          <mesh>
            <scale>0.1143 0.1143 0.1143</scale>
            <uri>model://rotors_description/meshes/propeller_cw.dae</uri>
          </mesh>
        </geometry>
        <material>
          <script>
            <name>Gazebo/DarkGrey</name>
            <uri>file://media/materials/scripts/gazebo.material</uri>
          </script>
        </material>
      </visual>
      <gravity>1</gravity>
      <velocity_decay/>
    </link>
    <joint name='rotor_3_joint' type='revolute'>
      <child>rotor_3</child>
      <parent>ouzel/tilt_unit_3</parent>
      <axis>
        <xyz>0 0 1</xyz>
        <limit>
          <lower>-1e+16</lower>
          <upper>1e+16</upper>
        </limit>
        <dynamics>
          <spring_reference>0</spring_reference>
          <spring_stiffness>0</spring_stiffness>
        </dynamics>
        <use_parent_model_frame>1</use_parent_model_frame>
      </axis>
    </joint>
    <link name='rotor_9'>
      <pose frame=''>-0.259808 -0.15 -0.06 0 -0 -2.61799</pose>
      <inertial>
        <pose frame=''>0 0 0 0 -0 0</pose>
        <mass>0.0065</mass>
        <inertia>
          <ixx>2.21542e-06</ixx>
          <ixy>0</ixy>
          <ixz>0</ixz>
          <iyy>7.08147e-05</iyy>
          <iyz>0</iyz>
          <izz>7.29326e-05</izz>
        </inertia>
      </inertial>
      <collision name='rotor_9_collision'>
        <pose frame=''>0 0 0 0 -0 0</pose>
        <geometry>
          <cylinder>
            <length>0.005</length>
            <radius>0.1143</radius>
          </cylinder>
        </geometry>
        <surface>
          <contact>
            <ode/>
          </contact>
          <friction>
            <ode/>
          </friction>
        </surface>
      </collision>
      <visual name='rotor_9_visual'>
        <pose frame=''>0 0 0 0 -0 0</pose>
        <geometry>
          <mesh>
            <scale>0.1143 0.1143 0.1143</scale>
            <uri>model://rotors_description/meshes/propeller_ccw.dae</uri>
          </mesh>
        </geometry>
        <material>
          <script>
            <name>Gazebo/DarkGrey</name>
            <uri>file://media/materials/scripts/gazebo.material</uri>
          </script>
        </material>
      </visual>
      <gravity>1</gravity>
      <velocity_decay/>
    </link>
    <joint name='rotor_9_joint' type='revolute'>
      <child>rotor_9</child>
      <parent>ouzel/tilt_unit_3</parent>
      <axis>
        <xyz>0 0 1</xyz>
        <limit>
          <lower>-1e+16</lower>
          <upper>1e+16</upper>
        </limit>
        <dynamics>
          <spring_reference>0</spring_reference>
          <spring_stiffness>0</spring_stiffness>
        </dynamics>
        <use_parent_model_frame>1</use_parent_model_frame>
      </axis>
    </joint>
    <link name='ouzel/tilt_unit_4'>
      <pose frame=''>0.259808 -0.15 0 0 -0 -0.523599</pose>
      <inertial>
        <pose frame=''>0 0 0 0 -0 0</pose>
        <mass>0.277</mass>
        <inertia>
          <ixx>0.00034257</ixx>
          <ixy>0</ixy>
          <ixz>0</ixz>
          <iyy>0.0013205</iyy>
          <iyz>0</iyz>
          <izz>0.0010037</izz>
        </inertia>
      </inertial>
      <collision name='ouzel/tilt_unit_4_collision'>
        <pose frame=''>0 0 0 0 -0 0</pose>
        <geometry>
          <box>
            <size>0.005 0.005 0.005</size>
          </box>
        </geometry>
        <surface>
          <contact>
            <ode/>
          </contact>
          <friction>
            <ode/>
          </friction>
        </surface>
      </collision>
      <visual name='ouzel/tilt_unit_4_visual'>
        <pose frame=''>0 0 0 0 -0 0</pose>
        <geometry>
          <mesh>
            <scale>1 1 1</scale>
            <uri>model://rotors_description/meshes/omav/omav_tiltarm.dae</uri>
          </mesh>
        </geometry>
        <material>
          <script>
            <name>Gazebo/White</name>
            <uri>file://media/materials/scripts/gazebo.material</uri>
          </script>
        </material>
      </visual>
      <gravity>1</gravity>
      <velocity_decay/>
    </link>
    <joint name='ouzel/tilt_unit_4_revolutejoint' type='revolute'>
      <child>ouzel/tilt_unit_4</child>
      <parent>ouzel/base_link</parent>
      <axis>
        <xyz>0.866025 -0.5 0</xyz>
        <limit>
          <lower>-1e+16</lower>
          <upper>1e+16</upper>
        </limit>
        <dynamics>
          <spring_reference>0</spring_reference>
          <spring_stiffness>0</spring_stiffness>
        </dynamics>
        <use_parent_model_frame>1</use_parent_model_frame>
      </axis>
    </joint>
    <link name='rotor_10'>
      <pose frame=''>0.259808 -0.15 -0.06 0 -0 -0.523599</pose>
      <inertial>
        <pose frame=''>0 0 0 0 -0 0</pose>
        <mass>0.0065</mass>
        <inertia>
          <ixx>2.21542e-06</ixx>
          <ixy>0</ixy>
          <ixz>0</ixz>
          <iyy>7.08147e-05</iyy>
          <iyz>0</iyz>
          <izz>7.29326e-05</izz>
        </inertia>
      </inertial>
      <collision name='rotor_10_collision'>
        <pose frame=''>0 0 0 0 -0 0</pose>
        <geometry>
          <cylinder>
            <length>0.005</length>
            <radius>0.1143</radius>
          </cylinder>
        </geometry>
        <surface>
          <contact>
            <ode/>
          </contact>
          <friction>
            <ode/>
          </friction>
        </surface>
      </collision>
      <visual name='rotor_10_visual'>
        <pose frame=''>0 0 0 0 -0 0</pose>
        <geometry>
          <mesh>
            <scale>0.1143 0.1143 0.1143</scale>
            <uri>model://rotors_description/meshes/propeller_ccw.dae</uri>
          </mesh>
        </geometry>
        <material>
          <script>
            <name>Gazebo/Orange</name>
            <uri>file://media/materials/scripts/gazebo.material</uri>
          </script>
        </material>
      </visual>
      <gravity>1</gravity>
      <velocity_decay/>
    </link>
    <joint name='rotor_10_joint' type='revolute'>
      <child>rotor_10</child>
      <parent>ouzel/tilt_unit_4</parent>
      <axis>
        <xyz>0 0 1</xyz>
        <limit>
          <lower>-1e+16</lower>
          <upper>1e+16</upper>
        </limit>
        <dynamics>
          <spring_reference>0</spring_reference>
          <spring_stiffness>0</spring_stiffness>
        </dynamics>
        <use_parent_model_frame>1</use_parent_model_frame>
      </axis>
    </joint>
    <link name='rotor_4'>
      <pose frame=''>0.259808 -0.15 0.06 0 -0 -0.523599</pose>
      <inertial>
        <pose frame=''>0 0 0 0 -0 0</pose>
        <mass>0.0065</mass>
        <inertia>
          <ixx>2.21542e-06</ixx>
          <ixy>0</ixy>
          <ixz>0</ixz>
          <iyy>7.08147e-05</iyy>
          <iyz>0</iyz>
          <izz>7.29326e-05</izz>
        </inertia>
      </inertial>
      <collision name='rotor_4_collision'>
        <pose frame=''>0 0 0 0 -0 0</pose>
        <geometry>
          <cylinder>
            <length>0.005</length>
            <radius>0.1143</radius>
          </cylinder>
        </geometry>
        <surface>
          <contact>
            <ode/>
          </contact>
          <friction>
            <ode/>
          </friction>
        </surface>
      </collision>
      <visual name='rotor_4_visual'>
        <pose frame=''>0 0 0 0 -0 0</pose>
        <geometry>
          <mesh>
            <scale>0.1143 0.1143 0.1143</scale>
            <uri>model://rotors_description/meshes/propeller_cw.dae</uri>
          </mesh>
        </geometry>
        <material>
          <script>
            <name>Gazebo/Orange</name>
            <uri>file://media/materials/scripts/gazebo.material</uri>
          </script>
        </material>
      </visual>
      <gravity>1</gravity>
      <velocity_decay/>
    </link>
    <joint name='rotor_4_joint' type='revolute'>
      <child>rotor_4</child>
      <parent>ouzel/tilt_unit_4</parent>
      <axis>
        <xyz>0 0 1</xyz>
        <limit>
          <lower>-1e+16</lower>
          <upper>1e+16</upper>
        </limit>
        <dynamics>
          <spring_reference>0</spring_reference>
          <spring_stiffness>0</spring_stiffness>
        </dynamics>
        <use_parent_model_frame>1</use_parent_model_frame>
      </axis>
    </joint>
    <link name='ouzel/tilt_unit_5'>
      <pose frame=''>-0.259808 0.15 0 0 -0 2.61799</pose>
      <inertial>
        <pose frame=''>0 0 0 0 -0 0</pose>
        <mass>0.277</mass>
        <inertia>
          <ixx>0.00034257</ixx>
          <ixy>0</ixy>
          <ixz>0</ixz>
          <iyy>0.0013205</iyy>
          <iyz>0</iyz>
          <izz>0.0010037</izz>
        </inertia>
      </inertial>
      <collision name='ouzel/tilt_unit_5_collision'>
        <pose frame=''>0 0 0 0 -0 0</pose>
        <geometry>
          <box>
            <size>0.005 0.005 0.005</size>
          </box>
        </geometry>
        <surface>
          <contact>
            <ode/>
          </contact>
          <friction>
            <ode/>
          </friction>
        </surface>
      </collision>
      <visual name='ouzel/tilt_unit_5_visual'>
        <pose frame=''>0 0 0 0 -0 0</pose>
        <geometry>
          <mesh>
            <scale>1 1 1</scale>
            <uri>model://rotors_description/meshes/omav/omav_tiltarm.dae</uri>
          </mesh>
        </geometry>
        <material>
          <script>
            <name>Gazebo/White</name>
            <uri>file://media/materials/scripts/gazebo.material</uri>
          </script>
        </material>
      </visual>
      <gravity>1</gravity>
      <velocity_decay/>
    </link>
    <joint name='ouzel/tilt_unit_5_revolutejoint' type='revolute'>
      <child>ouzel/tilt_unit_5</child>
      <parent>ouzel/base_link</parent>
      <axis>
        <xyz>-0.866025 0.5 0</xyz>
        <limit>
          <lower>-1e+16</lower>
          <upper>1e+16</upper>
        </limit>
        <dynamics>
          <spring_reference>0</spring_reference>
          <spring_stiffness>0</spring_stiffness>
        </dynamics>
        <use_parent_model_frame>1</use_parent_model_frame>
      </axis>
    </joint>
    <link name='rotor_11'>
      <pose frame=''>-0.259808 0.15 -0.06 0 -0 2.61799</pose>
      <inertial>
        <pose frame=''>0 0 0 0 -0 0</pose>
        <mass>0.0065</mass>
        <inertia>
          <ixx>2.21542e-06</ixx>
          <ixy>0</ixy>
          <ixz>0</ixz>
          <iyy>7.08147e-05</iyy>
          <iyz>0</iyz>
          <izz>7.29326e-05</izz>
        </inertia>
      </inertial>
      <collision name='rotor_11_collision'>
        <pose frame=''>0 0 0 0 -0 0</pose>
        <geometry>
          <cylinder>
            <length>0.005</length>
            <radius>0.1143</radius>
          </cylinder>
        </geometry>
        <surface>
          <contact>
            <ode/>
          </contact>
          <friction>
            <ode/>
          </friction>
        </surface>
      </collision>
      <visual name='rotor_11_visual'>
        <pose frame=''>0 0 0 0 -0 0</pose>
        <geometry>
          <mesh>
            <scale>0.1143 0.1143 0.1143</scale>
            <uri>model://rotors_description/meshes/propeller_cw.dae</uri>
          </mesh>
        </geometry>
        <material>
          <script>
            <name>Gazebo/DarkGrey</name>
            <uri>file://media/materials/scripts/gazebo.material</uri>
          </script>
        </material>
      </visual>
      <gravity>1</gravity>
      <velocity_decay/>
    </link>
    <joint name='rotor_11_joint' type='revolute'>
      <child>rotor_11</child>
      <parent>ouzel/tilt_unit_5</parent>
      <axis>
        <xyz>0 0 1</xyz>
        <limit>
          <lower>-1e+16</lower>
          <upper>1e+16</upper>
        </limit>
        <dynamics>
          <spring_reference>0</spring_reference>
          <spring_stiffness>0</spring_stiffness>
        </dynamics>
        <use_parent_model_frame>1</use_parent_model_frame>
      </axis>
    </joint>
    <link name='rotor_5'>
      <pose frame=''>-0.259808 0.15 0.06 0 -0 2.61799</pose>
      <inertial>
        <pose frame=''>0 0 0 0 -0 0</pose>
        <mass>0.0065</mass>
        <inertia>
          <ixx>2.21542e-06</ixx>
          <ixy>0</ixy>
          <ixz>0</ixz>
          <iyy>7.08147e-05</iyy>
          <iyz>0</iyz>
          <izz>7.29326e-05</izz>
        </inertia>
      </inertial>
      <collision name='rotor_5_collision'>
        <pose frame=''>0 0 0 0 -0 0</pose>
        <geometry>
          <cylinder>
            <length>0.005</length>
            <radius>0.1143</radius>
          </cylinder>
        </geometry>
        <surface>
          <contact>
            <ode/>
          </contact>
          <friction>
            <ode/>
          </friction>
        </surface>
      </collision>
      <visual name='rotor_5_visual'>
        <pose frame=''>0 0 0 0 -0 0</pose>
        <geometry>
          <mesh>
            <scale>0.1143 0.1143 0.1143</scale>
            <uri>model://rotors_description/meshes/propeller_ccw.dae</uri>
          </mesh>
        </geometry>
        <material>
          <script>
            <name>Gazebo/DarkGrey</name>
            <uri>file://media/materials/scripts/gazebo.material</uri>
          </script>
        </material>
      </visual>
      <gravity>1</gravity>
      <velocity_decay/>
    </link>
    <joint name='rotor_5_joint' type='revolute'>
      <child>rotor_5</child>
      <parent>ouzel/tilt_unit_5</parent>
      <axis>
        <xyz>0 0 1</xyz>
        <limit>
          <lower>-1e+16</lower>
          <upper>1e+16</upper>
        </limit>
        <dynamics>
          <spring_reference>0</spring_reference>
          <spring_stiffness>0</spring_stiffness>
        </dynamics>
        <use_parent_model_frame>1</use_parent_model_frame>
      </axis>
    </joint>
    <plugin name='multirotor_base_plugin' filename='librotors_gazebo_multirotor_base_plugin.so'>
      <robotNamespace>ouzel</robotNamespace>
      <linkName>ouzel/base_link</linkName>
      <rotorVelocitySlowdownSim>10</rotorVelocitySlowdownSim>
    </plugin>
    <plugin name='right_tilt_unit_model' filename='librotors_gazebo_motor_model.so'>
      <robotNamespace>ouzel</robotNamespace>
      <jointName>ouzel/tilt_unit_0_revolutejoint</jointName>
      <linkName>ouzel/tilt_unit_0</linkName>
      <turningDirection>ccw</turningDirection>
      <motorType>position</motorType>
      <commandSubTopic>/gazebo/command/motor_speed</commandSubTopic>
      <motorNumber>12</motorNumber>
      <motorSpeedPubTopic>/tilt_motor_0/velocity</motorSpeedPubTopic>
      <motorPositionPubTopic>/tilt_motor_0/position</motorPositionPubTopic>
      <joint_control_pid>
        <p>0.11</p>
        <i>0.0</i>
        <d>0.01</d>
        <iMax>1.0</iMax>
        <iMin>-1.0</iMin>
        <cmdMax>2.0</cmdMax>
        <cmdMin>-2.0</cmdMin>
      </joint_control_pid>
    </plugin>
    <plugin name='right_upper_motor_model' filename='librotors_gazebo_motor_model.so'>
      <robotNamespace>ouzel</robotNamespace>
      <jointName>rotor_0_joint</jointName>
      <linkName>rotor_0</linkName>
      <turningDirection>ccw</turningDirection>
      <timeConstantUp>0.0125</timeConstantUp>
      <timeConstantDown>0.025</timeConstantDown>
      <maxRotVelocity>1700</maxRotVelocity>
      <motorConstant>7.2e-06</motorConstant>
      <momentConstant>0.015</momentConstant>
      <commandSubTopic>/gazebo/command/motor_speed</commandSubTopic>
      <motorNumber>0</motorNumber>
      <rotorDragCoefficient>8.06428e-05</rotorDragCoefficient>
      <rollingMomentCoefficient>1e-06</rollingMomentCoefficient>
      <motorSpeedPubTopic>/motor_speed/0_upper</motorSpeedPubTopic>
      <rotorVelocitySlowdownSim>10</rotorVelocitySlowdownSim>
    </plugin>
    <plugin name='right_lower_motor_model' filename='librotors_gazebo_motor_model.so'>
      <robotNamespace>ouzel</robotNamespace>
      <jointName>rotor_6_joint</jointName>
      <linkName>rotor_6</linkName>
      <turningDirection>cw</turningDirection>
      <timeConstantUp>0.0125</timeConstantUp>
      <timeConstantDown>0.025</timeConstantDown>
      <maxRotVelocity>1700</maxRotVelocity>
      <motorConstant>7.2e-06</motorConstant>
      <momentConstant>0.005</momentConstant>
      <commandSubTopic>/gazebo/command/motor_speed</commandSubTopic>
      <motorNumber>6</motorNumber>
      <rotorDragCoefficient>8.06428e-05</rotorDragCoefficient>
      <rollingMomentCoefficient>1e-06</rollingMomentCoefficient>
      <motorSpeedPubTopic>/motor_speed/0_lower</motorSpeedPubTopic>
      <rotorVelocitySlowdownSim>10</rotorVelocitySlowdownSim>
    </plugin>
    <plugin name='left_tilt_unit_model' filename='librotors_gazebo_motor_model.so'>
      <robotNamespace>ouzel</robotNamespace>
      <jointName>ouzel/tilt_unit_1_revolutejoint</jointName>
      <linkName>ouzel/tilt_unit_1</linkName>
      <turningDirection>ccw</turningDirection>
      <motorType>position</motorType>
      <commandSubTopic>/gazebo/command/motor_speed</commandSubTopic>
      <motorNumber>13</motorNumber>
      <motorSpeedPubTopic>/tilt_motor_1/velocity</motorSpeedPubTopic>
      <motorPositionPubTopic>/tilt_motor_1/position</motorPositionPubTopic>
      <joint_control_pid>
        <p>0.11</p>
        <i>0.0</i>
        <d>0.01</d>
        <iMax>1.0</iMax>
        <iMin>-1.0</iMin>
        <cmdMax>2.0</cmdMax>
        <cmdMin>-2.0</cmdMin>
      </joint_control_pid>
    </plugin>
    <plugin name='left_upper_motor_model' filename='librotors_gazebo_motor_model.so'>
      <robotNamespace>ouzel</robotNamespace>
      <jointName>rotor_1_joint</jointName>
      <linkName>rotor_1</linkName>
      <turningDirection>cw</turningDirection>
      <timeConstantUp>0.0125</timeConstantUp>
      <timeConstantDown>0.025</timeConstantDown>
      <maxRotVelocity>1700</maxRotVelocity>
      <motorConstant>7.2e-06</motorConstant>
      <momentConstant>0.015</momentConstant>
      <commandSubTopic>/gazebo/command/motor_speed</commandSubTopic>
      <motorNumber>1</motorNumber>
      <rotorDragCoefficient>8.06428e-05</rotorDragCoefficient>
      <rollingMomentCoefficient>1e-06</rollingMomentCoefficient>
      <motorSpeedPubTopic>/motor_speed/1_upper</motorSpeedPubTopic>
      <rotorVelocitySlowdownSim>10</rotorVelocitySlowdownSim>
    </plugin>
    <plugin name='left_lower_motor_model' filename='librotors_gazebo_motor_model.so'>
      <robotNamespace>ouzel</robotNamespace>
      <jointName>rotor_7_joint</jointName>
      <linkName>rotor_7</linkName>
      <turningDirection>ccw</turningDirection>
      <timeConstantUp>0.0125</timeConstantUp>
      <timeConstantDown>0.025</timeConstantDown>
      <maxRotVelocity>1700</maxRotVelocity>
      <motorConstant>7.2e-06</motorConstant>
      <momentConstant>0.005</momentConstant>
      <commandSubTopic>/gazebo/command/motor_speed</commandSubTopic>
      <motorNumber>7</motorNumber>
      <rotorDragCoefficient>8.06428e-05</rotorDragCoefficient>
      <rollingMomentCoefficient>1e-06</rollingMomentCoefficient>
      <motorSpeedPubTopic>/motor_speed/1_lower</motorSpeedPubTopic>
      <rotorVelocitySlowdownSim>10</rotorVelocitySlowdownSim>
    </plugin>
    <plugin name='front_left_tilt_unit_model' filename='librotors_gazebo_motor_model.so'>
      <robotNamespace>ouzel</robotNamespace>
      <jointName>ouzel/tilt_unit_2_revolutejoint</jointName>
      <linkName>ouzel/tilt_unit_2</linkName>
      <turningDirection>ccw</turningDirection>
      <motorType>position</motorType>
      <commandSubTopic>/gazebo/command/motor_speed</commandSubTopic>
      <motorNumber>14</motorNumber>
      <motorSpeedPubTopic>/tilt_motor_2/velocity</motorSpeedPubTopic>
      <motorPositionPubTopic>/tilt_motor_2/position</motorPositionPubTopic>
      <joint_control_pid>
        <p>0.11</p>
        <i>0.0</i>
        <d>0.01</d>
        <iMax>1.0</iMax>
        <iMin>-1.0</iMin>
        <cmdMax>2.0</cmdMax>
        <cmdMin>-2.0</cmdMin>
      </joint_control_pid>
    </plugin>
    <plugin name='front_left_upper_motor_model' filename='librotors_gazebo_motor_model.so'>
      <robotNamespace>ouzel</robotNamespace>
      <jointName>rotor_2_joint</jointName>
      <linkName>rotor_2</linkName>
      <turningDirection>ccw</turningDirection>
      <timeConstantUp>0.0125</timeConstantUp>
      <timeConstantDown>0.025</timeConstantDown>
      <maxRotVelocity>1700</maxRotVelocity>
      <motorConstant>7.2e-06</motorConstant>
      <momentConstant>0.015</momentConstant>
      <commandSubTopic>/gazebo/command/motor_speed</commandSubTopic>
      <motorNumber>2</motorNumber>
      <rotorDragCoefficient>8.06428e-05</rotorDragCoefficient>
      <rollingMomentCoefficient>1e-06</rollingMomentCoefficient>
      <motorSpeedPubTopic>/motor_speed/2_upper</motorSpeedPubTopic>
      <rotorVelocitySlowdownSim>10</rotorVelocitySlowdownSim>
    </plugin>
    <plugin name='front_left_lower_motor_model' filename='librotors_gazebo_motor_model.so'>
      <robotNamespace>ouzel</robotNamespace>
      <jointName>rotor_8_joint</jointName>
      <linkName>rotor_8</linkName>
      <turningDirection>cw</turningDirection>
      <timeConstantUp>0.0125</timeConstantUp>
      <timeConstantDown>0.025</timeConstantDown>
      <maxRotVelocity>1700</maxRotVelocity>
      <motorConstant>7.2e-06</motorConstant>
      <momentConstant>0.005</momentConstant>
      <commandSubTopic>/gazebo/command/motor_speed</commandSubTopic>
      <motorNumber>8</motorNumber>
      <rotorDragCoefficient>8.06428e-05</rotorDragCoefficient>
      <rollingMomentCoefficient>1e-06</rollingMomentCoefficient>
      <motorSpeedPubTopic>/motor_speed/2_lower</motorSpeedPubTopic>
      <rotorVelocitySlowdownSim>10</rotorVelocitySlowdownSim>
    </plugin>
    <plugin name='back_right_tilt_unit_model' filename='librotors_gazebo_motor_model.so'>
      <robotNamespace>ouzel</robotNamespace>
      <jointName>ouzel/tilt_unit_3_revolutejoint</jointName>
      <linkName>ouzel/tilt_unit_3</linkName>
      <turningDirection>ccw</turningDirection>
      <motorType>position</motorType>
      <commandSubTopic>/gazebo/command/motor_speed</commandSubTopic>
      <motorNumber>15</motorNumber>
      <motorSpeedPubTopic>/tilt_motor_3/velocity</motorSpeedPubTopic>
      <motorPositionPubTopic>/tilt_motor_3/position</motorPositionPubTopic>
      <joint_control_pid>
        <p>0.11</p>
        <i>0.0</i>
        <d>0.01</d>
        <iMax>1.0</iMax>
        <iMin>-1.0</iMin>
        <cmdMax>2.0</cmdMax>
        <cmdMin>-2.0</cmdMin>
      </joint_control_pid>
    </plugin>
    <plugin name='back_right_upper_motor_model' filename='librotors_gazebo_motor_model.so'>
      <robotNamespace>ouzel</robotNamespace>
      <jointName>rotor_3_joint</jointName>
      <linkName>rotor_3</linkName>
      <turningDirection>cw</turningDirection>
      <timeConstantUp>0.0125</timeConstantUp>
      <timeConstantDown>0.025</timeConstantDown>
      <maxRotVelocity>1700</maxRotVelocity>
      <motorConstant>7.2e-06</motorConstant>
      <momentConstant>0.015</momentConstant>
      <commandSubTopic>/gazebo/command/motor_speed</commandSubTopic>
      <motorNumber>3</motorNumber>
      <rotorDragCoefficient>8.06428e-05</rotorDragCoefficient>
      <rollingMomentCoefficient>1e-06</rollingMomentCoefficient>
      <motorSpeedPubTopic>/motor_speed/3_upper</motorSpeedPubTopic>
      <rotorVelocitySlowdownSim>10</rotorVelocitySlowdownSim>
    </plugin>
    <plugin name='back_right_lower_motor_model' filename='librotors_gazebo_motor_model.so'>
      <robotNamespace>ouzel</robotNamespace>
      <jointName>rotor_9_joint</jointName>
      <linkName>rotor_9</linkName>
      <turningDirection>ccw</turningDirection>
      <timeConstantUp>0.0125</timeConstantUp>
      <timeConstantDown>0.025</timeConstantDown>
      <maxRotVelocity>1700</maxRotVelocity>
      <motorConstant>7.2e-06</motorConstant>
      <momentConstant>0.005</momentConstant>
      <commandSubTopic>/gazebo/command/motor_speed</commandSubTopic>
      <motorNumber>9</motorNumber>
      <rotorDragCoefficient>8.06428e-05</rotorDragCoefficient>
      <rollingMomentCoefficient>1e-06</rollingMomentCoefficient>
      <motorSpeedPubTopic>/motor_speed/3_lower</motorSpeedPubTopic>
      <rotorVelocitySlowdownSim>10</rotorVelocitySlowdownSim>
    </plugin>
    <plugin name='front_right_tilt_unit_model' filename='librotors_gazebo_motor_model.so'>
      <robotNamespace>ouzel</robotNamespace>
      <jointName>ouzel/tilt_unit_4_revolutejoint</jointName>
      <linkName>ouzel/tilt_unit_4</linkName>
      <turningDirection>ccw</turningDirection>
      <motorType>position</motorType>
      <commandSubTopic>/gazebo/command/motor_speed</commandSubTopic>
      <motorNumber>16</motorNumber>
      <motorSpeedPubTopic>/tilt_motor_4/velocity</motorSpeedPubTopic>
      <motorPositionPubTopic>/tilt_motor_4/position</motorPositionPubTopic>
      <joint_control_pid>
        <p>0.11</p>
        <i>0.0</i>
        <d>0.01</d>
        <iMax>1.0</iMax>
        <iMin>-1.0</iMin>
        <cmdMax>2.0</cmdMax>
        <cmdMin>-2.0</cmdMin>
      </joint_control_pid>
    </plugin>
    <plugin name='front_right_upper_motor_model' filename='librotors_gazebo_motor_model.so'>
      <robotNamespace>ouzel</robotNamespace>
      <jointName>rotor_4_joint</jointName>
      <linkName>rotor_4</linkName>
      <turningDirection>cw</turningDirection>
      <timeConstantUp>0.0125</timeConstantUp>
      <timeConstantDown>0.025</timeConstantDown>
      <maxRotVelocity>1700</maxRotVelocity>
      <motorConstant>7.2e-06</motorConstant>
      <momentConstant>0.015</momentConstant>
      <commandSubTopic>/gazebo/command/motor_speed</commandSubTopic>
      <motorNumber>4</motorNumber>
      <rotorDragCoefficient>8.06428e-05</rotorDragCoefficient>
      <rollingMomentCoefficient>1e-06</rollingMomentCoefficient>
      <motorSpeedPubTopic>/motor_speed/4_upper</motorSpeedPubTopic>
      <rotorVelocitySlowdownSim>10</rotorVelocitySlowdownSim>
    </plugin>
    <plugin name='front_right_lower_motor_model' filename='librotors_gazebo_motor_model.so'>
      <robotNamespace>ouzel</robotNamespace>
      <jointName>rotor_10_joint</jointName>
      <linkName>rotor_10</linkName>
      <turningDirection>ccw</turningDirection>
      <timeConstantUp>0.0125</timeConstantUp>
      <timeConstantDown>0.025</timeConstantDown>
      <maxRotVelocity>1700</maxRotVelocity>
      <motorConstant>7.2e-06</motorConstant>
      <momentConstant>0.005</momentConstant>
      <commandSubTopic>/gazebo/command/motor_speed</commandSubTopic>
      <motorNumber>10</motorNumber>
      <rotorDragCoefficient>8.06428e-05</rotorDragCoefficient>
      <rollingMomentCoefficient>1e-06</rollingMomentCoefficient>
      <motorSpeedPubTopic>/motor_speed/4_lower</motorSpeedPubTopic>
      <rotorVelocitySlowdownSim>10</rotorVelocitySlowdownSim>
    </plugin>
    <plugin name='back_left_tilt_unit_model' filename='librotors_gazebo_motor_model.so'>
      <robotNamespace>ouzel</robotNamespace>
      <jointName>ouzel/tilt_unit_5_revolutejoint</jointName>
      <linkName>ouzel/tilt_unit_5</linkName>
      <turningDirection>ccw</turningDirection>
      <motorType>position</motorType>
      <commandSubTopic>/gazebo/command/motor_speed</commandSubTopic>
      <motorNumber>17</motorNumber>
      <motorSpeedPubTopic>/tilt_motor_5/velocity</motorSpeedPubTopic>
      <motorPositionPubTopic>/tilt_motor_5/position</motorPositionPubTopic>
      <joint_control_pid>
        <p>0.11</p>
        <i>0.0</i>
        <d>0.01</d>
        <iMax>1.0</iMax>
        <iMin>-1.0</iMin>
        <cmdMax>2.0</cmdMax>
        <cmdMin>-2.0</cmdMin>
      </joint_control_pid>
    </plugin>
    <plugin name='back_left_upper_motor_model' filename='librotors_gazebo_motor_model.so'>
      <robotNamespace>ouzel</robotNamespace>
      <jointName>rotor_5_joint</jointName>
      <linkName>rotor_5</linkName>
      <turningDirection>ccw</turningDirection>
      <timeConstantUp>0.0125</timeConstantUp>
      <timeConstantDown>0.025</timeConstantDown>
      <maxRotVelocity>1700</maxRotVelocity>
      <motorConstant>7.2e-06</motorConstant>
      <momentConstant>0.015</momentConstant>
      <commandSubTopic>/gazebo/command/motor_speed</commandSubTopic>
      <motorNumber>5</motorNumber>
      <rotorDragCoefficient>8.06428e-05</rotorDragCoefficient>
      <rollingMomentCoefficient>1e-06</rollingMomentCoefficient>
      <motorSpeedPubTopic>/motor_speed/5_upper</motorSpeedPubTopic>
      <rotorVelocitySlowdownSim>10</rotorVelocitySlowdownSim>
    </plugin>
    <plugin name='back_left_lower_motor_model' filename='librotors_gazebo_motor_model.so'>
      <robotNamespace>ouzel</robotNamespace>
      <jointName>rotor_11_joint</jointName>
      <linkName>rotor_11</linkName>
      <turningDirection>cw</turningDirection>
      <timeConstantUp>0.0125</timeConstantUp>
      <timeConstantDown>0.025</timeConstantDown>
      <maxRotVelocity>1700</maxRotVelocity>
      <motorConstant>7.2e-06</motorConstant>
      <momentConstant>0.005</momentConstant>
      <commandSubTopic>/gazebo/command/motor_speed</commandSubTopic>
      <motorNumber>11</motorNumber>
      <rotorDragCoefficient>8.06428e-05</rotorDragCoefficient>
      <rollingMomentCoefficient>1e-06</rollingMomentCoefficient>
      <motorSpeedPubTopic>/motor_speed/5_lower</motorSpeedPubTopic>
      <rotorVelocitySlowdownSim>10</rotorVelocitySlowdownSim>
    </plugin>
    <plugin name='mavlink_interface' filename='librotors_gazebo_mavlink_interface.so'>
      <robotNamespace>ouzel</robotNamespace>
      <imu_rate>102</imu_rate>
      <imuSubTopic>/imu</imuSubTopic>
      <mavlink_addr>INADDR_ANY</mavlink_addr>
      <mavlink_udp_port>14560</mavlink_udp_port>
      <motorSpeedCommandPubTopic>/gazebo/command/motor_speed</motorSpeedCommandPubTopic>
      <control_channels>
        <channel name='rotor0'>
          <input_index>0</input_index>
          <input_offset>0</input_offset>
          <input_scaling>1700</input_scaling>
          <zero_position_disarmed>0</zero_position_disarmed>
          <zero_position_armed>100</zero_position_armed>
          <joint_control_type>velocity</joint_control_type>
        </channel>
        <channel name='rotor1'>
          <input_index>1</input_index>
          <input_offset>0</input_offset>
          <input_scaling>1700</input_scaling>
          <zero_position_disarmed>0</zero_position_disarmed>
          <zero_position_armed>100</zero_position_armed>
          <joint_control_type>velocity</joint_control_type>
        </channel>
        <channel name='rotor2'>
          <input_index>2</input_index>
          <input_offset>0</input_offset>
          <input_scaling>1700</input_scaling>
          <zero_position_disarmed>0</zero_position_disarmed>
          <zero_position_armed>100</zero_position_armed>
          <joint_control_type>velocity</joint_control_type>
        </channel>
        <channel name='rotor3'>
          <input_index>3</input_index>
          <input_offset>0</input_offset>
          <input_scaling>1700</input_scaling>
          <zero_position_disarmed>0</zero_position_disarmed>
          <zero_position_armed>100</zero_position_armed>
          <joint_control_type>velocity</joint_control_type>
        </channel>
        <channel name='rotor4'>
          <input_index>4</input_index>
          <input_offset>0</input_offset>
          <input_scaling>1700</input_scaling>
          <zero_position_disarmed>0</zero_position_disarmed>
          <zero_position_armed>100</zero_position_armed>
          <joint_control_type>velocity</joint_control_type>
        </channel>
        <channel name='rotor5'>
          <input_index>5</input_index>
          <input_offset>0</input_offset>
          <input_scaling>1700</input_scaling>
          <zero_position_disarmed>0</zero_position_disarmed>
          <zero_position_armed>100</zero_position_armed>
          <joint_control_type>velocity</joint_control_type>
        </channel>
        <channel name='rotor6'>
          <input_index>6</input_index>
          <input_offset>0</input_offset>
          <input_scaling>1700</input_scaling>
          <zero_position_disarmed>0</zero_position_disarmed>
          <zero_position_armed>100</zero_position_armed>
          <joint_control_type>velocity</joint_control_type>
        </channel>
        <channel name='rotor7'>
          <input_index>7</input_index>
          <input_offset>0</input_offset>
          <input_scaling>1700</input_scaling>
          <zero_position_disarmed>0</zero_position_disarmed>
          <zero_position_armed>100</zero_position_armed>
          <joint_control_type>velocity</joint_control_type>
        </channel>
        <channel name='rotor8'>
          <input_index>8</input_index>
          <input_offset>0</input_offset>
          <input_scaling>1700</input_scaling>
          <zero_position_disarmed>0</zero_position_disarmed>
          <zero_position_armed>100</zero_position_armed>
          <joint_control_type>velocity</joint_control_type>
        </channel>
        <channel name='rotor9'>
          <input_index>9</input_index>
          <input_offset>0</input_offset>
          <input_scaling>1700</input_scaling>
          <zero_position_disarmed>0</zero_position_disarmed>
          <zero_position_armed>100</zero_position_armed>
          <joint_control_type>velocity</joint_control_type>
        </channel>
        <channel name='rotor10'>
          <input_index>10</input_index>
          <input_offset>0</input_offset>
          <input_scaling>1700</input_scaling>
          <zero_position_disarmed>0</zero_position_disarmed>
          <zero_position_armed>100</zero_position_armed>
          <joint_control_type>velocity</joint_control_type>
        </channel>
        <channel name='rotor11'>
          <input_index>11</input_index>
          <input_offset>0</input_offset>
          <input_scaling>1700</input_scaling>
          <zero_position_disarmed>0</zero_position_disarmed>
          <zero_position_armed>100</zero_position_armed>
          <joint_control_type>velocity</joint_control_type>
        </channel>
        <channel name='tilt_unit0'>
          <input_index>12</input_index>
          <input_offset>0</input_offset>
          <input_scaling>31.4159</input_scaling>
          <zero_position_disarmed>0</zero_position_disarmed>
          <zero_position_armed>0</zero_position_armed>
          <joint_control_type>position</joint_control_type>
        </channel>
        <channel name='tilt_unit1'>
          <input_index>13</input_index>
          <input_offset>0</input_offset>
          <input_scaling>31.4159</input_scaling>
          <zero_position_disarmed>0</zero_position_disarmed>
          <zero_position_armed>0</zero_position_armed>
          <joint_control_type>position</joint_control_type>
        </channel>
        <channel name='tilt_unit2'>
          <input_index>14</input_index>
          <input_offset>0</input_offset>
          <input_scaling>31.4159</input_scaling>
          <zero_position_disarmed>0</zero_position_disarmed>
          <zero_position_armed>0</zero_position_armed>
          <joint_control_type>position</joint_control_type>
        </channel>
        <channel name='tilt_unit3'>
          <input_index>15</input_index>
          <input_offset>0</input_offset>
          <input_scaling>31.4159</input_scaling>
          <zero_position_disarmed>0</zero_position_disarmed>
          <zero_position_armed>0</zero_position_armed>
          <joint_control_type>position</joint_control_type>
        </channel>
        <channel name='tilt_unit4'>
          <input_index>16</input_index>
          <input_offset>0</input_offset>
          <input_scaling>31.4159</input_scaling>
          <zero_position_disarmed>0</zero_position_disarmed>
          <zero_position_armed>0</zero_position_armed>
          <joint_control_type>position</joint_control_type>
        </channel>
        <channel name='tilt_unit5'>
          <input_index>17</input_index>
          <input_offset>0</input_offset>
          <input_scaling>31.4159</input_scaling>
          <zero_position_disarmed>0</zero_position_disarmed>
          <zero_position_armed>0</zero_position_armed>
          <joint_control_type>position</joint_control_type>
        </channel>
      </control_channels>
    </plugin>
    <plugin name='controller_interface' filename='librotors_gazebo_controller_interface.so'>
      <robotNamespace>ouzel</robotNamespace>
      <commandAttitudeThrustSubTopic>command/attitude</commandAttitudeThrustSubTopic>
      <commandRateThrustSubTopic>command/rate</commandRateThrustSubTopic>
      <commandMotorSpeedSubTopic>command/motor_speed</commandMotorSpeedSubTopic>
      <imuSubTopic>imu</imuSubTopic>
      <motorSpeedCommandPubTopic>gazebo/command/motor_speed</motorSpeedCommandPubTopic>
    </plugin>
    <plugin name='rotors_gazebo_imu_plugin' filename='librotors_gazebo_imu_plugin.so'>
      <robotNamespace>ouzel</robotNamespace>
      <linkName>ouzel/imu_link</linkName>
      <imuTopic>imu</imuTopic>
      <gyroscopeNoiseDensity>5.366563e-05</gyroscopeNoiseDensity>
      <gyroscopeRandomWalk>3.8785e-05</gyroscopeRandomWalk>
      <gyroscopeBiasCorrelationTime>1000.0</gyroscopeBiasCorrelationTime>
      <gyroscopeTurnOnBiasSigma>0.0087</gyroscopeTurnOnBiasSigma>
      <accelerometerNoiseDensity>0.004</accelerometerNoiseDensity>
      <accelerometerRandomWalk>0.006</accelerometerRandomWalk>
      <accelerometerBiasCorrelationTime>300.0</accelerometerBiasCorrelationTime>
      <accelerometerTurnOnBiasSigma>0.196</accelerometerTurnOnBiasSigma>
      <measurementDivisor>2</measurementDivisor>
    </plugin>
    <static>0</static>
    <plugin name='odometry_sensor1' filename='librotors_gazebo_odometry_plugin.so'>
      <linkName>ouzel/odometry_sensor1_link</linkName>
      <robotNamespace>ouzel</robotNamespace>
      <poseTopic>odometry_sensor1/pose</poseTopic>
      <poseWithCovarianceTopic>odometry_sensor1/pose_with_covariance</poseWithCovarianceTopic>
      <positionTopic>odometry_sensor1/position</positionTopic>
      <transformTopic>odometry_sensor1/transform</transformTopic>
      <odometryTopic>odometry_sensor1/odometry</odometryTopic>
      <parentFrameId>world</parentFrameId>
      <childFrameId>ouzel/odometry_sensor1</childFrameId>
      <measurementDivisor>16</measurementDivisor>
      <measurementDelay>0.002</measurementDelay>
      <unknownDelay>0.0</unknownDelay>
      <noiseNormalPosition>0.00075 0.001 0.0003</noiseNormalPosition>
      <noiseNormalQuaternion>0.00075 0.001 0.0003</noiseNormalQuaternion>
      <noiseNormalLinearVelocity>0.003 0.003 0.003</noiseNormalLinearVelocity>
      <noiseNormalAngularVelocity>0.00075 0.001 0.0003</noiseNormalAngularVelocity>
      <noiseUniformPosition>0.0001 0.0001 0.0001</noiseUniformPosition>
      <noiseUniformQuaternion>0.0001 0.0001 0.0001</noiseUniformQuaternion>
      <noiseUniformLinearVelocity>0.0001 0.0001 0.0001</noiseUniformLinearVelocity>
      <noiseUniformAngularVelocity>0.0001 0.0001 0.0001</noiseUniformAngularVelocity>
    </plugin>
  </model>
</sdf>
