<?xml version="1.0" encoding="utf-8"?>
<!-- =================================================================================== -->
<!-- |    This document was autogenerated by xacro from ouzel_base.xacro               | -->
<!-- |    EDITING THIS FILE BY HAND IS NOT RECOMMENDED                                 | -->
<!-- =================================================================================== -->
<!--
  Copyright 2015 Fadri Furrer, ASL, ETH Zurich, Switzerland
  Copyright 2015 Michael Burri, ASL, ETH Zurich, Switzerland
  Copyright 2015 Mina Kamel, ASL, ETH Zurich, Switzerland
  Copyright 2015 Janosch Nikolic, ASL, ETH Zurich, Switzerland
  Copyright 2015 Markus Achtelik, ASL, ETH Zurich, Switzerland

  Licensed under the Apache License, Version 2.0 (the "License");
  you may not use this file except in compliance with the License.
  You may obtain a copy of the License at

  http://www.apache.org/licenses/LICENSE-2.0

  Unless required by applicable law or agreed to in writing, software
  distributed under the License is distributed on an "AS IS" BASIS,
  WITHOUT WARRANTIES OR CONDITIONS OF ANY KIND, either express or implied.
  See the License for the specific language governing permissions and
  limitations under the License.
-->
<robot name="ouzel">
  <!-- =============================================================== -->
  <!-- ==================== ROS INTERFACE MACRO ====================== -->
  <!-- =============================================================== -->
  <!-- <xacro:macro 
  		name="ros_interface_plugin_macro"
  		params="namespace">
    <gazebo>
      <plugin name="ros_interface_plugin" filename="librotors_gazebo_ros_interface_plugin.so">
        <robotNamespace>${namespace}</robotNamespace>
      </plugin>
    </gazebo>
  </xacro:macro>-->

    
  <link name="ouzel/base_link"/>
  <joint name="ouzel/base_joint" type="fixed">
    <origin rpy="0 0 0" xyz="0 0 0"/>
    <parent link="ouzel/base_link"/>
    <child link="ouzel/base_link_inertia"/>
  </joint>
  <link name="ouzel/base_link_inertia">
    <inertial>
      <mass value="3.13"/>
      <!-- [kg] -->
      <origin xyz="0.0 0.0 0.0"/>
      <inertia ixx="0.0075" ixy="-3.4208e-05" ixz="2.4695e-05" iyy="0.010939" iyz="-3.8826e-06" izz="0.01369"/>
    </inertial>
    <visual>
      <origin rpy="0 0 0" xyz="0 0 0"/>
      <geometry>
        <mesh filename="package://mav_description/meshes/ouzel_simple.stl" scale="1 1 1"/>
      </geometry>
    </visual>
    <collision>
      <origin rpy="0 0 0" xyz="0 0 0"/>
      <geometry>
        <box size="0.22 0.22 0.45"/>
        <!-- [m] [m] [m] -->
      </geometry>
    </collision>
  </link>
  <!-- attach multirotor_base_plugin to the base_link -->
  <gazebo>
    <plugin filename="librotors_gazebo_multirotor_base_plugin.so" name="multirotor_base_plugin">
      <robotNamespace>ouzel</robotNamespace>
      <linkName>ouzel/base_link</linkName>
      <rotorVelocitySlowdownSim>10</rotorVelocitySlowdownSim>
    </plugin>
  </gazebo>
  <!-- Rotor tilt_unit -->
  <joint name="ouzel/tilt_unit_0_revolutejoint" type="continuous">
    <origin rpy="0 0 4.71238898038" xyz="0 -0.3 0"/>
    <axis xyz="1 0 0"/>
    <parent link="ouzel/base_link"/>
    <child link="ouzel/tilt_unit_0"/>
  </joint>
  <link name="ouzel/tilt_unit_0">
    <inertial>
      <mass value="0.277"/>
      <!-- [kg] -->
      <inertia ixx="0.00034257" ixy="0" ixz="0" iyy="0.0013205" iyz="0" izz="0.0010037"/>
      <!-- [kg m^2] [kg m^2] [kg m^2] [kg m^2] [kg m^2] [kg m^2] -->
    </inertial>
    <visual>
      <geometry>
        <mesh filename="package://rotors_description/meshes/omav/omav_tiltarm.dae" scale="1 1 1"/>
      </geometry>
    </visual>
    <collision>
      <geometry>
        <box size="0.005 0.005 0.005"/>
        <!-- [m] -->
      </geometry>
    </collision>
  </link>
  <gazebo>
    <plugin filename="librotors_gazebo_motor_model.so" name="right_tilt_unit_model">
      <robotNamespace>ouzel</robotNamespace>
      <jointName>ouzel/tilt_unit_0_revolutejoint</jointName>
      <linkName>ouzel/tilt_unit_0</linkName>
      <turningDirection>ccw</turningDirection>
      <motorType>position</motorType>
      <commandSubTopic>/gazebo/command/motor_speed</commandSubTopic>
      <motorNumber>12</motorNumber>
      <motorSpeedPubTopic>/tilt_motor_0/velocity</motorSpeedPubTopic>
      <motorPositionPubTopic>/tilt_motor_0/position</motorPositionPubTopic>
      <joint_control_pid>
        <p>0.11</p>
        <i>0.0</i>
        <d>0.01</d>
        <iMax>1.0</iMax>
        <iMin>-1.0</iMin>
        <cmdMax>2.0</cmdMax>
        <cmdMin>-2.0</cmdMin>
      </joint_control_pid>
    </plugin>
  </gazebo>
  <gazebo reference="ouzel/tilt_unit_0">
    <material>Gazebo/White</material>
  </gazebo>
  <!-- Upper Rotor -->
  <joint name="rotor_0_joint" type="continuous">
    <origin rpy="0 0 0" xyz="0 0 0.06"/>
    <axis xyz="0 0 1"/>
    <parent link="ouzel/tilt_unit_0"/>
    <child link="rotor_0"/>
  </joint>
  <link name="rotor_0">
    <inertial>
      <mass value="0.0065"/>
      <!-- [kg] -->
      <inertia ixx="2.2154157805e-06" ixy="0.0" ixz="0.0" iyy="7.08147091741e-05" iyz="0.0" izz="7.29326249936e-05"/>
    </inertial>
    <visual>
      <geometry>
        <mesh filename="package://rotors_description/meshes/propeller_ccw.dae" scale="0.1143 0.1143 0.1143"/>
      </geometry>
    </visual>
    <collision>
      <geometry>
        <cylinder length="0.005" radius="0.1143"/>
        <!-- [m] -->
      </geometry>
    </collision>
  </link>
  <gazebo>
    <plugin filename="librotors_gazebo_motor_model.so" name="right_upper_motor_model">
      <robotNamespace>ouzel</robotNamespace>
      <jointName>rotor_0_joint</jointName>
      <linkName>rotor_0</linkName>
      <turningDirection>ccw</turningDirection>
      <timeConstantUp>0.0125</timeConstantUp>
      <timeConstantDown>0.025</timeConstantDown>
      <maxRotVelocity>1700</maxRotVelocity>
      <motorConstant>7.2e-06</motorConstant>
      <momentConstant>0.015</momentConstant>
      <commandSubTopic>/gazebo/command/motor_speed</commandSubTopic>
      <motorNumber>0</motorNumber>
      <rotorDragCoefficient>8.06428e-05</rotorDragCoefficient>
      <rollingMomentCoefficient>1e-06</rollingMomentCoefficient>
      <motorSpeedPubTopic>/motor_speed/0_upper</motorSpeedPubTopic>
      <rotorVelocitySlowdownSim>10</rotorVelocitySlowdownSim>
    </plugin>
  </gazebo>
  <gazebo reference="rotor_0">
    <material>Gazebo/Black</material>
  </gazebo>
  <!-- Lower Rotor -->
  <joint name="rotor_6_joint" type="continuous">
    <origin rpy="0 0 0" xyz="0 0 -0.06"/>
    <axis xyz="0 0 1"/>
    <parent link="ouzel/tilt_unit_0"/>
    <child link="rotor_6"/>
  </joint>
  <link name="rotor_6">
    <inertial>
      <mass value="0.0065"/>
      <!-- [kg] -->
      <inertia ixx="2.2154157805e-06" ixy="0.0" ixz="0.0" iyy="7.08147091741e-05" iyz="0.0" izz="7.29326249936e-05"/>
    </inertial>
    <visual>
      <geometry>
        <mesh filename="package://rotors_description/meshes/propeller_cw.dae" scale="0.1143 0.1143 0.1143"/>
      </geometry>
    </visual>
    <collision>
      <geometry>
        <cylinder length="0.005" radius="0.1143"/>
        <!-- [m] -->
      </geometry>
    </collision>
  </link>
  <gazebo>
    <plugin filename="librotors_gazebo_motor_model.so" name="right_lower_motor_model">
      <robotNamespace>ouzel</robotNamespace>
      <jointName>rotor_6_joint</jointName>
      <linkName>rotor_6</linkName>
      <turningDirection>cw</turningDirection>
      <timeConstantUp>0.0125</timeConstantUp>
      <timeConstantDown>0.025</timeConstantDown>
      <maxRotVelocity>1700</maxRotVelocity>
      <motorConstant>7.2e-06</motorConstant>
      <momentConstant>0.005</momentConstant>
      <commandSubTopic>/gazebo/command/motor_speed</commandSubTopic>
      <motorNumber>6</motorNumber>
      <rotorDragCoefficient>8.06428e-05</rotorDragCoefficient>
      <rollingMomentCoefficient>1e-06</rollingMomentCoefficient>
      <motorSpeedPubTopic>/motor_speed/0_lower</motorSpeedPubTopic>
      <rotorVelocitySlowdownSim>10</rotorVelocitySlowdownSim>
    </plugin>
  </gazebo>
  <gazebo reference="rotor_6">
    <material>Gazebo/Black</material>
  </gazebo>
  <!-- Rotor tilt_unit -->
  <joint name="ouzel/tilt_unit_1_revolutejoint" type="continuous">
    <origin rpy="0 0 1.57079632679" xyz="0 0.3 0"/>
    <axis xyz="1 0 0"/>
    <parent link="ouzel/base_link"/>
    <child link="ouzel/tilt_unit_1"/>
  </joint>
  <link name="ouzel/tilt_unit_1">
    <inertial>
      <mass value="0.277"/>
      <!-- [kg] -->
      <inertia ixx="0.00034257" ixy="0" ixz="0" iyy="0.0013205" iyz="0" izz="0.0010037"/>
      <!-- [kg m^2] [kg m^2] [kg m^2] [kg m^2] [kg m^2] [kg m^2] -->
    </inertial>
    <visual>
      <geometry>
        <mesh filename="package://rotors_description/meshes/omav/omav_tiltarm.dae" scale="1 1 1"/>
      </geometry>
    </visual>
    <collision>
      <geometry>
        <box size="0.005 0.005 0.005"/>
        <!-- [m] -->
      </geometry>
    </collision>
  </link>
  <gazebo>
    <plugin filename="librotors_gazebo_motor_model.so" name="left_tilt_unit_model">
      <robotNamespace>ouzel</robotNamespace>
      <jointName>ouzel/tilt_unit_1_revolutejoint</jointName>
      <linkName>ouzel/tilt_unit_1</linkName>
      <turningDirection>ccw</turningDirection>
      <motorType>position</motorType>
      <commandSubTopic>/gazebo/command/motor_speed</commandSubTopic>
      <motorNumber>13</motorNumber>
      <motorSpeedPubTopic>/tilt_motor_1/velocity</motorSpeedPubTopic>
      <motorPositionPubTopic>/tilt_motor_1/position</motorPositionPubTopic>
      <joint_control_pid>
        <p>0.11</p>
        <i>0.0</i>
        <d>0.01</d>
        <iMax>1.0</iMax>
        <iMin>-1.0</iMin>
        <cmdMax>2.0</cmdMax>
        <cmdMin>-2.0</cmdMin>
      </joint_control_pid>
    </plugin>
  </gazebo>
  <gazebo reference="ouzel/tilt_unit_1">
    <material>Gazebo/White</material>
  </gazebo>
  <!-- Upper Rotor -->
  <joint name="rotor_1_joint" type="continuous">
    <origin rpy="0 0 0" xyz="0 0 0.06"/>
    <axis xyz="0 0 1"/>
    <parent link="ouzel/tilt_unit_1"/>
    <child link="rotor_1"/>
  </joint>
  <link name="rotor_1">
    <inertial>
      <mass value="0.0065"/>
      <!-- [kg] -->
      <inertia ixx="2.2154157805e-06" ixy="0.0" ixz="0.0" iyy="7.08147091741e-05" iyz="0.0" izz="7.29326249936e-05"/>
    </inertial>
    <visual>
      <geometry>
        <mesh filename="package://rotors_description/meshes/propeller_cw.dae" scale="0.1143 0.1143 0.1143"/>
      </geometry>
    </visual>
    <collision>
      <geometry>
        <cylinder length="0.005" radius="0.1143"/>
        <!-- [m] -->
      </geometry>
    </collision>
  </link>
  <gazebo>
    <plugin filename="librotors_gazebo_motor_model.so" name="left_upper_motor_model">
      <robotNamespace>ouzel</robotNamespace>
      <jointName>rotor_1_joint</jointName>
      <linkName>rotor_1</linkName>
      <turningDirection>cw</turningDirection>
      <timeConstantUp>0.0125</timeConstantUp>
      <timeConstantDown>0.025</timeConstantDown>
      <maxRotVelocity>1700</maxRotVelocity>
      <motorConstant>7.2e-06</motorConstant>
      <momentConstant>0.015</momentConstant>
      <commandSubTopic>/gazebo/command/motor_speed</commandSubTopic>
      <motorNumber>1</motorNumber>
      <rotorDragCoefficient>8.06428e-05</rotorDragCoefficient>
      <rollingMomentCoefficient>1e-06</rollingMomentCoefficient>
      <motorSpeedPubTopic>/motor_speed/1_upper</motorSpeedPubTopic>
      <rotorVelocitySlowdownSim>10</rotorVelocitySlowdownSim>
    </plugin>
  </gazebo>
  <gazebo reference="rotor_1">
    <material>Gazebo/Black</material>
  </gazebo>
  <!-- Lower Rotor -->
  <joint name="rotor_7_joint" type="continuous">
    <origin rpy="0 0 0" xyz="0 0 -0.06"/>
    <axis xyz="0 0 1"/>
    <parent link="ouzel/tilt_unit_1"/>
    <child link="rotor_7"/>
  </joint>
  <link name="rotor_7">
    <inertial>
      <mass value="0.0065"/>
      <!-- [kg] -->
      <inertia ixx="2.2154157805e-06" ixy="0.0" ixz="0.0" iyy="7.08147091741e-05" iyz="0.0" izz="7.29326249936e-05"/>
    </inertial>
    <visual>
      <geometry>
        <mesh filename="package://rotors_description/meshes/propeller_ccw.dae" scale="0.1143 0.1143 0.1143"/>
      </geometry>
    </visual>
    <collision>
      <geometry>
        <cylinder length="0.005" radius="0.1143"/>
        <!-- [m] -->
      </geometry>
    </collision>
  </link>
  <gazebo>
    <plugin filename="librotors_gazebo_motor_model.so" name="left_lower_motor_model">
      <robotNamespace>ouzel</robotNamespace>
      <jointName>rotor_7_joint</jointName>
      <linkName>rotor_7</linkName>
      <turningDirection>ccw</turningDirection>
      <timeConstantUp>0.0125</timeConstantUp>
      <timeConstantDown>0.025</timeConstantDown>
      <maxRotVelocity>1700</maxRotVelocity>
      <motorConstant>7.2e-06</motorConstant>
      <momentConstant>0.005</momentConstant>
      <commandSubTopic>/gazebo/command/motor_speed</commandSubTopic>
      <motorNumber>7</motorNumber>
      <rotorDragCoefficient>8.06428e-05</rotorDragCoefficient>
      <rollingMomentCoefficient>1e-06</rollingMomentCoefficient>
      <motorSpeedPubTopic>/motor_speed/1_lower</motorSpeedPubTopic>
      <rotorVelocitySlowdownSim>10</rotorVelocitySlowdownSim>
    </plugin>
  </gazebo>
  <gazebo reference="rotor_7">
    <material>Gazebo/Black</material>
  </gazebo>
  <!-- Rotor tilt_unit -->
  <joint name="ouzel/tilt_unit_2_revolutejoint" type="continuous">
    <origin rpy="0 0 0.52359877559" xyz="0.259807621135 0.15 0"/>
    <axis xyz="1 0 0"/>
    <parent link="ouzel/base_link"/>
    <child link="ouzel/tilt_unit_2"/>
  </joint>
  <link name="ouzel/tilt_unit_2">
    <inertial>
      <mass value="0.277"/>
      <!-- [kg] -->
      <inertia ixx="0.00034257" ixy="0" ixz="0" iyy="0.0013205" iyz="0" izz="0.0010037"/>
      <!-- [kg m^2] [kg m^2] [kg m^2] [kg m^2] [kg m^2] [kg m^2] -->
    </inertial>
    <visual>
      <geometry>
        <mesh filename="package://rotors_description/meshes/omav/omav_tiltarm.dae" scale="1 1 1"/>
      </geometry>
    </visual>
    <collision>
      <geometry>
        <box size="0.005 0.005 0.005"/>
        <!-- [m] -->
      </geometry>
    </collision>
  </link>
  <gazebo>
    <plugin filename="librotors_gazebo_motor_model.so" name="front_left_tilt_unit_model">
      <robotNamespace>ouzel</robotNamespace>
      <jointName>ouzel/tilt_unit_2_revolutejoint</jointName>
      <linkName>ouzel/tilt_unit_2</linkName>
      <turningDirection>ccw</turningDirection>
      <motorType>position</motorType>
      <commandSubTopic>/gazebo/command/motor_speed</commandSubTopic>
      <motorNumber>14</motorNumber>
      <motorSpeedPubTopic>/tilt_motor_2/velocity</motorSpeedPubTopic>
      <motorPositionPubTopic>/tilt_motor_2/position</motorPositionPubTopic>
      <joint_control_pid>
        <p>0.11</p>
        <i>0.0</i>
        <d>0.01</d>
        <iMax>1.0</iMax>
        <iMin>-1.0</iMin>
        <cmdMax>2.0</cmdMax>
        <cmdMin>-2.0</cmdMin>
      </joint_control_pid>
    </plugin>
  </gazebo>
  <gazebo reference="ouzel/tilt_unit_2">
    <material>Gazebo/White</material>
  </gazebo>
  <!-- Upper Rotor -->
  <joint name="rotor_2_joint" type="continuous">
    <origin rpy="0 0 0" xyz="0 0 0.06"/>
    <axis xyz="0 0 1"/>
    <parent link="ouzel/tilt_unit_2"/>
    <child link="rotor_2"/>
  </joint>
  <link name="rotor_2">
    <inertial>
      <mass value="0.0065"/>
      <!-- [kg] -->
      <inertia ixx="2.2154157805e-06" ixy="0.0" ixz="0.0" iyy="7.08147091741e-05" iyz="0.0" izz="7.29326249936e-05"/>
    </inertial>
    <visual>
      <geometry>
        <mesh filename="package://rotors_description/meshes/propeller_ccw.dae" scale="0.1143 0.1143 0.1143"/>
      </geometry>
    </visual>
    <collision>
      <geometry>
        <cylinder length="0.005" radius="0.1143"/>
        <!-- [m] -->
      </geometry>
    </collision>
  </link>
  <gazebo>
    <plugin filename="librotors_gazebo_motor_model.so" name="front_left_upper_motor_model">
      <robotNamespace>ouzel</robotNamespace>
      <jointName>rotor_2_joint</jointName>
      <linkName>rotor_2</linkName>
      <turningDirection>ccw</turningDirection>
      <timeConstantUp>0.0125</timeConstantUp>
      <timeConstantDown>0.025</timeConstantDown>
      <maxRotVelocity>1700</maxRotVelocity>
      <motorConstant>7.2e-06</motorConstant>
      <momentConstant>0.015</momentConstant>
      <commandSubTopic>/gazebo/command/motor_speed</commandSubTopic>
      <motorNumber>2</motorNumber>
      <rotorDragCoefficient>8.06428e-05</rotorDragCoefficient>
      <rollingMomentCoefficient>1e-06</rollingMomentCoefficient>
      <motorSpeedPubTopic>/motor_speed/2_upper</motorSpeedPubTopic>
      <rotorVelocitySlowdownSim>10</rotorVelocitySlowdownSim>
    </plugin>
  </gazebo>
  <gazebo reference="rotor_2">
    <material>Gazebo/Orange</material>
  </gazebo>
  <!-- Lower Rotor -->
  <joint name="rotor_8_joint" type="continuous">
    <origin rpy="0 0 0" xyz="0 0 -0.06"/>
    <axis xyz="0 0 1"/>
    <parent link="ouzel/tilt_unit_2"/>
    <child link="rotor_8"/>
  </joint>
  <link name="rotor_8">
    <inertial>
      <mass value="0.0065"/>
      <!-- [kg] -->
      <inertia ixx="2.2154157805e-06" ixy="0.0" ixz="0.0" iyy="7.08147091741e-05" iyz="0.0" izz="7.29326249936e-05"/>
    </inertial>
    <visual>
      <geometry>
        <mesh filename="package://rotors_description/meshes/propeller_cw.dae" scale="0.1143 0.1143 0.1143"/>
      </geometry>
    </visual>
    <collision>
      <geometry>
        <cylinder length="0.005" radius="0.1143"/>
        <!-- [m] -->
      </geometry>
    </collision>
  </link>
  <gazebo>
    <plugin filename="librotors_gazebo_motor_model.so" name="front_left_lower_motor_model">
      <robotNamespace>ouzel</robotNamespace>
      <jointName>rotor_8_joint</jointName>
      <linkName>rotor_8</linkName>
      <turningDirection>cw</turningDirection>
      <timeConstantUp>0.0125</timeConstantUp>
      <timeConstantDown>0.025</timeConstantDown>
      <maxRotVelocity>1700</maxRotVelocity>
      <motorConstant>7.2e-06</motorConstant>
      <momentConstant>0.005</momentConstant>
      <commandSubTopic>/gazebo/command/motor_speed</commandSubTopic>
      <motorNumber>8</motorNumber>
      <rotorDragCoefficient>8.06428e-05</rotorDragCoefficient>
      <rollingMomentCoefficient>1e-06</rollingMomentCoefficient>
      <motorSpeedPubTopic>/motor_speed/2_lower</motorSpeedPubTopic>
      <rotorVelocitySlowdownSim>10</rotorVelocitySlowdownSim>
    </plugin>
  </gazebo>
  <gazebo reference="rotor_8">
    <material>Gazebo/Orange</material>
  </gazebo>
  <!-- Rotor tilt_unit -->
  <joint name="ouzel/tilt_unit_3_revolutejoint" type="continuous">
    <origin rpy="0 0 3.66519142919" xyz="-0.259807621135 -0.15 0"/>
    <axis xyz="1 0 0"/>
    <parent link="ouzel/base_link"/>
    <child link="ouzel/tilt_unit_3"/>
  </joint>
  <link name="ouzel/tilt_unit_3">
    <inertial>
      <mass value="0.277"/>
      <!-- [kg] -->
      <inertia ixx="0.00034257" ixy="0" ixz="0" iyy="0.0013205" iyz="0" izz="0.0010037"/>
      <!-- [kg m^2] [kg m^2] [kg m^2] [kg m^2] [kg m^2] [kg m^2] -->
    </inertial>
    <visual>
      <geometry>
        <mesh filename="package://rotors_description/meshes/omav/omav_tiltarm.dae" scale="1 1 1"/>
      </geometry>
    </visual>
    <collision>
      <geometry>
        <box size="0.005 0.005 0.005"/>
        <!-- [m] -->
      </geometry>
    </collision>
  </link>
  <gazebo>
    <plugin filename="librotors_gazebo_motor_model.so" name="back_right_tilt_unit_model">
      <robotNamespace>ouzel</robotNamespace>
      <jointName>ouzel/tilt_unit_3_revolutejoint</jointName>
      <linkName>ouzel/tilt_unit_3</linkName>
      <turningDirection>ccw</turningDirection>
      <motorType>position</motorType>
      <commandSubTopic>/gazebo/command/motor_speed</commandSubTopic>
      <motorNumber>15</motorNumber>
      <motorSpeedPubTopic>/tilt_motor_3/velocity</motorSpeedPubTopic>
      <motorPositionPubTopic>/tilt_motor_3/position</motorPositionPubTopic>
      <joint_control_pid>
        <p>0.11</p>
        <i>0.0</i>
        <d>0.01</d>
        <iMax>1.0</iMax>
        <iMin>-1.0</iMin>
        <cmdMax>2.0</cmdMax>
        <cmdMin>-2.0</cmdMin>
      </joint_control_pid>
    </plugin>
  </gazebo>
  <gazebo reference="ouzel/tilt_unit_3">
    <material>Gazebo/White</material>
  </gazebo>
  <!-- Upper Rotor -->
  <joint name="rotor_3_joint" type="continuous">
    <origin rpy="0 0 0" xyz="0 0 0.06"/>
    <axis xyz="0 0 1"/>
    <parent link="ouzel/tilt_unit_3"/>
    <child link="rotor_3"/>
  </joint>
  <link name="rotor_3">
    <inertial>
      <mass value="0.0065"/>
      <!-- [kg] -->
      <inertia ixx="2.2154157805e-06" ixy="0.0" ixz="0.0" iyy="7.08147091741e-05" iyz="0.0" izz="7.29326249936e-05"/>
    </inertial>
    <visual>
      <geometry>
        <mesh filename="package://rotors_description/meshes/propeller_cw.dae" scale="0.1143 0.1143 0.1143"/>
      </geometry>
    </visual>
    <collision>
      <geometry>
        <cylinder length="0.005" radius="0.1143"/>
        <!-- [m] -->
      </geometry>
    </collision>
  </link>
  <gazebo>
    <plugin filename="librotors_gazebo_motor_model.so" name="back_right_upper_motor_model">
      <robotNamespace>ouzel</robotNamespace>
      <jointName>rotor_3_joint</jointName>
      <linkName>rotor_3</linkName>
      <turningDirection>cw</turningDirection>
      <timeConstantUp>0.0125</timeConstantUp>
      <timeConstantDown>0.025</timeConstantDown>
      <maxRotVelocity>1700</maxRotVelocity>
      <motorConstant>7.2e-06</motorConstant>
      <momentConstant>0.015</momentConstant>
      <commandSubTopic>/gazebo/command/motor_speed</commandSubTopic>
      <motorNumber>3</motorNumber>
      <rotorDragCoefficient>8.06428e-05</rotorDragCoefficient>
      <rollingMomentCoefficient>1e-06</rollingMomentCoefficient>
      <motorSpeedPubTopic>/motor_speed/3_upper</motorSpeedPubTopic>
      <rotorVelocitySlowdownSim>10</rotorVelocitySlowdownSim>
    </plugin>
  </gazebo>
  <gazebo reference="rotor_3">
    <material>Gazebo/DarkGrey</material>
  </gazebo>
  <!-- Lower Rotor -->
  <joint name="rotor_9_joint" type="continuous">
    <origin rpy="0 0 0" xyz="0 0 -0.06"/>
    <axis xyz="0 0 1"/>
    <parent link="ouzel/tilt_unit_3"/>
    <child link="rotor_9"/>
  </joint>
  <link name="rotor_9">
    <inertial>
      <mass value="0.0065"/>
      <!-- [kg] -->
      <inertia ixx="2.2154157805e-06" ixy="0.0" ixz="0.0" iyy="7.08147091741e-05" iyz="0.0" izz="7.29326249936e-05"/>
    </inertial>
    <visual>
      <geometry>
        <mesh filename="package://rotors_description/meshes/propeller_ccw.dae" scale="0.1143 0.1143 0.1143"/>
      </geometry>
    </visual>
    <collision>
      <geometry>
        <cylinder length="0.005" radius="0.1143"/>
        <!-- [m] -->
      </geometry>
    </collision>
  </link>
  <gazebo>
    <plugin filename="librotors_gazebo_motor_model.so" name="back_right_lower_motor_model">
      <robotNamespace>ouzel</robotNamespace>
      <jointName>rotor_9_joint</jointName>
      <linkName>rotor_9</linkName>
      <turningDirection>ccw</turningDirection>
      <timeConstantUp>0.0125</timeConstantUp>
      <timeConstantDown>0.025</timeConstantDown>
      <maxRotVelocity>1700</maxRotVelocity>
      <motorConstant>7.2e-06</motorConstant>
      <momentConstant>0.005</momentConstant>
      <commandSubTopic>/gazebo/command/motor_speed</commandSubTopic>
      <motorNumber>9</motorNumber>
      <rotorDragCoefficient>8.06428e-05</rotorDragCoefficient>
      <rollingMomentCoefficient>1e-06</rollingMomentCoefficient>
      <motorSpeedPubTopic>/motor_speed/3_lower</motorSpeedPubTopic>
      <rotorVelocitySlowdownSim>10</rotorVelocitySlowdownSim>
    </plugin>
  </gazebo>
  <gazebo reference="rotor_9">
    <material>Gazebo/DarkGrey</material>
  </gazebo>
  <!-- Rotor tilt_unit -->
  <joint name="ouzel/tilt_unit_4_revolutejoint" type="continuous">
    <origin rpy="0 0 5.75958653158" xyz="0.259807621135 -0.15 0"/>
    <axis xyz="1 0 0"/>
    <parent link="ouzel/base_link"/>
    <child link="ouzel/tilt_unit_4"/>
  </joint>
  <link name="ouzel/tilt_unit_4">
    <inertial>
      <mass value="0.277"/>
      <!-- [kg] -->
      <inertia ixx="0.00034257" ixy="0" ixz="0" iyy="0.0013205" iyz="0" izz="0.0010037"/>
      <!-- [kg m^2] [kg m^2] [kg m^2] [kg m^2] [kg m^2] [kg m^2] -->
    </inertial>
    <visual>
      <geometry>
        <mesh filename="package://rotors_description/meshes/omav/omav_tiltarm.dae" scale="1 1 1"/>
      </geometry>
    </visual>
    <collision>
      <geometry>
        <box size="0.005 0.005 0.005"/>
        <!-- [m] -->
      </geometry>
    </collision>
  </link>
  <gazebo>
    <plugin filename="librotors_gazebo_motor_model.so" name="front_right_tilt_unit_model">
      <robotNamespace>ouzel</robotNamespace>
      <jointName>ouzel/tilt_unit_4_revolutejoint</jointName>
      <linkName>ouzel/tilt_unit_4</linkName>
      <turningDirection>ccw</turningDirection>
      <motorType>position</motorType>
      <commandSubTopic>/gazebo/command/motor_speed</commandSubTopic>
      <motorNumber>16</motorNumber>
      <motorSpeedPubTopic>/tilt_motor_4/velocity</motorSpeedPubTopic>
      <motorPositionPubTopic>/tilt_motor_4/position</motorPositionPubTopic>
      <joint_control_pid>
        <p>0.11</p>
        <i>0.0</i>
        <d>0.01</d>
        <iMax>1.0</iMax>
        <iMin>-1.0</iMin>
        <cmdMax>2.0</cmdMax>
        <cmdMin>-2.0</cmdMin>
      </joint_control_pid>
    </plugin>
  </gazebo>
  <gazebo reference="ouzel/tilt_unit_4">
    <material>Gazebo/White</material>
  </gazebo>
  <!-- Upper Rotor -->
  <joint name="rotor_4_joint" type="continuous">
    <origin rpy="0 0 0" xyz="0 0 0.06"/>
    <axis xyz="0 0 1"/>
    <parent link="ouzel/tilt_unit_4"/>
    <child link="rotor_4"/>
  </joint>
  <link name="rotor_4">
    <inertial>
      <mass value="0.0065"/>
      <!-- [kg] -->
      <inertia ixx="2.2154157805e-06" ixy="0.0" ixz="0.0" iyy="7.08147091741e-05" iyz="0.0" izz="7.29326249936e-05"/>
    </inertial>
    <visual>
      <geometry>
        <mesh filename="package://rotors_description/meshes/propeller_cw.dae" scale="0.1143 0.1143 0.1143"/>
      </geometry>
    </visual>
    <collision>
      <geometry>
        <cylinder length="0.005" radius="0.1143"/>
        <!-- [m] -->
      </geometry>
    </collision>
  </link>
  <gazebo>
    <plugin filename="librotors_gazebo_motor_model.so" name="front_right_upper_motor_model">
      <robotNamespace>ouzel</robotNamespace>
      <jointName>rotor_4_joint</jointName>
      <linkName>rotor_4</linkName>
      <turningDirection>cw</turningDirection>
      <timeConstantUp>0.0125</timeConstantUp>
      <timeConstantDown>0.025</timeConstantDown>
      <maxRotVelocity>1700</maxRotVelocity>
      <motorConstant>7.2e-06</motorConstant>
      <momentConstant>0.015</momentConstant>
      <commandSubTopic>/gazebo/command/motor_speed</commandSubTopic>
      <motorNumber>4</motorNumber>
      <rotorDragCoefficient>8.06428e-05</rotorDragCoefficient>
      <rollingMomentCoefficient>1e-06</rollingMomentCoefficient>
      <motorSpeedPubTopic>/motor_speed/4_upper</motorSpeedPubTopic>
      <rotorVelocitySlowdownSim>10</rotorVelocitySlowdownSim>
    </plugin>
  </gazebo>
  <gazebo reference="rotor_4">
    <material>Gazebo/Orange</material>
  </gazebo>
  <!-- Lower Rotor -->
  <joint name="rotor_10_joint" type="continuous">
    <origin rpy="0 0 0" xyz="0 0 -0.06"/>
    <axis xyz="0 0 1"/>
    <parent link="ouzel/tilt_unit_4"/>
    <child link="rotor_10"/>
  </joint>
  <link name="rotor_10">
    <inertial>
      <mass value="0.0065"/>
      <!-- [kg] -->
      <inertia ixx="2.2154157805e-06" ixy="0.0" ixz="0.0" iyy="7.08147091741e-05" iyz="0.0" izz="7.29326249936e-05"/>
    </inertial>
    <visual>
      <geometry>
        <mesh filename="package://rotors_description/meshes/propeller_ccw.dae" scale="0.1143 0.1143 0.1143"/>
      </geometry>
    </visual>
    <collision>
      <geometry>
        <cylinder length="0.005" radius="0.1143"/>
        <!-- [m] -->
      </geometry>
    </collision>
  </link>
  <gazebo>
    <plugin filename="librotors_gazebo_motor_model.so" name="front_right_lower_motor_model">
      <robotNamespace>ouzel</robotNamespace>
      <jointName>rotor_10_joint</jointName>
      <linkName>rotor_10</linkName>
      <turningDirection>ccw</turningDirection>
      <timeConstantUp>0.0125</timeConstantUp>
      <timeConstantDown>0.025</timeConstantDown>
      <maxRotVelocity>1700</maxRotVelocity>
      <motorConstant>7.2e-06</motorConstant>
      <momentConstant>0.005</momentConstant>
      <commandSubTopic>/gazebo/command/motor_speed</commandSubTopic>
      <motorNumber>10</motorNumber>
      <rotorDragCoefficient>8.06428e-05</rotorDragCoefficient>
      <rollingMomentCoefficient>1e-06</rollingMomentCoefficient>
      <motorSpeedPubTopic>/motor_speed/4_lower</motorSpeedPubTopic>
      <rotorVelocitySlowdownSim>10</rotorVelocitySlowdownSim>
    </plugin>
  </gazebo>
  <gazebo reference="rotor_10">
    <material>Gazebo/Orange</material>
  </gazebo>
  <!-- Rotor tilt_unit -->
  <joint name="ouzel/tilt_unit_5_revolutejoint" type="continuous">
    <origin rpy="0 0 2.61799387799" xyz="-0.259807621135 0.15 0"/>
    <axis xyz="1 0 0"/>
    <parent link="ouzel/base_link"/>
    <child link="ouzel/tilt_unit_5"/>
  </joint>
  <link name="ouzel/tilt_unit_5">
    <inertial>
      <mass value="0.277"/>
      <!-- [kg] -->
      <inertia ixx="0.00034257" ixy="0" ixz="0" iyy="0.0013205" iyz="0" izz="0.0010037"/>
      <!-- [kg m^2] [kg m^2] [kg m^2] [kg m^2] [kg m^2] [kg m^2] -->
    </inertial>
    <visual>
      <geometry>
        <mesh filename="package://rotors_description/meshes/omav/omav_tiltarm.dae" scale="1 1 1"/>
      </geometry>
    </visual>
    <collision>
      <geometry>
        <box size="0.005 0.005 0.005"/>
        <!-- [m] -->
      </geometry>
    </collision>
  </link>
  <gazebo>
    <plugin filename="librotors_gazebo_motor_model.so" name="back_left_tilt_unit_model">
      <robotNamespace>ouzel</robotNamespace>
      <jointName>ouzel/tilt_unit_5_revolutejoint</jointName>
      <linkName>ouzel/tilt_unit_5</linkName>
      <turningDirection>ccw</turningDirection>
      <motorType>position</motorType>
      <commandSubTopic>/gazebo/command/motor_speed</commandSubTopic>
      <motorNumber>17</motorNumber>
      <motorSpeedPubTopic>/tilt_motor_5/velocity</motorSpeedPubTopic>
      <motorPositionPubTopic>/tilt_motor_5/position</motorPositionPubTopic>
      <joint_control_pid>
        <p>0.11</p>
        <i>0.0</i>
        <d>0.01</d>
        <iMax>1.0</iMax>
        <iMin>-1.0</iMin>
        <cmdMax>2.0</cmdMax>
        <cmdMin>-2.0</cmdMin>
      </joint_control_pid>
    </plugin>
  </gazebo>
  <gazebo reference="ouzel/tilt_unit_5">
    <material>Gazebo/White</material>
  </gazebo>
  <!-- Upper Rotor -->
  <joint name="rotor_5_joint" type="continuous">
    <origin rpy="0 0 0" xyz="0 0 0.06"/>
    <axis xyz="0 0 1"/>
    <parent link="ouzel/tilt_unit_5"/>
    <child link="rotor_5"/>
  </joint>
  <link name="rotor_5">
    <inertial>
      <mass value="0.0065"/>
      <!-- [kg] -->
      <inertia ixx="2.2154157805e-06" ixy="0.0" ixz="0.0" iyy="7.08147091741e-05" iyz="0.0" izz="7.29326249936e-05"/>
    </inertial>
    <visual>
      <geometry>
        <mesh filename="package://rotors_description/meshes/propeller_ccw.dae" scale="0.1143 0.1143 0.1143"/>
      </geometry>
    </visual>
    <collision>
      <geometry>
        <cylinder length="0.005" radius="0.1143"/>
        <!-- [m] -->
      </geometry>
    </collision>
  </link>
  <gazebo>
    <plugin filename="librotors_gazebo_motor_model.so" name="back_left_upper_motor_model">
      <robotNamespace>ouzel</robotNamespace>
      <jointName>rotor_5_joint</jointName>
      <linkName>rotor_5</linkName>
      <turningDirection>ccw</turningDirection>
      <timeConstantUp>0.0125</timeConstantUp>
      <timeConstantDown>0.025</timeConstantDown>
      <maxRotVelocity>1700</maxRotVelocity>
      <motorConstant>7.2e-06</motorConstant>
      <momentConstant>0.015</momentConstant>
      <commandSubTopic>/gazebo/command/motor_speed</commandSubTopic>
      <motorNumber>5</motorNumber>
      <rotorDragCoefficient>8.06428e-05</rotorDragCoefficient>
      <rollingMomentCoefficient>1e-06</rollingMomentCoefficient>
      <motorSpeedPubTopic>/motor_speed/5_upper</motorSpeedPubTopic>
      <rotorVelocitySlowdownSim>10</rotorVelocitySlowdownSim>
    </plugin>
  </gazebo>
  <gazebo reference="rotor_5">
    <material>Gazebo/DarkGrey</material>
  </gazebo>
  <!-- Lower Rotor -->
  <joint name="rotor_11_joint" type="continuous">
    <origin rpy="0 0 0" xyz="0 0 -0.06"/>
    <axis xyz="0 0 1"/>
    <parent link="ouzel/tilt_unit_5"/>
    <child link="rotor_11"/>
  </joint>
  <link name="rotor_11">
    <inertial>
      <mass value="0.0065"/>
      <!-- [kg] -->
      <inertia ixx="2.2154157805e-06" ixy="0.0" ixz="0.0" iyy="7.08147091741e-05" iyz="0.0" izz="7.29326249936e-05"/>
    </inertial>
    <visual>
      <geometry>
        <mesh filename="package://rotors_description/meshes/propeller_cw.dae" scale="0.1143 0.1143 0.1143"/>
      </geometry>
    </visual>
    <collision>
      <geometry>
        <cylinder length="0.005" radius="0.1143"/>
        <!-- [m] -->
      </geometry>
    </collision>
  </link>
  <gazebo>
    <plugin filename="librotors_gazebo_motor_model.so" name="back_left_lower_motor_model">
      <robotNamespace>ouzel</robotNamespace>
      <jointName>rotor_11_joint</jointName>
      <linkName>rotor_11</linkName>
      <turningDirection>cw</turningDirection>
      <timeConstantUp>0.0125</timeConstantUp>
      <timeConstantDown>0.025</timeConstantDown>
      <maxRotVelocity>1700</maxRotVelocity>
      <motorConstant>7.2e-06</motorConstant>
      <momentConstant>0.005</momentConstant>
      <commandSubTopic>/gazebo/command/motor_speed</commandSubTopic>
      <motorNumber>11</motorNumber>
      <rotorDragCoefficient>8.06428e-05</rotorDragCoefficient>
      <rollingMomentCoefficient>1e-06</rollingMomentCoefficient>
      <motorSpeedPubTopic>/motor_speed/5_lower</motorSpeedPubTopic>
      <rotorVelocitySlowdownSim>10</rotorVelocitySlowdownSim>
    </plugin>
  </gazebo>
  <gazebo reference="rotor_11">
    <material>Gazebo/DarkGrey</material>
  </gazebo>
  <gazebo>
    <plugin filename="librotors_gazebo_mavlink_interface.so" name="mavlink_interface">
      <robotNamespace>ouzel</robotNamespace>
      <imu_rate>102</imu_rate>
      <imuSubTopic>/imu</imuSubTopic>
      <mavlink_addr>INADDR_ANY</mavlink_addr>
      <mavlink_udp_port>14560</mavlink_udp_port>
      <motorSpeedCommandPubTopic>/gazebo/command/motor_speed</motorSpeedCommandPubTopic>
      <control_channels>
        <channel name="rotor0">
          <input_index>0</input_index>
          <input_offset>0</input_offset>
          <input_scaling>1700</input_scaling>
          <zero_position_disarmed>0</zero_position_disarmed>
          <zero_position_armed>100</zero_position_armed>
          <joint_control_type>velocity</joint_control_type>
        </channel>
        <channel name="rotor1">
          <input_index>1</input_index>
          <input_offset>0</input_offset>
          <input_scaling>1700</input_scaling>
          <zero_position_disarmed>0</zero_position_disarmed>
          <zero_position_armed>100</zero_position_armed>
          <joint_control_type>velocity</joint_control_type>
        </channel>
        <channel name="rotor2">
          <input_index>2</input_index>
          <input_offset>0</input_offset>
          <input_scaling>1700</input_scaling>
          <zero_position_disarmed>0</zero_position_disarmed>
          <zero_position_armed>100</zero_position_armed>
          <joint_control_type>velocity</joint_control_type>
        </channel>
        <channel name="rotor3">
          <input_index>3</input_index>
          <input_offset>0</input_offset>
          <input_scaling>1700</input_scaling>
          <zero_position_disarmed>0</zero_position_disarmed>
          <zero_position_armed>100</zero_position_armed>
          <joint_control_type>velocity</joint_control_type>
        </channel>
        <channel name="rotor4">
          <input_index>4</input_index>
          <input_offset>0</input_offset>
          <input_scaling>1700</input_scaling>
          <zero_position_disarmed>0</zero_position_disarmed>
          <zero_position_armed>100</zero_position_armed>
          <joint_control_type>velocity</joint_control_type>
        </channel>
        <channel name="rotor5">
          <input_index>5</input_index>
          <input_offset>0</input_offset>
          <input_scaling>1700</input_scaling>
          <zero_position_disarmed>0</zero_position_disarmed>
          <zero_position_armed>100</zero_position_armed>
          <joint_control_type>velocity</joint_control_type>
        </channel>
        <channel name="rotor6">
          <input_index>6</input_index>
          <input_offset>0</input_offset>
          <input_scaling>1700</input_scaling>
          <zero_position_disarmed>0</zero_position_disarmed>
          <zero_position_armed>100</zero_position_armed>
          <joint_control_type>velocity</joint_control_type>
        </channel>
        <channel name="rotor7">
          <input_index>7</input_index>
          <input_offset>0</input_offset>
          <input_scaling>1700</input_scaling>
          <zero_position_disarmed>0</zero_position_disarmed>
          <zero_position_armed>100</zero_position_armed>
          <joint_control_type>velocity</joint_control_type>
        </channel>
        <channel name="rotor8">
          <input_index>8</input_index>
          <input_offset>0</input_offset>
          <input_scaling>1700</input_scaling>
          <zero_position_disarmed>0</zero_position_disarmed>
          <zero_position_armed>100</zero_position_armed>
          <joint_control_type>velocity</joint_control_type>
        </channel>
        <channel name="rotor9">
          <input_index>9</input_index>
          <input_offset>0</input_offset>
          <input_scaling>1700</input_scaling>
          <zero_position_disarmed>0</zero_position_disarmed>
          <zero_position_armed>100</zero_position_armed>
          <joint_control_type>velocity</joint_control_type>
        </channel>
        <channel name="rotor10">
          <input_index>10</input_index>
          <input_offset>0</input_offset>
          <input_scaling>1700</input_scaling>
          <zero_position_disarmed>0</zero_position_disarmed>
          <zero_position_armed>100</zero_position_armed>
          <joint_control_type>velocity</joint_control_type>
        </channel>
        <channel name="rotor11">
          <input_index>11</input_index>
          <input_offset>0</input_offset>
          <input_scaling>1700</input_scaling>
          <zero_position_disarmed>0</zero_position_disarmed>
          <zero_position_armed>100</zero_position_armed>
          <joint_control_type>velocity</joint_control_type>
        </channel>
        <channel name="tilt_unit0">
          <input_index>12</input_index>
          <input_offset>0</input_offset>
          <input_scaling>31.4159</input_scaling>
          <zero_position_disarmed>0</zero_position_disarmed>
          <zero_position_armed>0</zero_position_armed>
          <joint_control_type>position</joint_control_type>
        </channel>
        <channel name="tilt_unit1">
          <input_index>13</input_index>
          <input_offset>0</input_offset>
          <input_scaling>31.4159</input_scaling>
          <zero_position_disarmed>0</zero_position_disarmed>
          <zero_position_armed>0</zero_position_armed>
          <joint_control_type>position</joint_control_type>
        </channel>
        <channel name="tilt_unit2">
          <input_index>14</input_index>
          <input_offset>0</input_offset>
          <input_scaling>31.4159</input_scaling>
          <zero_position_disarmed>0</zero_position_disarmed>
          <zero_position_armed>0</zero_position_armed>
          <joint_control_type>position</joint_control_type>
        </channel>
        <channel name="tilt_unit3">
          <input_index>15</input_index>
          <input_offset>0</input_offset>
          <input_scaling>31.4159</input_scaling>
          <zero_position_disarmed>0</zero_position_disarmed>
          <zero_position_armed>0</zero_position_armed>
          <joint_control_type>position</joint_control_type>
        </channel>
        <channel name="tilt_unit4">
          <input_index>16</input_index>
          <input_offset>0</input_offset>
          <input_scaling>31.4159</input_scaling>
          <zero_position_disarmed>0</zero_position_disarmed>
          <zero_position_armed>0</zero_position_armed>
          <joint_control_type>position</joint_control_type>
        </channel>
        <channel name="tilt_unit5">
          <input_index>17</input_index>
          <input_offset>0</input_offset>
          <input_scaling>31.4159</input_scaling>
          <zero_position_disarmed>0</zero_position_disarmed>
          <zero_position_armed>0</zero_position_armed>
          <joint_control_type>position</joint_control_type>
        </channel>
      </control_channels>
    </plugin>
  </gazebo>
  <gazebo>
    <plugin filename="librotors_gazebo_controller_interface.so" name="controller_interface">
      <robotNamespace>ouzel</robotNamespace>
      <commandAttitudeThrustSubTopic>command/attitude</commandAttitudeThrustSubTopic>
      <commandRateThrustSubTopic>command/rate</commandRateThrustSubTopic>
      <commandMotorSpeedSubTopic>command/motor_speed</commandMotorSpeedSubTopic>
      <imuSubTopic>imu</imuSubTopic>
      <motorSpeedCommandPubTopic>gazebo/command/motor_speed</motorSpeedCommandPubTopic>
    </plugin>
  </gazebo>
  <!-- IMU link -->
  <link name="ouzel/imu_link">
    <inertial>
      <inertia ixx="0.00001" ixy="0.0" ixz="0.0" iyy="0.00001" iyz="0.0" izz="0.00001"/>
      <mass value="0.015"/>
      <!-- [kg] -->
      <origin rpy="0 0 0" xyz="0 0 0"/>
    </inertial>
  </link>
  <!-- IMU joint -->
  <joint name="ouzel/imu_joint" type="revolute">
    <origin rpy="0 0 0" xyz="0 0 0"/>
    <parent link="ouzel/base_link"/>
    <child link="ouzel/imu_link"/>
    <limit effort="0" lower="0" upper="0" velocity="0"/>
  </joint>
  <gazebo>
    <plugin filename="librotors_gazebo_imu_plugin.so" name="rotors_gazebo_imu_plugin">
      <!-- A good description of the IMU parameters can be found in the kalibr documentation:
           https://github.com/ethz-asl/kalibr/wiki/IMU-Noise-Model-and-Intrinsics -->
      <robotNamespace>ouzel</robotNamespace>
      <!-- (string, required): ros namespace in which the messages are published -->
      <linkName>ouzel/imu_link</linkName>
      <!-- (string, required): name of the body which holds the IMU sensor -->
      <imuTopic>imu</imuTopic>
      <!-- (string): name of the sensor output topic and prefix of service names (defaults to imu) -->
      <gyroscopeNoiseDensity>5.366563e-05</gyroscopeNoiseDensity>
      <!-- Gyroscope noise density (two-sided spectrum) [rad/s/sqrt(Hz)] -->
      <gyroscopeRandomWalk>3.8785e-05</gyroscopeRandomWalk>
      <!-- Gyroscope bias random walk [rad/s/s/sqrt(Hz)] -->
      <gyroscopeBiasCorrelationTime>1000.0</gyroscopeBiasCorrelationTime>
      <!-- Gyroscope bias correlation time constant [s] -->
      <gyroscopeTurnOnBiasSigma>0.0087</gyroscopeTurnOnBiasSigma>
      <!-- Gyroscope turn on bias standard deviation [rad/s] -->
      <accelerometerNoiseDensity>0.004</accelerometerNoiseDensity>
      <!-- Accelerometer noise density (two-sided spectrum) [m/s^2/sqrt(Hz)] -->
      <accelerometerRandomWalk>0.006</accelerometerRandomWalk>
      <!-- Accelerometer bias random walk. [m/s^2/s/sqrt(Hz)] -->
      <accelerometerBiasCorrelationTime>300.0</accelerometerBiasCorrelationTime>
      <!-- Accelerometer bias correlation time constant [s] -->
      <accelerometerTurnOnBiasSigma>0.196</accelerometerTurnOnBiasSigma>
      <!-- Accelerometer turn on bias standard deviation [m/s^2] -->
      <measurementDivisor>2</measurementDivisor>
      <!-- only every (seq % measurementDivisor) == 0 measurement is published [int] -->
    </plugin>
  </gazebo>
  <!-- odometry link -->
  <link name="ouzel/odometry_sensor1_link">
    <inertial>
      <inertia ixx="0.00001" ixy="0.0" ixz="0.0" iyy="0.00001" iyz="0.0" izz="0.00001"/>
      <mass value="1e-05"/>
      <!-- [kg] -->
    </inertial>
  </link>
  <!-- odometry joint -->
  <joint name="ouzel/odometry_sensor1_joint" type="revolute">
    <parent link="ouzel/base_link"/>
    <origin rpy="0.0 0.0 0.0" xyz="0.0 0.0 0.0"/>
    <child link="ouzel/odometry_sensor1_link"/>
    <limit effort="0" lower="0" upper="0" velocity="0"/>
  </joint>
  <gazebo>
    <plugin filename="librotors_gazebo_odometry_plugin.so" name="odometry_sensor1">
      <linkName>ouzel/odometry_sensor1_link</linkName>
      <robotNamespace>ouzel</robotNamespace>
      <poseTopic>odometry_sensor1/pose</poseTopic>
      <poseWithCovarianceTopic>odometry_sensor1/pose_with_covariance</poseWithCovarianceTopic>
      <positionTopic>odometry_sensor1/position</positionTopic>
      <transformTopic>odometry_sensor1/transform</transformTopic>
      <odometryTopic>odometry_sensor1/odometry</odometryTopic>
      <parentFrameId>world</parentFrameId>
      <!-- Use the scoped link name here. e.g. Model::link. -->
      <childFrameId>ouzel/odometry_sensor1</childFrameId>
      <measurementDivisor>16</measurementDivisor>
      <!-- only every (seq % measurementDivisor) == 0 measurement is published [int] -->
      <measurementDelay>0.002</measurementDelay>
      <!-- time that measurement gets held back before it's published in [simulation cycles (int)] -->
      <unknownDelay>0.0</unknownDelay>
      <!-- additional delay, that just gets added to the timestamp [s] -->
      <noiseNormalPosition>0.00075 0.001 0.0003</noiseNormalPosition>
      <!-- standard deviation of additive white gaussian noise [m] -->
      <noiseNormalQuaternion>0.00075 0.001 0.0003</noiseNormalQuaternion>
      <!-- standard deviation white gaussian noise [rad]: q_m = q*quaternionFromSmallAngleApproximation(noiseNormalQ) -->
      <noiseNormalLinearVelocity>0.003 0.003 0.003</noiseNormalLinearVelocity>
      <!-- standard deviation of additive white gaussian noise [m/s] -->
      <noiseNormalAngularVelocity>0.00075 0.001 0.0003</noiseNormalAngularVelocity>
      <!-- standard deviation of additive white gaussian noise [rad/s] -->
      <noiseUniformPosition>0.0001 0.0001 0.0001</noiseUniformPosition>
      <!-- symmetric bounds of uniform noise [m] -->
      <noiseUniformQuaternion>0.0001 0.0001 0.0001</noiseUniformQuaternion>
      <!-- symmetric bounds of uniform noise [rad], computation see above -->
      <noiseUniformLinearVelocity>0.0001 0.0001 0.0001</noiseUniformLinearVelocity>
      <!-- symmetric bounds of uniform noise [m/s] -->
      <noiseUniformAngularVelocity>0.0001 0.0001 0.0001</noiseUniformAngularVelocity>
    </plugin>
  </gazebo>

  <raisim_sensors>
    <plugin type="force" name="raisim_force_plugin">
      <robotNamespace>ouzel</robotNamespace>
        <!-- (string, required): ros namespace in which the messages are published -->
      <linkName>ouzel/base_link</linkName>
        <!-- (string, required): name of the body which holds the force sensor -->
      <topic>measured_interaction_wrench</topic>
    </plugin>

    <plugin type="contact" name="raisim_contact_plugin">
      <robotNamespace>ouzel</robotNamespace>
        <!-- (string, required): ros namespace in which the messages are published -->
      <linkName>ouzel/base_link</linkName>
        <!-- (string, required): name of the body which holds the contact sensor -->
      <topic>contact</topic>
    </plugin>
  </raisim_sensors>

</robot>
