

<?xml version="1.0" encoding="UTF-8"?>
<!-- =================================================================================== -->
<!-- |    This document was autogenerated by xacro from /home/eugenio/omav_ws/src/mav_tools/mav_description/urdf/ouzel_delta_base.xacro | -->
<!-- |    EDITING THIS FILE BY HAND IS NOT RECOMMENDED                                 | -->
<!-- =================================================================================== -->
<!--
  Copyright 2015 Fadri Furrer, ASL, ETH Zurich, Switzerland
  Copyright 2015 Michael Burri, ASL, ETH Zurich, Switzerland
  Copyright 2015 Mina Kamel, ASL, ETH Zurich, Switzerland
  Copyright 2015 Janosch Nikolic, ASL, ETH Zurich, Switzerland
  Copyright 2015 Markus Achtelik, ASL, ETH Zurich, Switzerland

  Licensed under the Apache License, Version 2.0 (the "License");
  you may not use this file except in compliance with the License.
  You may obtain a copy of the License at

  http://www.apache.org/licenses/LICENSE-2.0

  Unless required by applicable law or agreed to in writing, software
  distributed under the License is distributed on an "AS IS" BASIS,
  WITHOUT WARRANTIES OR CONDITIONS OF ANY KIND, either express or implied.
  See the License for the specific language governing permissions and
  limitations under the License.
-->
<robot name="ouzel">
   <!-- =============================================================== -->
   <!-- ==================== ROS INTERFACE MACRO ====================== -->
   <!-- =============================================================== -->
   <!-- <xacro:macro 
  		name="ros_interface_plugin_macro"
  		params="namespace">
    <gazebo>
      <plugin name="ros_interface_plugin" filename="librotors_gazebo_ros_interface_plugin.so">
        <robotNamespace>${namespace}</robotNamespace>
      </plugin>
    </gazebo>
  </xacro:macro>-->
   <link name="ouzel/base_link" />
   <joint name="ouzel/base_joint" type="fixed">
      <origin rpy="3.14 0 0" xyz="0 0 0" />
      <parent link="ouzel/base_link" />
      <child link="ouzel/base_link_inertia" />
   </joint>
   <link name="ouzel/base_link_inertia">
      <inertial>
         <mass value="2.53" />
         <!-- [kg] -->
         <origin xyz="0.0 0.0 0.03" />
         <inertia ixx="0.0075" ixy="-3.4208e-05" ixz="2.4695e-05" iyy="0.010939" iyz="-3.8826e-06" izz="0.01369" />
      </inertial>
      <visual>
         <origin rpy="0 0 0" xyz="0 0 0" />
         <geometry>
            <mesh filename="/home/eugenio/omav_ws/src/mav_tools/mav_description/meshes/ouzel_simple.stl" scale="1 1 1" />
         </geometry>
      </visual>
      <collision>
         <origin rpy="0 0 0" xyz="0 0 0" />
         <geometry>
            <mesh filename="/home/eugenio/omav_ws/src/mav_tools/mav_description/meshes/ouzel_simple.stl" scale="1 1 1" />
         </geometry>
      </collision>
      <surface>
         <friction>
            <ode>
               <mu>0.5</mu>
               <mu2>0.5</mu2>
            </ode>
         </friction>
         <bounce>
            <restitution_coefficient>0.01</restitution_coefficient>
            <threshold>0.01</threshold>
         </bounce>
         <contact>
            <ode>
               <max_vel>0.1</max_vel>
               <soft_cfm>0.8</soft_cfm>
               <soft_erp>0.8</soft_erp>
               <kd>2500</kd>
               <kp>10</kp>
               <min_depth>0.001</min_depth>
            </ode>
         </contact>
      </surface>
   </link>
   <!-- attach multirotor_base_plugin to the base_link -->
   <gazebo>
      <plugin filename="librotors_gazebo_multirotor_base_plugin.so" name="multirotor_base_plugin">
         <robotNamespace>ouzel</robotNamespace>
         <linkName>ouzel/base_link</linkName>
         <rotorVelocitySlowdownSim>10</rotorVelocitySlowdownSim>
      </plugin>
   </gazebo>
   <!-- Rotor tilt_unit -->
   <joint name="ouzel/tilt_unit_0_revolutejoint" type="continuous">
      <origin rpy="0 0 4.71238898038" xyz="0 -0.3 0" />
      <axis xyz="1 0 0" />
      <parent link="ouzel/base_link_inertia" />
      <child link="ouzel/tilt_unit_0" />
   </joint>
   <link name="ouzel/tilt_unit_0">
      <inertial>
         <mass value="0.277" />
         <!-- [kg] -->
         <inertia ixx="0.00034257" ixy="0" ixz="0" iyy="0.0013205" iyz="0" izz="0.0010037" />
         <!-- [kg m^2] [kg m^2] [kg m^2] [kg m^2] [kg m^2] [kg m^2] -->
      </inertial>
      <visual>
         <geometry>
            <mesh filename="/home/eugenio/omav_ws/src/rotors_simulator/rotors_description/meshes/omav/omav_tiltarm.dae" scale="1 1 1" />
         </geometry>
      </visual>
      <collision>
         <geometry>
            <box size="0.005 0.005 0.005" />
            <!-- [m] -->
         </geometry>
      </collision>
   </link>
   <gazebo>
      <plugin filename="librotors_gazebo_motor_model.so" name="right_tilt_unit_model">
         <robotNamespace>ouzel</robotNamespace>
         <jointName>ouzel/tilt_unit_0_revolutejoint</jointName>
         <linkName>ouzel/tilt_unit_0</linkName>
         <turningDirection>ccw</turningDirection>
         <motorType>position</motorType>
         <commandSubTopic>/gazebo/command/motor_speed</commandSubTopic>
         <motorNumber>12</motorNumber>
         <motorSpeedPubTopic>/tilt_motor_0/velocity</motorSpeedPubTopic>
         <motorPositionPubTopic>/tilt_motor_0/position</motorPositionPubTopic>
         <joint_control_pid>
            <p>1.0</p>
            <i>0.0</i>
            <d>0.01</d>
            <iMax>1.0</iMax>
            <iMin>-1.0</iMin>
            <cmdMax>2.0</cmdMax>
            <cmdMin>-2.0</cmdMin>
         </joint_control_pid>
      </plugin>
   </gazebo>
   <gazebo reference="ouzel/tilt_unit_0">
      <material>Gazebo/White</material>
   </gazebo>
   <!-- Upper Rotor -->
   <joint name="rotor_0_joint" type="continuous">
      <origin rpy="0 0 0" xyz="0 0 0.06" />
      <axis xyz="0 0 1" />
      <parent link="ouzel/tilt_unit_0" />
      <child link="rotor_0" />
   </joint>
   <link name="rotor_0">
      <inertial>
         <mass value="0.0065" />
         <!-- [kg] -->
         <inertia ixx="2.2154157805e-06" ixy="0.0" ixz="0.0" iyy="7.08147091741e-05" iyz="0.0" izz="7.29326249936e-05" />
      </inertial>
      <visual>
         <geometry>
            <mesh filename="/home/eugenio/omav_ws/src/rotors_simulator/rotors_description/meshes/propeller_ccw.dae" scale="0.1143 0.1143 0.1143" />
         </geometry>
      </visual>
      <collision>
         <geometry>
            <cylinder length="0.005" radius="0.1143" />
            <!-- [m] -->
         </geometry>
      </collision>
   </link>
   <gazebo>
      <plugin filename="librotors_gazebo_motor_model.so" name="right_upper_motor_model">
         <robotNamespace>ouzel</robotNamespace>
         <jointName>rotor_0_joint</jointName>
         <linkName>rotor_0</linkName>
         <turningDirection>ccw</turningDirection>
         <timeConstantUp>0.0125</timeConstantUp>
         <timeConstantDown>0.025</timeConstantDown>
         <maxRotVelocity>1700</maxRotVelocity>
         <motorConstant>7.2e-06</motorConstant>
         <momentConstant>0.015</momentConstant>
         <commandSubTopic>/gazebo/command/motor_speed</commandSubTopic>
         <motorNumber>0</motorNumber>
         <rotorDragCoefficient>8.06428e-05</rotorDragCoefficient>
         <rollingMomentCoefficient>1e-06</rollingMomentCoefficient>
         <motorSpeedPubTopic>/motor_speed/0_upper</motorSpeedPubTopic>
         <rotorVelocitySlowdownSim>10</rotorVelocitySlowdownSim>
      </plugin>
   </gazebo>
   <gazebo reference="rotor_0">
      <material>Gazebo/Black</material>
   </gazebo>
   <!-- Lower Rotor -->
   <joint name="rotor_6_joint" type="continuous">
      <origin rpy="0 0 0" xyz="0 0 -0.06" />
      <axis xyz="0 0 1" />
      <parent link="ouzel/tilt_unit_0" />
      <child link="rotor_6" />
   </joint>
   <link name="rotor_6">
      <inertial>
         <mass value="0.0065" />
         <!-- [kg] -->
         <inertia ixx="2.2154157805e-06" ixy="0.0" ixz="0.0" iyy="7.08147091741e-05" iyz="0.0" izz="7.29326249936e-05" />
      </inertial>
      <visual>
         <geometry>
            <mesh filename="/home/eugenio/omav_ws/src/rotors_simulator/rotors_description/meshes/propeller_cw.dae" scale="0.1143 0.1143 0.1143" />
         </geometry>
      </visual>
      <collision>
         <geometry>
            <cylinder length="0.005" radius="0.1143" />
            <!-- [m] -->
         </geometry>
      </collision>
   </link>
   <gazebo>
      <plugin filename="librotors_gazebo_motor_model.so" name="right_lower_motor_model">
         <robotNamespace>ouzel</robotNamespace>
         <jointName>rotor_6_joint</jointName>
         <linkName>rotor_6</linkName>
         <turningDirection>cw</turningDirection>
         <timeConstantUp>0.0125</timeConstantUp>
         <timeConstantDown>0.025</timeConstantDown>
         <maxRotVelocity>1700</maxRotVelocity>
         <motorConstant>7.2e-06</motorConstant>
         <momentConstant>0.005</momentConstant>
         <commandSubTopic>/gazebo/command/motor_speed</commandSubTopic>
         <motorNumber>6</motorNumber>
         <rotorDragCoefficient>8.06428e-05</rotorDragCoefficient>
         <rollingMomentCoefficient>1e-06</rollingMomentCoefficient>
         <motorSpeedPubTopic>/motor_speed/0_lower</motorSpeedPubTopic>
         <rotorVelocitySlowdownSim>10</rotorVelocitySlowdownSim>
      </plugin>
   </gazebo>
   <gazebo reference="rotor_6">
      <material>Gazebo/Black</material>
   </gazebo>
   <!-- Rotor tilt_unit -->
   <joint name="ouzel/tilt_unit_1_revolutejoint" type="continuous">
      <origin rpy="0 0 1.57079632679" xyz="0 0.3 0" />
      <axis xyz="1 0 0" />
      <parent link="ouzel/base_link_inertia" />
      <child link="ouzel/tilt_unit_1" />
   </joint>
   <link name="ouzel/tilt_unit_1">
      <inertial>
         <mass value="0.277" />
         <!-- [kg] -->
         <inertia ixx="0.00034257" ixy="0" ixz="0" iyy="0.0013205" iyz="0" izz="0.0010037" />
         <!-- [kg m^2] [kg m^2] [kg m^2] [kg m^2] [kg m^2] [kg m^2] -->
      </inertial>
      <visual>
         <geometry>
            <mesh filename="/home/eugenio/omav_ws/src/rotors_simulator/rotors_description/meshes/omav/omav_tiltarm.dae" scale="1 1 1" />
         </geometry>
      </visual>
      <collision>
         <geometry>
            <box size="0.005 0.005 0.005" />
            <!-- [m] -->
         </geometry>
      </collision>
   </link>
   <gazebo>
      <plugin filename="librotors_gazebo_motor_model.so" name="left_tilt_unit_model">
         <robotNamespace>ouzel</robotNamespace>
         <jointName>ouzel/tilt_unit_1_revolutejoint</jointName>
         <linkName>ouzel/tilt_unit_1</linkName>
         <turningDirection>ccw</turningDirection>
         <motorType>position</motorType>
         <commandSubTopic>/gazebo/command/motor_speed</commandSubTopic>
         <motorNumber>13</motorNumber>
         <motorSpeedPubTopic>/tilt_motor_1/velocity</motorSpeedPubTopic>
         <motorPositionPubTopic>/tilt_motor_1/position</motorPositionPubTopic>
         <joint_control_pid>
            <p>1.0</p>
            <i>0.0</i>
            <d>0.01</d>
            <iMax>1.0</iMax>
            <iMin>-1.0</iMin>
            <cmdMax>2.0</cmdMax>
            <cmdMin>-2.0</cmdMin>
         </joint_control_pid>
      </plugin>
   </gazebo>
   <gazebo reference="ouzel/tilt_unit_1">
      <material>Gazebo/White</material>
   </gazebo>
   <!-- Upper Rotor -->
   <joint name="rotor_1_joint" type="continuous">
      <origin rpy="0 0 0" xyz="0 0 0.06" />
      <axis xyz="0 0 1" />
      <parent link="ouzel/tilt_unit_1" />
      <child link="rotor_1" />
   </joint>
   <link name="rotor_1">
      <inertial>
         <mass value="0.0065" />
         <!-- [kg] -->
         <inertia ixx="2.2154157805e-06" ixy="0.0" ixz="0.0" iyy="7.08147091741e-05" iyz="0.0" izz="7.29326249936e-05" />
      </inertial>
      <visual>
         <geometry>
            <mesh filename="/home/eugenio/omav_ws/src/rotors_simulator/rotors_description/meshes/propeller_cw.dae" scale="0.1143 0.1143 0.1143" />
         </geometry>
      </visual>
      <collision>
         <geometry>
            <cylinder length="0.005" radius="0.1143" />
            <!-- [m] -->
         </geometry>
      </collision>
   </link>
   <gazebo>
      <plugin filename="librotors_gazebo_motor_model.so" name="left_upper_motor_model">
         <robotNamespace>ouzel</robotNamespace>
         <jointName>rotor_1_joint</jointName>
         <linkName>rotor_1</linkName>
         <turningDirection>cw</turningDirection>
         <timeConstantUp>0.0125</timeConstantUp>
         <timeConstantDown>0.025</timeConstantDown>
         <maxRotVelocity>1700</maxRotVelocity>
         <motorConstant>7.2e-06</motorConstant>
         <momentConstant>0.015</momentConstant>
         <commandSubTopic>/gazebo/command/motor_speed</commandSubTopic>
         <motorNumber>1</motorNumber>
         <rotorDragCoefficient>8.06428e-05</rotorDragCoefficient>
         <rollingMomentCoefficient>1e-06</rollingMomentCoefficient>
         <motorSpeedPubTopic>/motor_speed/1_upper</motorSpeedPubTopic>
         <rotorVelocitySlowdownSim>10</rotorVelocitySlowdownSim>
      </plugin>
   </gazebo>
   <gazebo reference="rotor_1">
      <material>Gazebo/Black</material>
   </gazebo>
   <!-- Lower Rotor -->
   <joint name="rotor_7_joint" type="continuous">
      <origin rpy="0 0 0" xyz="0 0 -0.06" />
      <axis xyz="0 0 1" />
      <parent link="ouzel/tilt_unit_1" />
      <child link="rotor_7" />
   </joint>
   <link name="rotor_7">
      <inertial>
         <mass value="0.0065" />
         <!-- [kg] -->
         <inertia ixx="2.2154157805e-06" ixy="0.0" ixz="0.0" iyy="7.08147091741e-05" iyz="0.0" izz="7.29326249936e-05" />
      </inertial>
      <visual>
         <geometry>
            <mesh filename="/home/eugenio/omav_ws/src/rotors_simulator/rotors_description/meshes/propeller_ccw.dae" scale="0.1143 0.1143 0.1143" />
         </geometry>
      </visual>
      <collision>
         <geometry>
            <cylinder length="0.005" radius="0.1143" />
            <!-- [m] -->
         </geometry>
      </collision>
   </link>
   <gazebo>
      <plugin filename="librotors_gazebo_motor_model.so" name="left_lower_motor_model">
         <robotNamespace>ouzel</robotNamespace>
         <jointName>rotor_7_joint</jointName>
         <linkName>rotor_7</linkName>
         <turningDirection>ccw</turningDirection>
         <timeConstantUp>0.0125</timeConstantUp>
         <timeConstantDown>0.025</timeConstantDown>
         <maxRotVelocity>1700</maxRotVelocity>
         <motorConstant>7.2e-06</motorConstant>
         <momentConstant>0.005</momentConstant>
         <commandSubTopic>/gazebo/command/motor_speed</commandSubTopic>
         <motorNumber>7</motorNumber>
         <rotorDragCoefficient>8.06428e-05</rotorDragCoefficient>
         <rollingMomentCoefficient>1e-06</rollingMomentCoefficient>
         <motorSpeedPubTopic>/motor_speed/1_lower</motorSpeedPubTopic>
         <rotorVelocitySlowdownSim>10</rotorVelocitySlowdownSim>
      </plugin>
   </gazebo>
   <gazebo reference="rotor_7">
      <material>Gazebo/Black</material>
   </gazebo>
   <!-- Rotor tilt_unit -->
   <joint name="ouzel/tilt_unit_2_revolutejoint" type="continuous">
      <origin rpy="0 0 0.52359877559" xyz="0.259807621135 0.15 0" />
      <axis xyz="1 0 0" />
      <parent link="ouzel/base_link_inertia" />
      <child link="ouzel/tilt_unit_2" />
   </joint>
   <link name="ouzel/tilt_unit_2">
      <inertial>
         <mass value="0.277" />
         <!-- [kg] -->
         <inertia ixx="0.00034257" ixy="0" ixz="0" iyy="0.0013205" iyz="0" izz="0.0010037" />
         <!-- [kg m^2] [kg m^2] [kg m^2] [kg m^2] [kg m^2] [kg m^2] -->
      </inertial>
      <visual>
         <geometry>
            <mesh filename="/home/eugenio/omav_ws/src/rotors_simulator/rotors_description/meshes/omav/omav_tiltarm.dae" scale="1 1 1" />
         </geometry>
      </visual>
      <collision>
         <geometry>
            <box size="0.005 0.005 0.005" />
            <!-- [m] -->
         </geometry>
      </collision>
   </link>
   <gazebo>
      <plugin filename="librotors_gazebo_motor_model.so" name="front_left_tilt_unit_model">
         <robotNamespace>ouzel</robotNamespace>
         <jointName>ouzel/tilt_unit_2_revolutejoint</jointName>
         <linkName>ouzel/tilt_unit_2</linkName>
         <turningDirection>ccw</turningDirection>
         <motorType>position</motorType>
         <commandSubTopic>/gazebo/command/motor_speed</commandSubTopic>
         <motorNumber>14</motorNumber>
         <motorSpeedPubTopic>/tilt_motor_2/velocity</motorSpeedPubTopic>
         <motorPositionPubTopic>/tilt_motor_2/position</motorPositionPubTopic>
         <joint_control_pid>
            <p>1.0</p>
            <i>0.0</i>
            <d>0.01</d>
            <iMax>1.0</iMax>
            <iMin>-1.0</iMin>
            <cmdMax>2.0</cmdMax>
            <cmdMin>-2.0</cmdMin>
         </joint_control_pid>
      </plugin>
   </gazebo>
   <gazebo reference="ouzel/tilt_unit_2">
      <material>Gazebo/White</material>
   </gazebo>
   <!-- Upper Rotor -->
   <joint name="rotor_2_joint" type="continuous">
      <origin rpy="0 0 0" xyz="0 0 0.06" />
      <axis xyz="0 0 1" />
      <parent link="ouzel/tilt_unit_2" />
      <child link="rotor_2" />
   </joint>
   <link name="rotor_2">
      <inertial>
         <mass value="0.0065" />
         <!-- [kg] -->
         <inertia ixx="2.2154157805e-06" ixy="0.0" ixz="0.0" iyy="7.08147091741e-05" iyz="0.0" izz="7.29326249936e-05" />
      </inertial>
      <visual>
         <geometry>
            <mesh filename="/home/eugenio/omav_ws/src/rotors_simulator/rotors_description/meshes/propeller_ccw.dae" scale="0.1143 0.1143 0.1143" />
         </geometry>
      </visual>
      <collision>
         <geometry>
            <cylinder length="0.005" radius="0.1143" />
            <!-- [m] -->
         </geometry>
      </collision>
   </link>
   <gazebo>
      <plugin filename="librotors_gazebo_motor_model.so" name="front_left_upper_motor_model">
         <robotNamespace>ouzel</robotNamespace>
         <jointName>rotor_2_joint</jointName>
         <linkName>rotor_2</linkName>
         <turningDirection>ccw</turningDirection>
         <timeConstantUp>0.0125</timeConstantUp>
         <timeConstantDown>0.025</timeConstantDown>
         <maxRotVelocity>1700</maxRotVelocity>
         <motorConstant>7.2e-06</motorConstant>
         <momentConstant>0.015</momentConstant>
         <commandSubTopic>/gazebo/command/motor_speed</commandSubTopic>
         <motorNumber>2</motorNumber>
         <rotorDragCoefficient>8.06428e-05</rotorDragCoefficient>
         <rollingMomentCoefficient>1e-06</rollingMomentCoefficient>
         <motorSpeedPubTopic>/motor_speed/2_upper</motorSpeedPubTopic>
         <rotorVelocitySlowdownSim>10</rotorVelocitySlowdownSim>
      </plugin>
   </gazebo>
   <gazebo reference="rotor_2">
      <material>Gazebo/Orange</material>
   </gazebo>
   <!-- Lower Rotor -->
   <joint name="rotor_8_joint" type="continuous">
      <origin rpy="0 0 0" xyz="0 0 -0.06" />
      <axis xyz="0 0 1" />
      <parent link="ouzel/tilt_unit_2" />
      <child link="rotor_8" />
   </joint>
   <link name="rotor_8">
      <inertial>
         <mass value="0.0065" />
         <!-- [kg] -->
         <inertia ixx="2.2154157805e-06" ixy="0.0" ixz="0.0" iyy="7.08147091741e-05" iyz="0.0" izz="7.29326249936e-05" />
      </inertial>
      <visual>
         <geometry>
            <mesh filename="/home/eugenio/omav_ws/src/rotors_simulator/rotors_description/meshes/propeller_cw.dae" scale="0.1143 0.1143 0.1143" />
         </geometry>
      </visual>
      <collision>
         <geometry>
            <cylinder length="0.005" radius="0.1143" />
            <!-- [m] -->
         </geometry>
      </collision>
   </link>
   <gazebo>
      <plugin filename="librotors_gazebo_motor_model.so" name="front_left_lower_motor_model">
         <robotNamespace>ouzel</robotNamespace>
         <jointName>rotor_8_joint</jointName>
         <linkName>rotor_8</linkName>
         <turningDirection>cw</turningDirection>
         <timeConstantUp>0.0125</timeConstantUp>
         <timeConstantDown>0.025</timeConstantDown>
         <maxRotVelocity>1700</maxRotVelocity>
         <motorConstant>7.2e-06</motorConstant>
         <momentConstant>0.005</momentConstant>
         <commandSubTopic>/gazebo/command/motor_speed</commandSubTopic>
         <motorNumber>8</motorNumber>
         <rotorDragCoefficient>8.06428e-05</rotorDragCoefficient>
         <rollingMomentCoefficient>1e-06</rollingMomentCoefficient>
         <motorSpeedPubTopic>/motor_speed/2_lower</motorSpeedPubTopic>
         <rotorVelocitySlowdownSim>10</rotorVelocitySlowdownSim>
      </plugin>
   </gazebo>
   <gazebo reference="rotor_8">
      <material>Gazebo/Orange</material>
   </gazebo>
   <!-- Rotor tilt_unit -->
   <joint name="ouzel/tilt_unit_3_revolutejoint" type="continuous">
      <origin rpy="0 0 3.66519142919" xyz="-0.259807621135 -0.15 0" />
      <axis xyz="1 0 0" />
      <parent link="ouzel/base_link_inertia" />
      <child link="ouzel/tilt_unit_3" />
   </joint>
   <link name="ouzel/tilt_unit_3">
      <inertial>
         <mass value="0.277" />
         <!-- [kg] -->
         <inertia ixx="0.00034257" ixy="0" ixz="0" iyy="0.0013205" iyz="0" izz="0.0010037" />
         <!-- [kg m^2] [kg m^2] [kg m^2] [kg m^2] [kg m^2] [kg m^2] -->
      </inertial>
      <visual>
         <geometry>
            <mesh filename="/home/eugenio/omav_ws/src/rotors_simulator/rotors_description/meshes/omav/omav_tiltarm.dae" scale="1 1 1" />
         </geometry>
      </visual>
      <collision>
         <geometry>
            <box size="0.005 0.005 0.005" />
            <!-- [m] -->
         </geometry>
      </collision>
   </link>
   <gazebo>
      <plugin filename="librotors_gazebo_motor_model.so" name="back_right_tilt_unit_model">
         <robotNamespace>ouzel</robotNamespace>
         <jointName>ouzel/tilt_unit_3_revolutejoint</jointName>
         <linkName>ouzel/tilt_unit_3</linkName>
         <turningDirection>ccw</turningDirection>
         <motorType>position</motorType>
         <commandSubTopic>/gazebo/command/motor_speed</commandSubTopic>
         <motorNumber>15</motorNumber>
         <motorSpeedPubTopic>/tilt_motor_3/velocity</motorSpeedPubTopic>
         <motorPositionPubTopic>/tilt_motor_3/position</motorPositionPubTopic>
         <joint_control_pid>
            <p>1.0</p>
            <i>0.0</i>
            <d>0.01</d>
            <iMax>1.0</iMax>
            <iMin>-1.0</iMin>
            <cmdMax>2.0</cmdMax>
            <cmdMin>-2.0</cmdMin>
         </joint_control_pid>
      </plugin>
   </gazebo>
   <gazebo reference="ouzel/tilt_unit_3">
      <material>Gazebo/White</material>
   </gazebo>
   <!-- Upper Rotor -->
   <joint name="rotor_3_joint" type="continuous">
      <origin rpy="0 0 0" xyz="0 0 0.06" />
      <axis xyz="0 0 1" />
      <parent link="ouzel/tilt_unit_3" />
      <child link="rotor_3" />
   </joint>
   <link name="rotor_3">
      <inertial>
         <mass value="0.0065" />
         <!-- [kg] -->
         <inertia ixx="2.2154157805e-06" ixy="0.0" ixz="0.0" iyy="7.08147091741e-05" iyz="0.0" izz="7.29326249936e-05" />
      </inertial>
      <visual>
         <geometry>
            <mesh filename="/home/eugenio/omav_ws/src/rotors_simulator/rotors_description/meshes/propeller_cw.dae" scale="0.1143 0.1143 0.1143" />
         </geometry>
      </visual>
      <collision>
         <geometry>
            <cylinder length="0.005" radius="0.1143" />
            <!-- [m] -->
         </geometry>
      </collision>
   </link>
   <gazebo>
      <plugin filename="librotors_gazebo_motor_model.so" name="back_right_upper_motor_model">
         <robotNamespace>ouzel</robotNamespace>
         <jointName>rotor_3_joint</jointName>
         <linkName>rotor_3</linkName>
         <turningDirection>cw</turningDirection>
         <timeConstantUp>0.0125</timeConstantUp>
         <timeConstantDown>0.025</timeConstantDown>
         <maxRotVelocity>1700</maxRotVelocity>
         <motorConstant>7.2e-06</motorConstant>
         <momentConstant>0.015</momentConstant>
         <commandSubTopic>/gazebo/command/motor_speed</commandSubTopic>
         <motorNumber>3</motorNumber>
         <rotorDragCoefficient>8.06428e-05</rotorDragCoefficient>
         <rollingMomentCoefficient>1e-06</rollingMomentCoefficient>
         <motorSpeedPubTopic>/motor_speed/3_upper</motorSpeedPubTopic>
         <rotorVelocitySlowdownSim>10</rotorVelocitySlowdownSim>
      </plugin>
   </gazebo>
   <gazebo reference="rotor_3">
      <material>Gazebo/DarkGrey</material>
   </gazebo>
   <!-- Lower Rotor -->
   <joint name="rotor_9_joint" type="continuous">
      <origin rpy="0 0 0" xyz="0 0 -0.06" />
      <axis xyz="0 0 1" />
      <parent link="ouzel/tilt_unit_3" />
      <child link="rotor_9" />
   </joint>
   <link name="rotor_9">
      <inertial>
         <mass value="0.0065" />
         <!-- [kg] -->
         <inertia ixx="2.2154157805e-06" ixy="0.0" ixz="0.0" iyy="7.08147091741e-05" iyz="0.0" izz="7.29326249936e-05" />
      </inertial>
      <visual>
         <geometry>
            <mesh filename="/home/eugenio/omav_ws/src/rotors_simulator/rotors_description/meshes/propeller_ccw.dae" scale="0.1143 0.1143 0.1143" />
         </geometry>
      </visual>
      <collision>
         <geometry>
            <cylinder length="0.005" radius="0.1143" />
            <!-- [m] -->
         </geometry>
      </collision>
   </link>
   <gazebo>
      <plugin filename="librotors_gazebo_motor_model.so" name="back_right_lower_motor_model">
         <robotNamespace>ouzel</robotNamespace>
         <jointName>rotor_9_joint</jointName>
         <linkName>rotor_9</linkName>
         <turningDirection>ccw</turningDirection>
         <timeConstantUp>0.0125</timeConstantUp>
         <timeConstantDown>0.025</timeConstantDown>
         <maxRotVelocity>1700</maxRotVelocity>
         <motorConstant>7.2e-06</motorConstant>
         <momentConstant>0.005</momentConstant>
         <commandSubTopic>/gazebo/command/motor_speed</commandSubTopic>
         <motorNumber>9</motorNumber>
         <rotorDragCoefficient>8.06428e-05</rotorDragCoefficient>
         <rollingMomentCoefficient>1e-06</rollingMomentCoefficient>
         <motorSpeedPubTopic>/motor_speed/3_lower</motorSpeedPubTopic>
         <rotorVelocitySlowdownSim>10</rotorVelocitySlowdownSim>
      </plugin>
   </gazebo>
   <gazebo reference="rotor_9">
      <material>Gazebo/DarkGrey</material>
   </gazebo>
   <!-- Rotor tilt_unit -->
   <joint name="ouzel/tilt_unit_4_revolutejoint" type="continuous">
      <origin rpy="0 0 5.75958653158" xyz="0.259807621135 -0.15 0" />
      <axis xyz="1 0 0" />
      <parent link="ouzel/base_link_inertia" />
      <child link="ouzel/tilt_unit_4" />
   </joint>
   <link name="ouzel/tilt_unit_4">
      <inertial>
         <mass value="0.277" />
         <!-- [kg] -->
         <inertia ixx="0.00034257" ixy="0" ixz="0" iyy="0.0013205" iyz="0" izz="0.0010037" />
         <!-- [kg m^2] [kg m^2] [kg m^2] [kg m^2] [kg m^2] [kg m^2] -->
      </inertial>
      <visual>
         <geometry>
            <mesh filename="/home/eugenio/omav_ws/src/rotors_simulator/rotors_description/meshes/omav/omav_tiltarm.dae" scale="1 1 1" />
         </geometry>
      </visual>
      <collision>
         <geometry>
            <box size="0.005 0.005 0.005" />
            <!-- [m] -->
         </geometry>
      </collision>
   </link>
   <gazebo>
      <plugin filename="librotors_gazebo_motor_model.so" name="front_right_tilt_unit_model">
         <robotNamespace>ouzel</robotNamespace>
         <jointName>ouzel/tilt_unit_4_revolutejoint</jointName>
         <linkName>ouzel/tilt_unit_4</linkName>
         <turningDirection>ccw</turningDirection>
         <motorType>position</motorType>
         <commandSubTopic>/gazebo/command/motor_speed</commandSubTopic>
         <motorNumber>16</motorNumber>
         <motorSpeedPubTopic>/tilt_motor_4/velocity</motorSpeedPubTopic>
         <motorPositionPubTopic>/tilt_motor_4/position</motorPositionPubTopic>
         <joint_control_pid>
            <p>1.0</p>
            <i>0.0</i>
            <d>0.01</d>
            <iMax>1.0</iMax>
            <iMin>-1.0</iMin>
            <cmdMax>2.0</cmdMax>
            <cmdMin>-2.0</cmdMin>
         </joint_control_pid>
      </plugin>
   </gazebo>
   <gazebo reference="ouzel/tilt_unit_4">
      <material>Gazebo/White</material>
   </gazebo>
   <!-- Upper Rotor -->
   <joint name="rotor_4_joint" type="continuous">
      <origin rpy="0 0 0" xyz="0 0 0.06" />
      <axis xyz="0 0 1" />
      <parent link="ouzel/tilt_unit_4" />
      <child link="rotor_4" />
   </joint>
   <link name="rotor_4">
      <inertial>
         <mass value="0.0065" />
         <!-- [kg] -->
         <inertia ixx="2.2154157805e-06" ixy="0.0" ixz="0.0" iyy="7.08147091741e-05" iyz="0.0" izz="7.29326249936e-05" />
      </inertial>
      <visual>
         <geometry>
            <mesh filename="/home/eugenio/omav_ws/src/rotors_simulator/rotors_description/meshes/propeller_cw.dae" scale="0.1143 0.1143 0.1143" />
         </geometry>
      </visual>
      <collision>
         <geometry>
            <cylinder length="0.005" radius="0.1143" />
            <!-- [m] -->
         </geometry>
      </collision>
   </link>
   <gazebo>
      <plugin filename="librotors_gazebo_motor_model.so" name="front_right_upper_motor_model">
         <robotNamespace>ouzel</robotNamespace>
         <jointName>rotor_4_joint</jointName>
         <linkName>rotor_4</linkName>
         <turningDirection>cw</turningDirection>
         <timeConstantUp>0.0125</timeConstantUp>
         <timeConstantDown>0.025</timeConstantDown>
         <maxRotVelocity>1700</maxRotVelocity>
         <motorConstant>7.2e-06</motorConstant>
         <momentConstant>0.015</momentConstant>
         <commandSubTopic>/gazebo/command/motor_speed</commandSubTopic>
         <motorNumber>4</motorNumber>
         <rotorDragCoefficient>8.06428e-05</rotorDragCoefficient>
         <rollingMomentCoefficient>1e-06</rollingMomentCoefficient>
         <motorSpeedPubTopic>/motor_speed/4_upper</motorSpeedPubTopic>
         <rotorVelocitySlowdownSim>10</rotorVelocitySlowdownSim>
      </plugin>
   </gazebo>
   <gazebo reference="rotor_4">
      <material>Gazebo/Orange</material>
   </gazebo>
   <!-- Lower Rotor -->
   <joint name="rotor_10_joint" type="continuous">
      <origin rpy="0 0 0" xyz="0 0 -0.06" />
      <axis xyz="0 0 1" />
      <parent link="ouzel/tilt_unit_4" />
      <child link="rotor_10" />
   </joint>
   <link name="rotor_10">
      <inertial>
         <mass value="0.0065" />
         <!-- [kg] -->
         <inertia ixx="2.2154157805e-06" ixy="0.0" ixz="0.0" iyy="7.08147091741e-05" iyz="0.0" izz="7.29326249936e-05" />
      </inertial>
      <visual>
         <geometry>
            <mesh filename="/home/eugenio/omav_ws/src/rotors_simulator/rotors_description/meshes/propeller_ccw.dae" scale="0.1143 0.1143 0.1143" />
         </geometry>
      </visual>
      <collision>
         <geometry>
            <cylinder length="0.005" radius="0.1143" />
            <!-- [m] -->
         </geometry>
      </collision>
   </link>
   <gazebo>
      <plugin filename="librotors_gazebo_motor_model.so" name="front_right_lower_motor_model">
         <robotNamespace>ouzel</robotNamespace>
         <jointName>rotor_10_joint</jointName>
         <linkName>rotor_10</linkName>
         <turningDirection>ccw</turningDirection>
         <timeConstantUp>0.0125</timeConstantUp>
         <timeConstantDown>0.025</timeConstantDown>
         <maxRotVelocity>1700</maxRotVelocity>
         <motorConstant>7.2e-06</motorConstant>
         <momentConstant>0.005</momentConstant>
         <commandSubTopic>/gazebo/command/motor_speed</commandSubTopic>
         <motorNumber>10</motorNumber>
         <rotorDragCoefficient>8.06428e-05</rotorDragCoefficient>
         <rollingMomentCoefficient>1e-06</rollingMomentCoefficient>
         <motorSpeedPubTopic>/motor_speed/4_lower</motorSpeedPubTopic>
         <rotorVelocitySlowdownSim>10</rotorVelocitySlowdownSim>
      </plugin>
   </gazebo>
   <gazebo reference="rotor_10">
      <material>Gazebo/Orange</material>
   </gazebo>
   <!-- Rotor tilt_unit -->
   <joint name="ouzel/tilt_unit_5_revolutejoint" type="continuous">
      <origin rpy="0 0 2.61799387799" xyz="-0.259807621135 0.15 0" />
      <axis xyz="1 0 0" />
      <parent link="ouzel/base_link_inertia" />
      <child link="ouzel/tilt_unit_5" />
   </joint>
   <link name="ouzel/tilt_unit_5">
      <inertial>
         <mass value="0.277" />
         <!-- [kg] -->
         <inertia ixx="0.00034257" ixy="0" ixz="0" iyy="0.0013205" iyz="0" izz="0.0010037" />
         <!-- [kg m^2] [kg m^2] [kg m^2] [kg m^2] [kg m^2] [kg m^2] -->
      </inertial>
      <visual>
         <geometry>
            <mesh filename="/home/eugenio/omav_ws/src/rotors_simulator/rotors_description/meshes/omav/omav_tiltarm.dae" scale="1 1 1" />
         </geometry>
      </visual>
      <collision>
         <geometry>
            <box size="0.005 0.005 0.005" />
            <!-- [m] -->
         </geometry>
      </collision>
   </link>
   <gazebo>
      <plugin filename="librotors_gazebo_motor_model.so" name="back_left_tilt_unit_model">
         <robotNamespace>ouzel</robotNamespace>
         <jointName>ouzel/tilt_unit_5_revolutejoint</jointName>
         <linkName>ouzel/tilt_unit_5</linkName>
         <turningDirection>ccw</turningDirection>
         <motorType>position</motorType>
         <commandSubTopic>/gazebo/command/motor_speed</commandSubTopic>
         <motorNumber>17</motorNumber>
         <motorSpeedPubTopic>/tilt_motor_5/velocity</motorSpeedPubTopic>
         <motorPositionPubTopic>/tilt_motor_5/position</motorPositionPubTopic>
         <joint_control_pid>
            <p>1.0</p>
            <i>0.0</i>
            <d>0.01</d>
            <iMax>1.0</iMax>
            <iMin>-1.0</iMin>
            <cmdMax>2.0</cmdMax>
            <cmdMin>-2.0</cmdMin>
         </joint_control_pid>
      </plugin>
   </gazebo>
   <gazebo reference="ouzel/tilt_unit_5">
      <material>Gazebo/White</material>
   </gazebo>
   <!-- Upper Rotor -->
   <joint name="rotor_5_joint" type="continuous">
      <origin rpy="0 0 0" xyz="0 0 0.06" />
      <axis xyz="0 0 1" />
      <parent link="ouzel/tilt_unit_5" />
      <child link="rotor_5" />
   </joint>
   <link name="rotor_5">
      <inertial>
         <mass value="0.0065" />
         <!-- [kg] -->
         <inertia ixx="2.2154157805e-06" ixy="0.0" ixz="0.0" iyy="7.08147091741e-05" iyz="0.0" izz="7.29326249936e-05" />
      </inertial>
      <visual>
         <geometry>
            <mesh filename="/home/eugenio/omav_ws/src/rotors_simulator/rotors_description/meshes/propeller_ccw.dae" scale="0.1143 0.1143 0.1143" />
         </geometry>
      </visual>
      <collision>
         <geometry>
            <cylinder length="0.005" radius="0.1143" />
            <!-- [m] -->
         </geometry>
      </collision>
   </link>
   <gazebo>
      <plugin filename="librotors_gazebo_motor_model.so" name="back_left_upper_motor_model">
         <robotNamespace>ouzel</robotNamespace>
         <jointName>rotor_5_joint</jointName>
         <linkName>rotor_5</linkName>
         <turningDirection>ccw</turningDirection>
         <timeConstantUp>0.0125</timeConstantUp>
         <timeConstantDown>0.025</timeConstantDown>
         <maxRotVelocity>1700</maxRotVelocity>
         <motorConstant>7.2e-06</motorConstant>
         <momentConstant>0.015</momentConstant>
         <commandSubTopic>/gazebo/command/motor_speed</commandSubTopic>
         <motorNumber>5</motorNumber>
         <rotorDragCoefficient>8.06428e-05</rotorDragCoefficient>
         <rollingMomentCoefficient>1e-06</rollingMomentCoefficient>
         <motorSpeedPubTopic>/motor_speed/5_upper</motorSpeedPubTopic>
         <rotorVelocitySlowdownSim>10</rotorVelocitySlowdownSim>
      </plugin>
   </gazebo>
   <gazebo reference="rotor_5">
      <material>Gazebo/DarkGrey</material>
   </gazebo>
   <!-- Lower Rotor -->
   <joint name="rotor_11_joint" type="continuous">
      <origin rpy="0 0 0" xyz="0 0 -0.06" />
      <axis xyz="0 0 1" />
      <parent link="ouzel/tilt_unit_5" />
      <child link="rotor_11" />
   </joint>
   <link name="rotor_11">
      <inertial>
         <mass value="0.0065" />
         <!-- [kg] -->
         <inertia ixx="2.2154157805e-06" ixy="0.0" ixz="0.0" iyy="7.08147091741e-05" iyz="0.0" izz="7.29326249936e-05" />
      </inertial>
      <visual>
         <geometry>
            <mesh filename="/home/eugenio/omav_ws/src/rotors_simulator/rotors_description/meshes/propeller_cw.dae" scale="0.1143 0.1143 0.1143" />
         </geometry>
      </visual>
      <collision>
         <geometry>
            <cylinder length="0.005" radius="0.1143" />
            <!-- [m] -->
         </geometry>
      </collision>
   </link>
   <gazebo>
      <plugin filename="librotors_gazebo_motor_model.so" name="back_left_lower_motor_model">
         <robotNamespace>ouzel</robotNamespace>
         <jointName>rotor_11_joint</jointName>
         <linkName>rotor_11</linkName>
         <turningDirection>cw</turningDirection>
         <timeConstantUp>0.0125</timeConstantUp>
         <timeConstantDown>0.025</timeConstantDown>
         <maxRotVelocity>1700</maxRotVelocity>
         <motorConstant>7.2e-06</motorConstant>
         <momentConstant>0.005</momentConstant>
         <commandSubTopic>/gazebo/command/motor_speed</commandSubTopic>
         <motorNumber>11</motorNumber>
         <rotorDragCoefficient>8.06428e-05</rotorDragCoefficient>
         <rollingMomentCoefficient>1e-06</rollingMomentCoefficient>
         <motorSpeedPubTopic>/motor_speed/5_lower</motorSpeedPubTopic>
         <rotorVelocitySlowdownSim>10</rotorVelocitySlowdownSim>
      </plugin>
   </gazebo>
   <gazebo reference="rotor_11">
      <material>Gazebo/DarkGrey</material>
   </gazebo>
   <gazebo>
      <plugin filename="librotors_gazebo_mavlink_interface.so" name="mavlink_interface">
         <robotNamespace>ouzel</robotNamespace>
         <imu_rate>102</imu_rate>
         <imuSubTopic>/imu</imuSubTopic>
         <mavlink_addr>INADDR_ANY</mavlink_addr>
         <mavlink_udp_port>14560</mavlink_udp_port>
         <motorSpeedCommandPubTopic>/gazebo/command/motor_speed</motorSpeedCommandPubTopic>
         <control_channels>
            <channel name="rotor0">
               <input_index>0</input_index>
               <input_offset>0</input_offset>
               <input_scaling>1700</input_scaling>
               <zero_position_disarmed>0</zero_position_disarmed>
               <zero_position_armed>100</zero_position_armed>
               <joint_control_type>velocity</joint_control_type>
            </channel>
            <channel name="rotor1">
               <input_index>1</input_index>
               <input_offset>0</input_offset>
               <input_scaling>1700</input_scaling>
               <zero_position_disarmed>0</zero_position_disarmed>
               <zero_position_armed>100</zero_position_armed>
               <joint_control_type>velocity</joint_control_type>
            </channel>
            <channel name="rotor2">
               <input_index>2</input_index>
               <input_offset>0</input_offset>
               <input_scaling>1700</input_scaling>
               <zero_position_disarmed>0</zero_position_disarmed>
               <zero_position_armed>100</zero_position_armed>
               <joint_control_type>velocity</joint_control_type>
            </channel>
            <channel name="rotor3">
               <input_index>3</input_index>
               <input_offset>0</input_offset>
               <input_scaling>1700</input_scaling>
               <zero_position_disarmed>0</zero_position_disarmed>
               <zero_position_armed>100</zero_position_armed>
               <joint_control_type>velocity</joint_control_type>
            </channel>
            <channel name="rotor4">
               <input_index>4</input_index>
               <input_offset>0</input_offset>
               <input_scaling>1700</input_scaling>
               <zero_position_disarmed>0</zero_position_disarmed>
               <zero_position_armed>100</zero_position_armed>
               <joint_control_type>velocity</joint_control_type>
            </channel>
            <channel name="rotor5">
               <input_index>5</input_index>
               <input_offset>0</input_offset>
               <input_scaling>1700</input_scaling>
               <zero_position_disarmed>0</zero_position_disarmed>
               <zero_position_armed>100</zero_position_armed>
               <joint_control_type>velocity</joint_control_type>
            </channel>
            <channel name="rotor6">
               <input_index>6</input_index>
               <input_offset>0</input_offset>
               <input_scaling>1700</input_scaling>
               <zero_position_disarmed>0</zero_position_disarmed>
               <zero_position_armed>100</zero_position_armed>
               <joint_control_type>velocity</joint_control_type>
            </channel>
            <channel name="rotor7">
               <input_index>7</input_index>
               <input_offset>0</input_offset>
               <input_scaling>1700</input_scaling>
               <zero_position_disarmed>0</zero_position_disarmed>
               <zero_position_armed>100</zero_position_armed>
               <joint_control_type>velocity</joint_control_type>
            </channel>
            <channel name="rotor8">
               <input_index>8</input_index>
               <input_offset>0</input_offset>
               <input_scaling>1700</input_scaling>
               <zero_position_disarmed>0</zero_position_disarmed>
               <zero_position_armed>100</zero_position_armed>
               <joint_control_type>velocity</joint_control_type>
            </channel>
            <channel name="rotor9">
               <input_index>9</input_index>
               <input_offset>0</input_offset>
               <input_scaling>1700</input_scaling>
               <zero_position_disarmed>0</zero_position_disarmed>
               <zero_position_armed>100</zero_position_armed>
               <joint_control_type>velocity</joint_control_type>
            </channel>
            <channel name="rotor10">
               <input_index>10</input_index>
               <input_offset>0</input_offset>
               <input_scaling>1700</input_scaling>
               <zero_position_disarmed>0</zero_position_disarmed>
               <zero_position_armed>100</zero_position_armed>
               <joint_control_type>velocity</joint_control_type>
            </channel>
            <channel name="rotor11">
               <input_index>11</input_index>
               <input_offset>0</input_offset>
               <input_scaling>1700</input_scaling>
               <zero_position_disarmed>0</zero_position_disarmed>
               <zero_position_armed>100</zero_position_armed>
               <joint_control_type>velocity</joint_control_type>
            </channel>
            <channel name="tilt_unit0">
               <input_index>12</input_index>
               <input_offset>0</input_offset>
               <input_scaling>31.4159</input_scaling>
               <zero_position_disarmed>0</zero_position_disarmed>
               <zero_position_armed>0</zero_position_armed>
               <joint_control_type>position</joint_control_type>
            </channel>
            <channel name="tilt_unit1">
               <input_index>13</input_index>
               <input_offset>0</input_offset>
               <input_scaling>31.4159</input_scaling>
               <zero_position_disarmed>0</zero_position_disarmed>
               <zero_position_armed>0</zero_position_armed>
               <joint_control_type>position</joint_control_type>
            </channel>
            <channel name="tilt_unit2">
               <input_index>14</input_index>
               <input_offset>0</input_offset>
               <input_scaling>31.4159</input_scaling>
               <zero_position_disarmed>0</zero_position_disarmed>
               <zero_position_armed>0</zero_position_armed>
               <joint_control_type>position</joint_control_type>
            </channel>
            <channel name="tilt_unit3">
               <input_index>15</input_index>
               <input_offset>0</input_offset>
               <input_scaling>31.4159</input_scaling>
               <zero_position_disarmed>0</zero_position_disarmed>
               <zero_position_armed>0</zero_position_armed>
               <joint_control_type>position</joint_control_type>
            </channel>
            <channel name="tilt_unit4">
               <input_index>16</input_index>
               <input_offset>0</input_offset>
               <input_scaling>31.4159</input_scaling>
               <zero_position_disarmed>0</zero_position_disarmed>
               <zero_position_armed>0</zero_position_armed>
               <joint_control_type>position</joint_control_type>
            </channel>
            <channel name="tilt_unit5">
               <input_index>17</input_index>
               <input_offset>0</input_offset>
               <input_scaling>31.4159</input_scaling>
               <zero_position_disarmed>0</zero_position_disarmed>
               <zero_position_armed>0</zero_position_armed>
               <joint_control_type>position</joint_control_type>
            </channel>
         </control_channels>
      </plugin>
   </gazebo>
   <gazebo>
      <plugin filename="librotors_gazebo_controller_interface.so" name="controller_interface">
         <robotNamespace>ouzel</robotNamespace>
         <commandAttitudeThrustSubTopic>command/attitude</commandAttitudeThrustSubTopic>
         <commandRateThrustSubTopic>command/rate</commandRateThrustSubTopic>
         <commandMotorSpeedSubTopic>command/motor_speed</commandMotorSpeedSubTopic>
         <imuSubTopic>imu</imuSubTopic>
         <motorSpeedCommandPubTopic>gazebo/command/motor_speed</motorSpeedCommandPubTopic>
      </plugin>
   </gazebo>
   <!-- IMU link -->
   <link name="ouzel/imu_link">
      <inertial>
         <inertia ixx="0.00001" ixy="0.0" ixz="0.0" iyy="0.00001" iyz="0.0" izz="0.00001" />
         <mass value="0.015" />
         <!-- [kg] -->
         <origin rpy="0 0 0" xyz="0 0 0" />
      </inertial>
   </link>
   <!-- IMU joint -->
   <joint name="ouzel/imu_joint" type="fixed">
      <origin rpy="0 0 0" xyz="0 0 0" />
      <parent link="ouzel/base_link_inertia" />
      <child link="ouzel/imu_link" />
      <limit effort="0" lower="0" upper="0" velocity="0" />
   </joint>
   <gazebo>
      <plugin filename="librotors_gazebo_imu_plugin.so" name="rotors_gazebo_imu_plugin">
         <!-- A good description of the IMU parameters can be found in the kalibr documentation:
           https://github.com/ethz-asl/kalibr/wiki/IMU-Noise-Model-and-Intrinsics -->
         <robotNamespace>ouzel</robotNamespace>
         <!-- (string, required): ros namespace in which the messages are published -->
         <linkName>ouzel/imu_link</linkName>
         <!-- (string, required): name of the body which holds the IMU sensor -->
         <imuTopic>imu</imuTopic>
         <!-- (string): name of the sensor output topic and prefix of service names (defaults to imu) -->
         <gyroscopeNoiseDensity>5.366563e-05</gyroscopeNoiseDensity>
         <!-- Gyroscope noise density (two-sided spectrum) [rad/s/sqrt(Hz)] -->
         <gyroscopeRandomWalk>3.8785e-05</gyroscopeRandomWalk>
         <!-- Gyroscope bias random walk [rad/s/s/sqrt(Hz)] -->
         <gyroscopeBiasCorrelationTime>1000.0</gyroscopeBiasCorrelationTime>
         <!-- Gyroscope bias correlation time constant [s] -->
         <gyroscopeTurnOnBiasSigma>0.0087</gyroscopeTurnOnBiasSigma>
         <!-- Gyroscope turn on bias standard deviation [rad/s] -->
         <accelerometerNoiseDensity>0.004</accelerometerNoiseDensity>
         <!-- Accelerometer noise density (two-sided spectrum) [m/s^2/sqrt(Hz)] -->
         <accelerometerRandomWalk>0.006</accelerometerRandomWalk>
         <!-- Accelerometer bias random walk. [m/s^2/s/sqrt(Hz)] -->
         <accelerometerBiasCorrelationTime>300.0</accelerometerBiasCorrelationTime>
         <!-- Accelerometer bias correlation time constant [s] -->
         <accelerometerTurnOnBiasSigma>0.196</accelerometerTurnOnBiasSigma>
         <!-- Accelerometer turn on bias standard deviation [m/s^2] -->
         <measurementDivisor>2</measurementDivisor>
         <!-- only every (seq % measurementDivisor) == 0 measurement is published [int] -->
      </plugin>
   </gazebo>
   <!-- IMU link -->
   <link name="ouzel/imugt_link">
      <inertial>
         <inertia ixx="0.00001" ixy="0.0" ixz="0.0" iyy="0.00001" iyz="0.0" izz="0.00001" />
         <mass value="1e-05" />
         <!-- [kg] -->
         <origin rpy="0 0 0" xyz="0 0 0" />
      </inertial>
   </link>
   <!-- IMU joint -->
   <joint name="ouzel/imugt_joint" type="fixed">
      <origin rpy="0 0 0" xyz="0 0 0" />
      <parent link="ouzel/base_link_inertia" />
      <child link="ouzel/imugt_link" />
      <limit effort="0" lower="0" upper="0" velocity="0" />
   </joint>
   <gazebo>
      <plugin filename="librotors_gazebo_imu_plugin.so" name="rotors_gazebo_imugt_plugin">
         <!-- A good description of the IMU parameters can be found in the kalibr documentation:
           https://github.com/ethz-asl/kalibr/wiki/IMU-Noise-Model-and-Intrinsics -->
         <robotNamespace>ouzel</robotNamespace>
         <!-- (string, required): ros namespace in which the messages are published -->
         <linkName>ouzel/imugt_link</linkName>
         <!-- (string, required): name of the body which holds the IMU sensor -->
         <imuTopic>ground_truth/imu</imuTopic>
         <!-- (string): name of the sensor output topic and prefix of service names (defaults to imu) -->
         <gyroscopeNoiseDensity>0.0</gyroscopeNoiseDensity>
         <!-- Gyroscope noise density (two-sided spectrum) [rad/s/sqrt(Hz)] -->
         <gyroscopeRandomWalk>0.0</gyroscopeRandomWalk>
         <!-- Gyroscope bias random walk [rad/s/s/sqrt(Hz)] -->
         <gyroscopeBiasCorrelationTime>1000.0</gyroscopeBiasCorrelationTime>
         <!-- Gyroscope bias correlation time constant [s] -->
         <gyroscopeTurnOnBiasSigma>0.0</gyroscopeTurnOnBiasSigma>
         <!-- Gyroscope turn on bias standard deviation [rad/s] -->
         <accelerometerNoiseDensity>0.0</accelerometerNoiseDensity>
         <!-- Accelerometer noise density (two-sided spectrum) [m/s^2/sqrt(Hz)] -->
         <accelerometerRandomWalk>0.0</accelerometerRandomWalk>
         <!-- Accelerometer bias random walk. [m/s^2/s/sqrt(Hz)] -->
         <accelerometerBiasCorrelationTime>300.0</accelerometerBiasCorrelationTime>
         <!-- Accelerometer bias correlation time constant [s] -->
         <accelerometerTurnOnBiasSigma>0.0</accelerometerTurnOnBiasSigma>
         <!-- Accelerometer turn on bias standard deviation [m/s^2] -->
         <measurementDivisor>1</measurementDivisor>
         <!-- only every (seq % measurementDivisor) == 0 measurement is published [int] -->
      </plugin>
   </gazebo>
   <!-- odometry link -->
   <link name="ouzel/odometry_sensorgt_link">
      <inertial>
         <inertia ixx="0.00001" ixy="0.0" ixz="0.0" iyy="0.00001" iyz="0.0" izz="0.00001" />
         <mass value="1e-05" />
         <!-- [kg] -->
      </inertial>
   </link>
   <!-- odometry joint -->
   <joint name="ouzel/odometry_sensorgt_joint" type="fixed">
      <parent link="ouzel/base_link_inertia" />
      <origin rpy="0.0 0.0 0.0" xyz="0.0 0.0 0.0" />
      <child link="ouzel/odometry_sensorgt_link" />
      <limit effort="0" lower="0" upper="0" velocity="0" />
   </joint>
   <gazebo>
      <plugin filename="librotors_gazebo_odometry_plugin.so" name="odometry_sensorgt">
         <linkName>ouzel/odometry_sensorgt_link</linkName>
         <robotNamespace>ouzel</robotNamespace>
         <poseTopic>ground_truth/pose</poseTopic>
         <poseWithCovarianceTopic>ground_truth/pose_with_covariance</poseWithCovarianceTopic>
         <positionTopic>ground_truth/position</positionTopic>
         <transformTopic>ground_truth/transform</transformTopic>
         <odometryTopic>ground_truth/odometry</odometryTopic>
         <parentFrameId>world</parentFrameId>
         <!-- Use the scoped link name here. e.g. Model::link. -->
         <childFrameId>ouzel/base_link</childFrameId>
         <measurementDivisor>1</measurementDivisor>
         <!-- only every (seq % measurementDivisor) == 0 measurement is published [int] -->
         <measurementDelay>0</measurementDelay>
         <!-- time that measurement gets held back before it's published in [simulation cycles (int)] -->
         <unknownDelay>0.0</unknownDelay>
         <!-- additional delay, that just gets added to the timestamp [s] -->
         <noiseNormalPosition>0 0 0</noiseNormalPosition>
         <!-- standard deviation of additive white gaussian noise [m] -->
         <noiseNormalQuaternion>0 0 0</noiseNormalQuaternion>
         <!-- standard deviation white gaussian noise [rad]: q_m = q*quaternionFromSmallAngleApproximation(noiseNormalQ) -->
         <noiseNormalLinearVelocity>0 0 0</noiseNormalLinearVelocity>
         <!-- standard deviation of additive white gaussian noise [m/s] -->
         <noiseNormalAngularVelocity>0 0 0</noiseNormalAngularVelocity>
         <!-- standard deviation of additive white gaussian noise [rad/s] -->
         <noiseUniformPosition>0 0 0</noiseUniformPosition>
         <!-- symmetric bounds of uniform noise [m] -->
         <noiseUniformQuaternion>0 0 0</noiseUniformQuaternion>
         <!-- symmetric bounds of uniform noise [rad], computation see above -->
         <noiseUniformLinearVelocity>0 0 0</noiseUniformLinearVelocity>
         <!-- symmetric bounds of uniform noise [m/s] -->
         <noiseUniformAngularVelocity>0 0 0</noiseUniformAngularVelocity>
      </plugin>
   </gazebo>
   <joint name="mounting_joint" type="fixed">
      <origin rpy="0.0 0.0 0.0" xyz="0 0 0.073" />
      <parent link="ouzel/base_link" />
      <child link="delta/delta_base_link" />
   </joint>
   <link name="delta/delta_base_link">
      <!--             <visual>
                <xacro:insert_block name="base_plate_origin"/>
                <xacro:insert_block name="base_plate_geometry"/>
            </visual> -->
      <!--             <collision>
                <xacro:insert_block name="base_plate_origin"/>
                <xacro:insert_block name="base_plate_geometry"/>
            </collision> -->
      <inertial>
         <origin rpy="0.0 0.0 0.0" xyz="0.0 0.0 0.0" />
         <mass value="0.25" />
         <inertia ixx="0.00345689322898" ixy="0.0" ixz="0.0" iyy="0.00345689322898" iyz="0.0" izz="0.0185914" />
      </inertial>
   </link>
   <link name="delta/delta_link1_0">
      <visual>
         <origin rpy="0.0 0.0 0.0" xyz="0.07791135 0.0 0.0" />
         <geometry>
            <box size="0.1558227 0.019 0.01" />
         </geometry>
      </visual>
      <collision>
         <origin rpy="0.0 0.0 0.0" xyz="0.07791135 0.0 0.0" />
         <geometry>
            <box size="0.1558227 0.019 0.01" />
         </geometry>
      </collision>
      <inertial>
         <origin rpy="0.0 0.0 0.0" xyz="0.07791135 0.0 0.0" />
         <mass value="0.041" />
         <inertia ixx="1.5744533e-05" ixy="0.0" ixz="0.0" iyy="0.000832674519617" iyz="0.0" izz="0.000841588452617" />
      </inertial>
   </link>
   <joint name="delta/delta_joint_upper_0" type="continuous">
      <parent link="delta/delta_base_link" />
      <child link="delta/delta_link1_0" />
      <origin rpy="0.0 0.0 0" xyz="0.0743656 0.0 0.0" />
      <axis xyz="0.0 1.0 0.0" />
      <limit effort="10.0" lower="-1.5707963268" upper="1.5707963268" velocity="5.0" />
      <safety_controller k_velocity="0.5" />
      <dynamics damping="0.001" friction="0.001" />
   </joint>
   <!--         <gazebo>
          <plugin name="delta_${suffix}_motor_model" filename="librotors_gazebo_motor_model.so">
            <robotNamespace>${delta_namespace}</robotNamespace>
            <jointName>${delta_namespace}/delta_joint_upper_${suffix}</jointName>
            <linkName>${delta_namespace}/delta_link1_${suffix}</linkName>
            <turningDirection>ccw</turningDirection>
            <motorType>position</motorType>
            <commandSubTopic>/gazebo/command/motor_speed</commandSubTopic>
            <motorNumber>${suffix+motor_start_index}</motorNumber>
            <motorSpeedPubTopic>/delta_motor_${suffix}/velocity</motorSpeedPubTopic>
            <motorPositionPubTopic>/delta_motor_${suffix}/position</motorPositionPubTopic>
            <joint_control_pid>
                <p>${delta_p_gain}</p>
                <i>${delta_i_gain}</i>
                <d>${delta_d_gain}</d>
                <iMax>1.0</iMax>
                <iMin>-1.0</iMin>
                <cmdMax>2.0</cmdMax>
                <cmdMin>-2.0</cmdMin>
            </joint_control_pid>
          </plugin>
        </gazebo> -->
   <gazebo>
      <link name="delta/delta_link2_right_0">
         <pose>0.232188299999 -0.0095 0.073 0 -0.9824450951 0</pose>
         <visual name="link2_right_0_visual">
            <pose frame="">0 0 0.1215283 0 0 0</pose>
            <geometry>
               <cylinder>
                  <length>0.2430566</length>
                  <radius>0.0024</radius>
               </cylinder>
            </geometry>
         </visual>
         <collision name="link2_right_0_collision">
            <pose frame="">0 0 0.1215283 0 0 0</pose>
            <geometry>
               <cylinder>
                  <length>0.2430566</length>
                  <radius>0.0024</radius>
               </cylinder>
            </geometry>
         </collision>
         <inertial>
            <pose frame="">0 0 0.1215283 0 0 0</pose>
            <mass>0.02</mass>
            <inertia>
               <ixx>0.000984502554787</ixx>
               <ixy>0</ixy>
               <ixz>0</ixz>
               <iyy>0.000984502554787</iyy>
               <iyz>0</iyz>
               <izz>4.8e-05</izz>
            </inertia>
         </inertial>
      </link>
   </gazebo>
   <gazebo>
      <link name="delta/delta_link2_left_0">
         <pose>0.232188299999 0.0095 0.073 0 -0.9824450951 0</pose>
         <visual name="link2_left_0_visual">
            <pose frame="">0 0 0.1215283 0 0 0</pose>
            <geometry>
               <cylinder>
                  <length>0.2430566</length>
                  <radius>0.0024</radius>
               </cylinder>
            </geometry>
         </visual>
         <collision name="link2_left_0_collision">
            <pose frame="">0 0 0.1215283 0 0 0</pose>
            <geometry>
               <cylinder>
                  <length>0.2430566</length>
                  <radius>0.0024</radius>
               </cylinder>
            </geometry>
         </collision>
         <inertial>
            <pose frame="">0 0 0.1215283 0 0 0</pose>
            <mass>0.02</mass>
            <inertia>
               <ixx>0.000984502554787</ixx>
               <ixy>0</ixy>
               <ixz>0</ixz>
               <iyy>0.000984502554787</iyy>
               <iyz>0</iyz>
               <izz>4.8e-05</izz>
            </inertia>
         </inertial>
      </link>
   </gazebo>
   <gazebo>
      <joint name="delta/delta_joint_middle_right_0" type="universal">
         <child>delta/delta_link2_right_0</child>
         <parent>delta/delta_link1_0</parent>
         <axis>
            <xyz>-0.0 1.0 0</xyz>
            <limit>
               <lower>-1e+16</lower>
               <upper>1e+16</upper>
            </limit>
            <dynamics>
               <damping>0.001</damping>
               <friction>0.001</friction>
               <spring_reference>0</spring_reference>
               <spring_stiffness>0</spring_stiffness>
            </dynamics>
            <use_parent_model_frame>1</use_parent_model_frame>
         </axis>
      </joint>
   </gazebo>
   <gazebo>
      <joint name="delta/delta_joint_middle_left_0" type="universal">
         <child>delta/delta_link2_left_0</child>
         <parent>delta/delta_link1_0</parent>
         <axis>
            <xyz>-0.0 1.0 0</xyz>
            <limit>
               <lower>-1e+16</lower>
               <upper>1e+16</upper>
            </limit>
            <dynamics>
               <damping>0.001</damping>
               <friction>0.001</friction>
               <spring_reference>0</spring_reference>
               <spring_stiffness>0</spring_stiffness>
            </dynamics>
            <use_parent_model_frame>1</use_parent_model_frame>
         </axis>
      </joint>
   </gazebo>
   <gazebo>
      <joint name="delta/delta_joint_lower_right_0" type="universal">
         <child>delta/delta_link2_right_0</child>
         <parent>delta/delta_tool_plate</parent>
         <pose>0 0 0.2430566 0 0 0</pose>
         <axis>
            <xyz>-0.0 1.0 0</xyz>
            <limit>
               <lower>-1e+16</lower>
               <upper>1e+16</upper>
            </limit>
            <dynamics>
               <damping>0.001</damping>
               <friction>0.001</friction>
               <spring_reference>0</spring_reference>
               <spring_stiffness>0</spring_stiffness>
            </dynamics>
            <use_parent_model_frame>1</use_parent_model_frame>
         </axis>
      </joint>
   </gazebo>
   <gazebo>
      <joint name="delta/delta_joint_lower_left_0" type="universal">
         <child>delta/delta_link2_left_0</child>
         <parent>delta/delta_tool_plate</parent>
         <pose>0 0 0.2430566 0 0 0</pose>
         <axis>
            <xyz>-0.0 1.0 0</xyz>
            <limit>
               <lower>-1e+16</lower>
               <upper>1e+16</upper>
            </limit>
            <dynamics>
               <damping>0.001</damping>
               <friction>0.001</friction>
               <spring_reference>0</spring_reference>
               <spring_stiffness>0</spring_stiffness>
            </dynamics>
            <use_parent_model_frame>1</use_parent_model_frame>
         </axis>
      </joint>
   </gazebo>
   <link name="delta/delta_link1_1">
      <visual>
         <origin rpy="0.0 0.0 0.0" xyz="0.07791135 0.0 0.0" />
         <geometry>
            <box size="0.1558227 0.019 0.01" />
         </geometry>
      </visual>
      <collision>
         <origin rpy="0.0 0.0 0.0" xyz="0.07791135 0.0 0.0" />
         <geometry>
            <box size="0.1558227 0.019 0.01" />
         </geometry>
      </collision>
      <inertial>
         <origin rpy="0.0 0.0 0.0" xyz="0.07791135 0.0 0.0" />
         <mass value="0.041" />
         <inertia ixx="1.5744533e-05" ixy="0.0" ixz="0.0" iyy="0.000832674519617" iyz="0.0" izz="0.000841588452617" />
      </inertial>
   </link>
   <joint name="delta/delta_joint_upper_1" type="continuous">
      <parent link="delta/delta_base_link" />
      <child link="delta/delta_link1_1" />
      <origin rpy="0.0 0.0 2.09439510239" xyz="-0.0371828 0.0644024987677 0.0" />
      <axis xyz="0.0 1.0 0.0" />
      <limit effort="10.0" lower="-1.5707963268" upper="1.5707963268" velocity="5.0" />
      <safety_controller k_velocity="0.5" />
      <dynamics damping="0.001" friction="0.001" />
   </joint>
   <!--         <gazebo>
          <plugin name="delta_${suffix}_motor_model" filename="librotors_gazebo_motor_model.so">
            <robotNamespace>${delta_namespace}</robotNamespace>
            <jointName>${delta_namespace}/delta_joint_upper_${suffix}</jointName>
            <linkName>${delta_namespace}/delta_link1_${suffix}</linkName>
            <turningDirection>ccw</turningDirection>
            <motorType>position</motorType>
            <commandSubTopic>/gazebo/command/motor_speed</commandSubTopic>
            <motorNumber>${suffix+motor_start_index}</motorNumber>
            <motorSpeedPubTopic>/delta_motor_${suffix}/velocity</motorSpeedPubTopic>
            <motorPositionPubTopic>/delta_motor_${suffix}/position</motorPositionPubTopic>
            <joint_control_pid>
                <p>${delta_p_gain}</p>
                <i>${delta_i_gain}</i>
                <d>${delta_d_gain}</d>
                <iMax>1.0</iMax>
                <iMin>-1.0</iMin>
                <cmdMax>2.0</cmdMax>
                <cmdMin>-2.0</cmdMin>
            </joint_control_pid>
          </plugin>
        </gazebo> -->
   <gazebo>
      <link name="delta/delta_link2_right_1">
         <pose>-0.107866908664 0.205830966261 0.073 0 -0.9824450951 2.09439510239</pose>
         <visual name="link2_right_1_visual">
            <pose frame="">0 0 0.1215283 0 0 0</pose>
            <geometry>
               <cylinder>
                  <length>0.2430566</length>
                  <radius>0.0024</radius>
               </cylinder>
            </geometry>
         </visual>
         <collision name="link2_right_1_collision">
            <pose frame="">0 0 0.1215283 0 0 0</pose>
            <geometry>
               <cylinder>
                  <length>0.2430566</length>
                  <radius>0.0024</radius>
               </cylinder>
            </geometry>
         </collision>
         <inertial>
            <pose frame="">0 0 0.1215283 0 0 0</pose>
            <mass>0.02</mass>
            <inertia>
               <ixx>0.000984502554787</ixx>
               <ixy>0</ixy>
               <ixz>0</ixz>
               <iyy>0.000984502554787</iyy>
               <iyz>0</iyz>
               <izz>4.8e-05</izz>
            </inertia>
         </inertial>
      </link>
   </gazebo>
   <gazebo>
      <link name="delta/delta_link2_left_1">
         <pose>-0.124321391336 0.196330966261 0.073 0 -0.9824450951 2.09439510239</pose>
         <visual name="link2_left_1_visual">
            <pose frame="">0 0 0.1215283 0 0 0</pose>
            <geometry>
               <cylinder>
                  <length>0.2430566</length>
                  <radius>0.0024</radius>
               </cylinder>
            </geometry>
         </visual>
         <collision name="link2_left_1_collision">
            <pose frame="">0 0 0.1215283 0 0 0</pose>
            <geometry>
               <cylinder>
                  <length>0.2430566</length>
                  <radius>0.0024</radius>
               </cylinder>
            </geometry>
         </collision>
         <inertial>
            <pose frame="">0 0 0.1215283 0 0 0</pose>
            <mass>0.02</mass>
            <inertia>
               <ixx>0.000984502554787</ixx>
               <ixy>0</ixy>
               <ixz>0</ixz>
               <iyy>0.000984502554787</iyy>
               <iyz>0</iyz>
               <izz>4.8e-05</izz>
            </inertia>
         </inertial>
      </link>
   </gazebo>
   <gazebo>
      <joint name="delta/delta_joint_middle_right_1" type="universal">
         <child>delta/delta_link2_right_1</child>
         <parent>delta/delta_link1_1</parent>
         <axis>
            <xyz>-0.866025403784 -0.5 0</xyz>
            <limit>
               <lower>-1e+16</lower>
               <upper>1e+16</upper>
            </limit>
            <dynamics>
               <damping>0.001</damping>
               <friction>0.001</friction>
               <spring_reference>0</spring_reference>
               <spring_stiffness>0</spring_stiffness>
            </dynamics>
            <use_parent_model_frame>1</use_parent_model_frame>
         </axis>
      </joint>
   </gazebo>
   <gazebo>
      <joint name="delta/delta_joint_middle_left_1" type="universal">
         <child>delta/delta_link2_left_1</child>
         <parent>delta/delta_link1_1</parent>
         <axis>
            <xyz>-0.866025403784 -0.5 0</xyz>
            <limit>
               <lower>-1e+16</lower>
               <upper>1e+16</upper>
            </limit>
            <dynamics>
               <damping>0.001</damping>
               <friction>0.001</friction>
               <spring_reference>0</spring_reference>
               <spring_stiffness>0</spring_stiffness>
            </dynamics>
            <use_parent_model_frame>1</use_parent_model_frame>
         </axis>
      </joint>
   </gazebo>
   <gazebo>
      <joint name="delta/delta_joint_lower_right_1" type="universal">
         <child>delta/delta_link2_right_1</child>
         <parent>delta/delta_tool_plate</parent>
         <pose>0 0 0.2430566 0 0 0</pose>
         <axis>
            <xyz>-0.866025403784 -0.5 0</xyz>
            <limit>
               <lower>-1e+16</lower>
               <upper>1e+16</upper>
            </limit>
            <dynamics>
               <damping>0.001</damping>
               <friction>0.001</friction>
               <spring_reference>0</spring_reference>
               <spring_stiffness>0</spring_stiffness>
            </dynamics>
            <use_parent_model_frame>1</use_parent_model_frame>
         </axis>
      </joint>
   </gazebo>
   <gazebo>
      <joint name="delta/delta_joint_lower_left_1" type="universal">
         <child>delta/delta_link2_left_1</child>
         <parent>delta/delta_tool_plate</parent>
         <pose>0 0 0.2430566 0 0 0</pose>
         <axis>
            <xyz>-0.866025403784 -0.5 0</xyz>
            <limit>
               <lower>-1e+16</lower>
               <upper>1e+16</upper>
            </limit>
            <dynamics>
               <damping>0.001</damping>
               <friction>0.001</friction>
               <spring_reference>0</spring_reference>
               <spring_stiffness>0</spring_stiffness>
            </dynamics>
            <use_parent_model_frame>1</use_parent_model_frame>
         </axis>
      </joint>
   </gazebo>
   <link name="delta/delta_link1_2">
      <visual>
         <origin rpy="0.0 0.0 0.0" xyz="0.07791135 0.0 0.0" />
         <geometry>
            <box size="0.1558227 0.019 0.01" />
         </geometry>
      </visual>
      <collision>
         <origin rpy="0.0 0.0 0.0" xyz="0.07791135 0.0 0.0" />
         <geometry>
            <box size="0.1558227 0.019 0.01" />
         </geometry>
      </collision>
      <inertial>
         <origin rpy="0.0 0.0 0.0" xyz="0.07791135 0.0 0.0" />
         <mass value="0.041" />
         <inertia ixx="1.5744533e-05" ixy="0.0" ixz="0.0" iyy="0.000832674519617" iyz="0.0" izz="0.000841588452617" />
      </inertial>
   </link>
   <joint name="delta/delta_joint_upper_2" type="continuous">
      <parent link="delta/delta_base_link" />
      <child link="delta/delta_link1_2" />
      <origin rpy="0.0 0.0 4.18879020479" xyz="-0.0371828 -0.0644024987677 0.0" />
      <axis xyz="0.0 1.0 0.0" />
      <limit effort="10.0" lower="-1.5707963268" upper="1.5707963268" velocity="5.0" />
      <safety_controller k_velocity="0.5" />
      <dynamics damping="0.001" friction="0.001" />
   </joint>
   <!--         <gazebo>
          <plugin name="delta_${suffix}_motor_model" filename="librotors_gazebo_motor_model.so">
            <robotNamespace>${delta_namespace}</robotNamespace>
            <jointName>${delta_namespace}/delta_joint_upper_${suffix}</jointName>
            <linkName>${delta_namespace}/delta_link1_${suffix}</linkName>
            <turningDirection>ccw</turningDirection>
            <motorType>position</motorType>
            <commandSubTopic>/gazebo/command/motor_speed</commandSubTopic>
            <motorNumber>${suffix+motor_start_index}</motorNumber>
            <motorSpeedPubTopic>/delta_motor_${suffix}/velocity</motorSpeedPubTopic>
            <motorPositionPubTopic>/delta_motor_${suffix}/position</motorPositionPubTopic>
            <joint_control_pid>
                <p>${delta_p_gain}</p>
                <i>${delta_i_gain}</i>
                <d>${delta_d_gain}</d>
                <iMax>1.0</iMax>
                <iMin>-1.0</iMin>
                <cmdMax>2.0</cmdMax>
                <cmdMin>-2.0</cmdMin>
            </joint_control_pid>
          </plugin>
        </gazebo> -->
   <gazebo>
      <link name="delta/delta_link2_right_2">
         <pose>-0.124321391336 -0.196330966261 0.073 0 -0.9824450951 4.18879020479</pose>
         <visual name="link2_right_2_visual">
            <pose frame="">0 0 0.1215283 0 0 0</pose>
            <geometry>
               <cylinder>
                  <length>0.2430566</length>
                  <radius>0.0024</radius>
               </cylinder>
            </geometry>
         </visual>
         <collision name="link2_right_2_collision">
            <pose frame="">0 0 0.1215283 0 0 0</pose>
            <geometry>
               <cylinder>
                  <length>0.2430566</length>
                  <radius>0.0024</radius>
               </cylinder>
            </geometry>
         </collision>
         <inertial>
            <pose frame="">0 0 0.1215283 0 0 0</pose>
            <mass>0.02</mass>
            <inertia>
               <ixx>0.000984502554787</ixx>
               <ixy>0</ixy>
               <ixz>0</ixz>
               <iyy>0.000984502554787</iyy>
               <iyz>0</iyz>
               <izz>4.8e-05</izz>
            </inertia>
         </inertial>
      </link>
   </gazebo>
   <gazebo>
      <link name="delta/delta_link2_left_2">
         <pose>-0.107866908664 -0.205830966261 0.073 0 -0.9824450951 4.18879020479</pose>
         <visual name="link2_left_2_visual">
            <pose frame="">0 0 0.1215283 0 0 0</pose>
            <geometry>
               <cylinder>
                  <length>0.2430566</length>
                  <radius>0.0024</radius>
               </cylinder>
            </geometry>
         </visual>
         <collision name="link2_left_2_collision">
            <pose frame="">0 0 0.1215283 0 0 0</pose>
            <geometry>
               <cylinder>
                  <length>0.2430566</length>
                  <radius>0.0024</radius>
               </cylinder>
            </geometry>
         </collision>
         <inertial>
            <pose frame="">0 0 0.1215283 0 0 0</pose>
            <mass>0.02</mass>
            <inertia>
               <ixx>0.000984502554787</ixx>
               <ixy>0</ixy>
               <ixz>0</ixz>
               <iyy>0.000984502554787</iyy>
               <iyz>0</iyz>
               <izz>4.8e-05</izz>
            </inertia>
         </inertial>
      </link>
   </gazebo>
   <gazebo>
      <joint name="delta/delta_joint_middle_right_2" type="universal">
         <child>delta/delta_link2_right_2</child>
         <parent>delta/delta_link1_2</parent>
         <axis>
            <xyz>0.866025403785 -0.5 0</xyz>
            <limit>
               <lower>-1e+16</lower>
               <upper>1e+16</upper>
            </limit>
            <dynamics>
               <damping>0.001</damping>
               <friction>0.001</friction>
               <spring_reference>0</spring_reference>
               <spring_stiffness>0</spring_stiffness>
            </dynamics>
            <use_parent_model_frame>1</use_parent_model_frame>
         </axis>
      </joint>
   </gazebo>
   <gazebo>
      <joint name="delta/delta_joint_middle_left_2" type="universal">
         <child>delta/delta_link2_left_2</child>
         <parent>delta/delta_link1_2</parent>
         <axis>
            <xyz>0.866025403785 -0.5 0</xyz>
            <limit>
               <lower>-1e+16</lower>
               <upper>1e+16</upper>
            </limit>
            <dynamics>
               <damping>0.001</damping>
               <friction>0.001</friction>
               <spring_reference>0</spring_reference>
               <spring_stiffness>0</spring_stiffness>
            </dynamics>
            <use_parent_model_frame>1</use_parent_model_frame>
         </axis>
      </joint>
   </gazebo>
   <gazebo>
      <joint name="delta/delta_joint_lower_right_2" type="universal">
         <child>delta/delta_link2_right_2</child>
         <parent>delta/delta_tool_plate</parent>
         <pose>0 0 0.2430566 0 0 0</pose>
         <axis>
            <xyz>0.866025403785 -0.5 0</xyz>
            <limit>
               <lower>-1e+16</lower>
               <upper>1e+16</upper>
            </limit>
            <dynamics>
               <damping>0.001</damping>
               <friction>0.001</friction>
               <spring_reference>0</spring_reference>
               <spring_stiffness>0</spring_stiffness>
            </dynamics>
            <use_parent_model_frame>1</use_parent_model_frame>
         </axis>
      </joint>
   </gazebo>
   <gazebo>
      <joint name="delta/delta_joint_lower_left_2" type="universal">
         <child>delta/delta_link2_left_2</child>
         <parent>delta/delta_tool_plate</parent>
         <pose>0 0 0.2430566 0 0 0</pose>
         <axis>
            <xyz>0.866025403785 -0.5 0</xyz>
            <limit>
               <lower>-1e+16</lower>
               <upper>1e+16</upper>
            </limit>
            <dynamics>
               <damping>0.001</damping>
               <friction>0.001</friction>
               <spring_reference>0</spring_reference>
               <spring_stiffness>0</spring_stiffness>
            </dynamics>
            <use_parent_model_frame>1</use_parent_model_frame>
         </axis>
      </joint>
   </gazebo>
   <gazebo>
      <link name="delta/delta_tool_plate">
         <pose>0.03 -0.0095 0.209122181888 0 0 0</pose>
         <visual name="tool_plate_visual">
            <pose frame="">-0.03 0.0095 0 0 0 0</pose>
            <geometry>
               <cylinder>
                  <length>0.01</length>
                  <radius>0.03</radius>
               </cylinder>
            </geometry>
         </visual>
         <collision name="tool_plate_collision">
            <pose frame="">-0.03 0.0095 0 0 0 0</pose>
            <geometry>
               <cylinder>
                  <length>0.01</length>
                  <radius>0.03</radius>
               </cylinder>
            </geometry>
         </collision>
         <inertial>
            <pose frame="">-0.03 0.0095 0 0 0 0</pose>
            <mass>0.0233</mass>
            <inertia>
               <ixx>5.434492e-05</ixx>
               <ixy>0</ixy>
               <ixz>0</ixz>
               <iyy>5.434492e-05</iyy>
               <iyz>0</iyz>
               <izz>0.000699</izz>
            </inertia>
         </inertial>
      </link>
   </gazebo>
   <gazebo>
      <!-- odometry link -->
      <link name="delta/odometry_sensor_tool_link">
         <pose>0 0 0.209122181888 0 0 0</pose>
         <inertial>
            <pose frame="">0 0 0 0 0 0</pose>
            <mass>1e-05</mass>
            <inertia>
               <ixx>1e-05</ixx>
               <ixy>0</ixy>
               <ixz>0</ixz>
               <iyy>1e-05</iyy>
               <iyz>0</iyz>
               <izz>1e-05</izz>
            </inertia>
         </inertial>
      </link>
      <!-- odometry joint -->
      <joint name="delta/odometry_sensortool_joint" type="revolute">
         <parent>delta/delta_tool_plate</parent>
         <child>delta/odometry_sensor_tool_link</child>
         <pose>0 0 0 0 0 0</pose>
         <axis>
            <xyz>1 0 0</xyz>
            <limit>
               <lower>0</lower>
               <upper>0</upper>
            </limit>
            <dynamics>
               <damping>0.001</damping>
               <friction>0.001</friction>
               <spring_reference>0</spring_reference>
               <spring_stiffness>0</spring_stiffness>
            </dynamics>
            <use_parent_model_frame>1</use_parent_model_frame>
         </axis>
      </joint>
      <plugin filename="librotors_gazebo_odometry_plugin.so" name="odometry_sensor_tool">
         <linkName>delta/odometry_sensor_tool_link</linkName>
         <robotNamespace>delta</robotNamespace>
         <poseTopic>odometry_sensor_tool/pose</poseTopic>
         <poseWithCovarianceTopic>odometry_sensor_tool/pose_with_covariance</poseWithCovarianceTopic>
         <positionTopic>odometry_sensor_tool/position</positionTopic>
         <transformTopic>odometry_sensor_tool/transform</transformTopic>
         <odometryTopic>odometry_sensor_tool/odometry</odometryTopic>
         <parentFrameId>world</parentFrameId>
         <!-- Use the scoped link name here. e.g. Model::link. -->
         <childFrameId>delta/odometry_sensor_tool</childFrameId>
         <measurementDivisor>16</measurementDivisor>
         <!-- only every (seq % measurementDivisor) == 0 measurement is published [int] -->
         <measurementDelay>0.002</measurementDelay>
         <!-- time that measurement gets held back before it's published in [simulation cycles (int)] -->
         <unknownDelay>0.0</unknownDelay>
         <!-- additional delay, that just gets added to the timestamp [s] -->
         <noiseNormalPosition>0.0001 0.0001 0.0001</noiseNormalPosition>
         <!-- standard deviation of additive white gaussian noise [m] -->
         <noiseNormalQuaternion>0.0001 0.0001 0.0001</noiseNormalQuaternion>
         <!-- standard deviation white gaussian noise [rad]: q_m = q*quaternionFromSmallAngleApproximation(noiseNormalQ) -->
         <noiseNormalLinearVelocity>0.001 0.001 0.001</noiseNormalLinearVelocity>
         <!-- standard deviation of additive white gaussian noise [m/s] -->
         <noiseNormalAngularVelocity>0.001 0.001 0.001</noiseNormalAngularVelocity>
         <!-- standard deviation of additive white gaussian noise [rad/s] -->
         <noiseUniformPosition>0.0001 0.0001 0.0001</noiseUniformPosition>
         <!-- symmetric bounds of uniform noise [m] -->
         <noiseUniformQuaternion>0.0001 0.0001 0.0001</noiseUniformQuaternion>
         <!-- symmetric bounds of uniform noise [rad], computation see above -->
         <noiseUniformLinearVelocity>0.0001 0.0001 0.0001</noiseUniformLinearVelocity>
         <!-- symmetric bounds of uniform noise [m/s] -->
         <noiseUniformAngularVelocity>0.0001 0.0001 0.0001</noiseUniformAngularVelocity>
         <!-- symmetric bounds of uniform noise [rad/s] -->
      </plugin>
   </gazebo>
   <!-- Relationship between the p, d gain and the closed-loop dynamics behaviour of the system:
  It behaves like a second-order system in the frequency domain: Y(s) = U(s)*(ds + p)/(Is**2 + ds + p)
  Y(s) is the Laplace transform of the actual tilt motor angle and U(s) is the one of the tilt motor angle command, p and d are the gains, I is the inertia of the link.
  The pid gain set here corresponds to p = 1200, i = 1000, d =500 on the firmware.
   -->
   <!-- Add motors. -->
   <gazebo>
      <plugin filename="librotors_gazebo_multimotor_plugin.so" name="delta_multimotor_plugin">
         <robotNamespace>delta</robotNamespace>
         <servos>
            <servo>
               <jointName>delta/delta_joint_upper_0</jointName>
               <spinDirection>cw</spinDirection>
               <controlMode>position</controlMode>
               <maxRotVelocity>10</maxRotVelocity>
               <minRotPosition>-3.14159265359</minRotPosition>
               <maxRotPosition>3.14159265359</maxRotPosition>
               <zeroOffset>0.0</zeroOffset>
               <joint_control_pid>
                  <p>5.0</p>
                  <i>0.1</i>
                  <d>1.0</d>
                  <iMax>20.0</iMax>
                  <iMin>-20.0</iMin>
                  <cmdMax>100.0</cmdMax>
                  <cmdMin>-100.0</cmdMin>
               </joint_control_pid>
            </servo>
            <servo>
               <jointName>delta/delta_joint_upper_1</jointName>
               <spinDirection>cw</spinDirection>
               <controlMode>position</controlMode>
               <maxRotVelocity>10</maxRotVelocity>
               <minRotPosition>-3.14159265359</minRotPosition>
               <maxRotPosition>3.14159265359</maxRotPosition>
               <zeroOffset>0.0</zeroOffset>
               <joint_control_pid>
                  <p>5.0</p>
                  <i>0.1</i>
                  <d>1.0</d>
                  <iMax>20.0</iMax>
                  <iMin>-20.0</iMin>
                  <cmdMax>100.0</cmdMax>
                  <cmdMin>-100.0</cmdMin>
               </joint_control_pid>
            </servo>
            <servo>
               <jointName>delta/delta_joint_upper_2</jointName>
               <spinDirection>cw</spinDirection>
               <controlMode>position</controlMode>
               <maxRotVelocity>10</maxRotVelocity>
               <minRotPosition>-3.14159265359</minRotPosition>
               <maxRotPosition>3.14159265359</maxRotPosition>
               <zeroOffset>0.0</zeroOffset>
               <joint_control_pid>
                  <p>5.0</p>
                  <i>0.1</i>
                  <d>1.0</d>
                  <iMax>20.0</iMax>
                  <iMin>-20.0</iMin>
                  <cmdMax>100.0</cmdMax>
                  <cmdMin>-100.0</cmdMin>
               </joint_control_pid>
            </servo>
         </servos>
      </plugin>
   </gazebo>
   <!-- odometry link -->
   <link name="ouzel/odometry_sensor1_link">
      <inertial>
         <inertia ixx="0.00001" ixy="0.0" ixz="0.0" iyy="0.00001" iyz="0.0" izz="0.00001" />
         <mass value="1e-05" />
         <!-- [kg] -->
      </inertial>
   </link>
   <!-- odometry joint -->
   <joint name="ouzel/odometry_sensor1_joint" type="fixed">
      <parent link="ouzel/base_link_inertia" />
      <origin rpy="0.0 0.0 0.0" xyz="0.0 0.0 0.0" />
      <child link="ouzel/odometry_sensor1_link" />
      <limit effort="0" lower="0" upper="0" velocity="0" />
   </joint>
   <gazebo>
      <plugin filename="librotors_gazebo_odometry_plugin.so" name="odometry_sensor1">
         <linkName>ouzel/odometry_sensor1_link</linkName>
         <robotNamespace>ouzel</robotNamespace>
         <poseTopic>odometry_sensor1/pose</poseTopic>
         <poseWithCovarianceTopic>odometry_sensor1/pose_with_covariance</poseWithCovarianceTopic>
         <positionTopic>odometry_sensor1/position</positionTopic>
         <transformTopic>odometry_sensor1/transform</transformTopic>
         <odometryTopic>odometry_sensor1/odometry</odometryTopic>
         <parentFrameId>world</parentFrameId>
         <!-- Use the scoped link name here. e.g. Model::link. -->
         <childFrameId>ouzel/odometry_sensor1</childFrameId>
         <measurementDivisor>16</measurementDivisor>
         <!-- only every (seq % measurementDivisor) == 0 measurement is published [int] -->
         <measurementDelay>0.002</measurementDelay>
         <!-- time that measurement gets held back before it's published in [simulation cycles (int)] -->
         <unknownDelay>0.0</unknownDelay>
         <!-- additional delay, that just gets added to the timestamp [s] -->
         <noiseNormalPosition>0.00075 0.001 0.0003</noiseNormalPosition>
         <!-- standard deviation of additive white gaussian noise [m] -->
         <noiseNormalQuaternion>0.00075 0.001 0.0003</noiseNormalQuaternion>
         <!-- standard deviation white gaussian noise [rad]: q_m = q*quaternionFromSmallAngleApproximation(noiseNormalQ) -->
         <noiseNormalLinearVelocity>0.003 0.003 0.003</noiseNormalLinearVelocity>
         <!-- standard deviation of additive white gaussian noise [m/s] -->
         <noiseNormalAngularVelocity>0.00075 0.001 0.0003</noiseNormalAngularVelocity>
         <!-- standard deviation of additive white gaussian noise [rad/s] -->
         <noiseUniformPosition>0.0001 0.0001 0.0001</noiseUniformPosition>
         <!-- symmetric bounds of uniform noise [m] -->
         <noiseUniformQuaternion>0.0001 0.0001 0.0001</noiseUniformQuaternion>
         <!-- symmetric bounds of uniform noise [rad], computation see above -->
         <noiseUniformLinearVelocity>0.0001 0.0001 0.0001</noiseUniformLinearVelocity>
         <!-- symmetric bounds of uniform noise [m/s] -->
         <noiseUniformAngularVelocity>0.0001 0.0001 0.0001</noiseUniformAngularVelocity>
      </plugin>
   </gazebo>
</robot>

