<?xml version="1.0" encoding="utf-8" ?><!-- =================================================================================== --><!-- |    This document was autogenerated by xacro from /home/eugenio/omav_ws/src/mav_tools/mav_description/urdf/delta_tests.urdf | --><!-- |    EDITING THIS FILE BY HAND IS NOT RECOMMENDED                                 | --><!-- =================================================================================== --><robot name="ouzel"><link name="delta/delta_base_link"><visual><origin rpy="0.0 0.0 0.0" xyz="0.0 0.0 0.0" /><geometry><cylinder length="0.01" radius="0.1" /></geometry></visual><inertial><origin rpy="0.0 0.0 0.0" xyz="0.0 0.0 0.0" /><mass value="10.25" /><inertia ixx="0.00345689322898" ixy="0.0" ixz="0.0" iyy="0.00345689322898" iyz="0.0" izz="0.0185914" /></inertial></link><link name="delta/delta_link1_0"><visual><origin rpy="0.0 0.0 0.0" xyz="0.07791135 0.0 0.0" /><geometry><box size="0.1558227 0.019 0.01" /></geometry></visual><collision><origin rpy="0.0 0.0 0.0" xyz="0.07791135 0.0 0.0" /><geometry><box size="0.1558227 0.019 0.01" /></geometry></collision><inertial><origin rpy="0.0 0.0 0.0" xyz="0.07791135 0.0 0.0" /><mass value="0.041" /><inertia ixx="1.5744533e-05" ixy="0.0" ixz="0.0" iyy="0.000832674519617" iyz="0.0" izz="0.000841588452617" /></inertial></link><joint name="delta/delta_joint_upper_0" type="continuous"><parent link="delta/delta_base_link" /><child link="delta/delta_link1_0" /><origin rpy="0.0 0.0 0" xyz="0.0743656 0.0 0.0" /><axis xyz="0.0 1.0 0.0" /><limit effort="10.0" lower="-1.5707963268" upper="1.5707963268" velocity="5.0" /><safety_controller k_velocity="0.5" /><dynamics damping="0.001" friction="0.001" /></joint><link name="delta/delta_link2_right_0"><!-- <origin rpy="0 -0.9824450951 0" xyz="0.232188299999 -0.0095 0.073"/> --><visual><origin rpy="0 0 0" xyz="0 0 0.1215283" /><geometry><cylinder length="0.2430566" radius="0.0024" /></geometry></visual><inertial><origin rpy="0 0 0" xyz="0 0 0.1215283" /><mass value="0.02" /><inertia ixx="0.000984502554787" ixy="0" ixz="0" iyy="0.000984502554787" iyz="0" izz="4.8e-05" /></inertial></link><link name="delta/delta_link2_left_0"><!-- <origin rpy="0 -0.9824450951 0" xyz="0.232188299999 0.0095 0.073"/> --><visual><origin rpy="0 0 0" xyz="0 0 0.1215283" /><geometry><cylinder length="0.2430566" radius="0.0024" /></geometry></visual><inertial><origin rpy="0 0 0" xyz="0 0 0.1215283" /><mass value="0.02" /><inertia ixx="0.000984502554787" ixy="0" ixz="0" iyy="0.000984502554787" iyz="0" izz="4.8e-05" /></inertial></link><joint name="delta/delta_joint_middle_right_0" type="continuous"><child link="delta/delta_link2_right_0" /><parent link="delta/delta_link1_0" /><axis xyz="-0.0 1.0 0" /><limit effort="10.0" lower="-1.5707963268" upper="1.5707963268" velocity="5.0" /><origin xyz="0.1558227 -0.0095 0.0" /></joint><joint name="delta/delta_joint_middle_left_0" type="continuous"><child link="delta/delta_link2_left_0" /><parent link="delta/delta_link1_0" /><axis xyz="-0.0 1.0 0" /><limit effort="10.0" lower="-1.5707963268" upper="1.5707963268" velocity="5.0" /><origin xyz="0.1558227 0.0095 0.0" /></joint><joint name="delta/delta_joint_lower_right_0" type="fixed"><child link="delta/delta_link2_right_0" /><parent link="delta/delta_tool_plate" /><origin rpy="0 0 0" xyz="0 0 0.2430566" /><axis xyz="-0.0 1.0 0" /><!-- <limit lower="-1e+16" upper="1e+16"/> --><!-- <dynamics damping="0.001" friction="0.001" spring_reference="0" spring_stiffness="0"/> --></joint><joint name="delta/delta_joint_lower_left_0" type="fixed"><child link="delta/delta_link2_left_0" /><parent link="delta/delta_tool_plate" /><origin rpy="0 0 0" xyz="0 0 0.2430566" /><axis xyz="-0.0 1.0 0" /></joint><link name="delta/delta_tool_plate"><origin rpy="0 0 0" xyz="0.03 -0.0095 0.209122181888" /><visual><origin rpy="0 0 0" xyz="-0.03 0.0095 0" /><geometry><cylinder length="0.01" radius="0.03" /></geometry></visual><collision><origin rpy="0 0 0" xyz="-0.03 0.0095 0" /><geometry><cylinder length="0.01" radius="0.03" /></geometry></collision><inertial><origin rpy="0 0 0" xyz="-0.03 0.0095 0" /><mass value="0.0233" /><inertia ixx="5.434492e-05" ixy="0" ixz="0" iyy="5.434492e-05" iyz="0" izz="0.000699" /></inertial></link><!--
   <link name="delta/delta_link2_right_0">
         <pose>0.232188299999 -0.0095 0.073 0 -0.9824450951 0</pose>
         <visual name="link2_right_0_visual">
            <pose frame="">0 0 0.1215283 0 0 0</pose>
            <geometry>
               <cylinder>
                  <length>0.2430566</length>
                  <radius>0.0024</radius>
               </cylinder>
            </geometry>
         </visual>
         <collision name="link2_right_0_collision">
            <pose frame="">0 0 0.1215283 0 0 0</pose>
            <geometry>
               <cylinder>
                  <length>0.2430566</length>
                  <radius>0.0024</radius>
               </cylinder>
            </geometry>
         </collision>
         <inertial>
            <pose frame="">0 0 0.1215283 0 0 0</pose>
            <mass>0.02</mass>
            <inertia>
               <ixx>0.000984502554787</ixx>
               <ixy>0</ixy>
               <ixz>0</ixz>
               <iyy>0.000984502554787</iyy>
               <iyz>0</iyz>
               <izz>4.8e-05</izz>
            </inertia>
         </inertial>
   </link>
   <link name="delta/delta_link2_left_0">
         <pose>0.232188299999 0.0095 0.073 0 -0.9824450951 0</pose>
         <visual name="link2_left_0_visual">
            <pose frame="">0 0 0.1215283 0 0 0</pose>
            <geometry>
               <cylinder>
                  <length>0.2430566</length>
                  <radius>0.0024</radius>
               </cylinder>
            </geometry>
         </visual>
         <collision name="link2_left_0_collision">
            <pose frame="">0 0 0.1215283 0 0 0</pose>
            <geometry>
               <cylinder>
                  <length>0.2430566</length>
                  <radius>0.0024</radius>
               </cylinder>
            </geometry>
         </collision>
         <inertial>
            <pose frame="">0 0 0.1215283 0 0 0</pose>
            <mass>0.02</mass>
            <inertia>
               <ixx>0.000984502554787</ixx>
               <ixy>0</ixy>
               <ixz>0</ixz>
               <iyy>0.000984502554787</iyy>
               <iyz>0</iyz>
               <izz>4.8e-05</izz>
            </inertia>
         </inertial>
   </link>
   <joint name="delta/delta_joint_middle_right_0" type="universal">
         <child>delta/delta_link2_right_0</child>
         <parent>delta/delta_link1_0</parent>
         <axis>
            <xyz>-0.0 1.0 0</xyz>
            <limit>
               <lower>-1e+16</lower>
               <upper>1e+16</upper>
            </limit>
            <dynamics>
               <damping>0.001</damping>
               <friction>0.001</friction>
               <spring_reference>0</spring_reference>
               <spring_stiffness>0</spring_stiffness>
            </dynamics>
            <use_parent_model_frame>1</use_parent_model_frame>
         </axis>
   </joint>
   <joint name="delta/delta_joint_middle_left_0" type="universal">
         <child>delta/delta_link2_left_0</child>
         <parent>delta/delta_link1_0</parent>
         <axis>
            <xyz>-0.0 1.0 0</xyz>
            <limit>
               <lower>-1e+16</lower>
               <upper>1e+16</upper>
            </limit>
            <dynamics>
               <damping>0.001</damping>
               <friction>0.001</friction>
               <spring_reference>0</spring_reference>
               <spring_stiffness>0</spring_stiffness>
            </dynamics>
            <use_parent_model_frame>1</use_parent_model_frame>
         </axis>
   </joint>
   <gazebo>
      <link name="delta/delta_link2_right_0">
         <pose>0.232188299999 -0.0095 0.073 0 -0.9824450951 0</pose>
         <visual name="link2_right_0_visual">
            <pose frame="">0 0 0.1215283 0 0 0</pose>
            <geometry>
               <cylinder>
                  <length>0.2430566</length>
                  <radius>0.0024</radius>
               </cylinder>
            </geometry>
         </visual>
         <collision name="link2_right_0_collision">
            <pose frame="">0 0 0.1215283 0 0 0</pose>
            <geometry>
               <cylinder>
                  <length>0.2430566</length>
                  <radius>0.0024</radius>
               </cylinder>
            </geometry>
         </collision>
         <inertial>
            <pose frame="">0 0 0.1215283 0 0 0</pose>
            <mass>0.02</mass>
            <inertia>
               <ixx>0.000984502554787</ixx>
               <ixy>0</ixy>
               <ixz>0</ixz>
               <iyy>0.000984502554787</iyy>
               <iyz>0</iyz>
               <izz>4.8e-05</izz>
            </inertia>
         </inertial>
      </link>
   </gazebo>
   <gazebo>
      <link name="delta/delta_link2_left_0">
         <pose>0.232188299999 0.0095 0.073 0 -0.9824450951 0</pose>
         <visual name="link2_left_0_visual">
            <pose frame="">0 0 0.1215283 0 0 0</pose>
            <geometry>
               <cylinder>
                  <length>0.2430566</length>
                  <radius>0.0024</radius>
               </cylinder>
            </geometry>
         </visual>
         <collision name="link2_left_0_collision">
            <pose frame="">0 0 0.1215283 0 0 0</pose>
            <geometry>
               <cylinder>
                  <length>0.2430566</length>
                  <radius>0.0024</radius>
               </cylinder>
            </geometry>
         </collision>
         <inertial>
            <pose frame="">0 0 0.1215283 0 0 0</pose>
            <mass>0.02</mass>
            <inertia>
               <ixx>0.000984502554787</ixx>
               <ixy>0</ixy>
               <ixz>0</ixz>
               <iyy>0.000984502554787</iyy>
               <iyz>0</iyz>
               <izz>4.8e-05</izz>
            </inertia>
         </inertial>
      </link>
   </gazebo>
   <gazebo>
      <joint name="delta/delta_joint_middle_right_0" type="universal">
         <child>delta/delta_link2_right_0</child>
         <parent>delta/delta_link1_0</parent>
         <axis>
            <xyz>-0.0 1.0 0</xyz>
            <limit>
               <lower>-1e+16</lower>
               <upper>1e+16</upper>
            </limit>
            <dynamics>
               <damping>0.001</damping>
               <friction>0.001</friction>
               <spring_reference>0</spring_reference>
               <spring_stiffness>0</spring_stiffness>
            </dynamics>
            <use_parent_model_frame>1</use_parent_model_frame>
         </axis>
      </joint>
   </gazebo>
   <gazebo>
      <joint name="delta/delta_joint_middle_left_0" type="universal">
         <child>delta/delta_link2_left_0</child>
         <parent>delta/delta_link1_0</parent>
         <axis>
            <xyz>-0.0 1.0 0</xyz>
            <limit>
               <lower>-1e+16</lower>
               <upper>1e+16</upper>
            </limit>
            <dynamics>
               <damping>0.001</damping>
               <friction>0.001</friction>
               <spring_reference>0</spring_reference>
               <spring_stiffness>0</spring_stiffness>
            </dynamics>
            <use_parent_model_frame>1</use_parent_model_frame>
         </axis>
      </joint>
   </gazebo>
   <gazebo>
      <joint name="delta/delta_joint_lower_right_0" type="universal">
         <child>delta/delta_link2_right_0</child>
         <parent>delta/delta_tool_plate</parent>
         <pose>0 0 0.2430566 0 0 0</pose>
         <axis>
            <xyz>-0.0 1.0 0</xyz>
            <limit>
               <lower>-1e+16</lower>
               <upper>1e+16</upper>
            </limit>
            <dynamics>
               <damping>0.001</damping>
               <friction>0.001</friction>
               <spring_reference>0</spring_reference>
               <spring_stiffness>0</spring_stiffness>
            </dynamics>
            <use_parent_model_frame>1</use_parent_model_frame>
         </axis>
      </joint>
   </gazebo>
   <gazebo>
      <joint name="delta/delta_joint_lower_left_0" type="universal">
         <child>delta/delta_link2_left_0</child>
         <parent>delta/delta_tool_plate</parent>
         <pose>0 0 0.2430566 0 0 0</pose>
         <axis>
            <xyz>-0.0 1.0 0</xyz>
            <limit>
               <lower>-1e+16</lower>
               <upper>1e+16</upper>
            </limit>
            <dynamics>
               <damping>0.001</damping>
               <friction>0.001</friction>
               <spring_reference>0</spring_reference>
               <spring_stiffness>0</spring_stiffness>
            </dynamics>
            <use_parent_model_frame>1</use_parent_model_frame>
         </axis>
      </joint>
   </gazebo> --><link name="delta/delta_link1_1"><visual><origin rpy="0.0 0.0 0.0" xyz="0.07791135 0.0 0.0" /><geometry><box size="0.1558227 0.019 0.01" /></geometry></visual><collision><origin rpy="0.0 0.0 0.0" xyz="0.07791135 0.0 0.0" /><geometry><box size="0.1558227 0.019 0.01" /></geometry></collision><inertial><origin rpy="0.0 0.0 0.0" xyz="0.07791135 0.0 0.0" /><mass value="0.041" /><inertia ixx="1.5744533e-05" ixy="0.0" ixz="0.0" iyy="0.000832674519617" iyz="0.0" izz="0.000841588452617" /></inertial></link><joint name="delta/delta_joint_upper_1" type="continuous"><parent link="delta/delta_base_link" /><child link="delta/delta_link1_1" /><origin rpy="0.0 0.0 2.09439510239" xyz="-0.0371828 0.0644024987677 0.0" /><axis xyz="0.0 1.0 0.0" /><limit effort="10.0" lower="-1.5707963268" upper="1.5707963268" velocity="5.0" /><safety_controller k_velocity="0.5" /><dynamics damping="0.001" friction="0.001" /></joint><!-- <gazebo>
      <link name="delta/delta_link2_right_1">
         <pose>-0.107866908664 0.205830966261 0.073 0 -0.9824450951 2.09439510239</pose>
         <visual name="link2_right_1_visual">
            <pose frame="">0 0 0.1215283 0 0 0</pose>
            <geometry>
               <cylinder>
                  <length>0.2430566</length>
                  <radius>0.0024</radius>
               </cylinder>
            </geometry>
         </visual>
         <collision name="link2_right_1_collision">
            <pose frame="">0 0 0.1215283 0 0 0</pose>
            <geometry>
               <cylinder>
                  <length>0.2430566</length>
                  <radius>0.0024</radius>
               </cylinder>
            </geometry>
         </collision>
         <inertial>
            <pose frame="">0 0 0.1215283 0 0 0</pose>
            <mass>0.02</mass>
            <inertia>
               <ixx>0.000984502554787</ixx>
               <ixy>0</ixy>
               <ixz>0</ixz>
               <iyy>0.000984502554787</iyy>
               <iyz>0</iyz>
               <izz>4.8e-05</izz>
            </inertia>
         </inertial>
      </link>
   </gazebo>
   <gazebo>
      <link name="delta/delta_link2_left_1">
         <pose>-0.124321391336 0.196330966261 0.073 0 -0.9824450951 2.09439510239</pose>
         <visual name="link2_left_1_visual">
            <pose frame="">0 0 0.1215283 0 0 0</pose>
            <geometry>
               <cylinder>
                  <length>0.2430566</length>
                  <radius>0.0024</radius>
               </cylinder>
            </geometry>
         </visual>
         <collision name="link2_left_1_collision">
            <pose frame="">0 0 0.1215283 0 0 0</pose>
            <geometry>
               <cylinder>
                  <length>0.2430566</length>
                  <radius>0.0024</radius>
               </cylinder>
            </geometry>
         </collision>
         <inertial>
            <pose frame="">0 0 0.1215283 0 0 0</pose>
            <mass>0.02</mass>
            <inertia>
               <ixx>0.000984502554787</ixx>
               <ixy>0</ixy>
               <ixz>0</ixz>
               <iyy>0.000984502554787</iyy>
               <iyz>0</iyz>
               <izz>4.8e-05</izz>
            </inertia>
         </inertial>
      </link>
   </gazebo>
   <gazebo>
      <joint name="delta/delta_joint_middle_right_1" type="universal">
         <child>delta/delta_link2_right_1</child>
         <parent>delta/delta_link1_1</parent>
         <axis>
            <xyz>-0.866025403784 -0.5 0</xyz>
            <limit>
               <lower>-1e+16</lower>
               <upper>1e+16</upper>
            </limit>
            <dynamics>
               <damping>0.001</damping>
               <friction>0.001</friction>
               <spring_reference>0</spring_reference>
               <spring_stiffness>0</spring_stiffness>
            </dynamics>
            <use_parent_model_frame>1</use_parent_model_frame>
         </axis>
      </joint>
   </gazebo>
   <gazebo>
      <joint name="delta/delta_joint_middle_left_1" type="universal">
         <child>delta/delta_link2_left_1</child>
         <parent>delta/delta_link1_1</parent>
         <axis>
            <xyz>-0.866025403784 -0.5 0</xyz>
            <limit>
               <lower>-1e+16</lower>
               <upper>1e+16</upper>
            </limit>
            <dynamics>
               <damping>0.001</damping>
               <friction>0.001</friction>
               <spring_reference>0</spring_reference>
               <spring_stiffness>0</spring_stiffness>
            </dynamics>
            <use_parent_model_frame>1</use_parent_model_frame>
         </axis>
      </joint>
   </gazebo>
   <gazebo>
      <joint name="delta/delta_joint_lower_right_1" type="universal">
         <child>delta/delta_link2_right_1</child>
         <parent>delta/delta_tool_plate</parent>
         <pose>0 0 0.2430566 0 0 0</pose>
         <axis>
            <xyz>-0.866025403784 -0.5 0</xyz>
            <limit>
               <lower>-1e+16</lower>
               <upper>1e+16</upper>
            </limit>
            <dynamics>
               <damping>0.001</damping>
               <friction>0.001</friction>
               <spring_reference>0</spring_reference>
               <spring_stiffness>0</spring_stiffness>
            </dynamics>
            <use_parent_model_frame>1</use_parent_model_frame>
         </axis>
      </joint>
   </gazebo>
   <gazebo>
      <joint name="delta/delta_joint_lower_left_1" type="universal">
         <child>delta/delta_link2_left_1</child>
         <parent>delta/delta_tool_plate</parent>
         <pose>0 0 0.2430566 0 0 0</pose>
         <axis>
            <xyz>-0.866025403784 -0.5 0</xyz>
            <limit>
               <lower>-1e+16</lower>
               <upper>1e+16</upper>
            </limit>
            <dynamics>
               <damping>0.001</damping>
               <friction>0.001</friction>
               <spring_reference>0</spring_reference>
               <spring_stiffness>0</spring_stiffness>
            </dynamics>
            <use_parent_model_frame>1</use_parent_model_frame>
         </axis>
      </joint>
   </gazebo> --><link name="delta/delta_link1_2"><visual><origin rpy="0.0 0.0 0.0" xyz="0.07791135 0.0 0.0" /><geometry><box size="0.1558227 0.019 0.01" /></geometry></visual><collision><origin rpy="0.0 0.0 0.0" xyz="0.07791135 0.0 0.0" /><geometry><box size="0.1558227 0.019 0.01" /></geometry></collision><inertial><origin rpy="0.0 0.0 0.0" xyz="0.07791135 0.0 0.0" /><mass value="0.041" /><inertia ixx="1.5744533e-05" ixy="0.0" ixz="0.0" iyy="0.000832674519617" iyz="0.0" izz="0.000841588452617" /></inertial></link><joint name="delta/delta_joint_upper_2" type="continuous"><parent link="delta/delta_base_link" /><child link="delta/delta_link1_2" /><origin rpy="0.0 0.0 4.18879020479" xyz="-0.0371828 -0.0644024987677 0.0" /><axis xyz="0.0 1.0 0.0" /><limit effort="10.0" lower="-1.5707963268" upper="1.5707963268" velocity="5.0" /><safety_controller k_velocity="0.5" /><dynamics damping="0.001" friction="0.001" /></joint><!-- <gazebo>
      <link name="delta/delta_link2_right_2">
         <pose>-0.124321391336 -0.196330966261 0.073 0 -0.9824450951 4.18879020479</pose>
         <visual name="link2_right_2_visual">
            <pose frame="">0 0 0.1215283 0 0 0</pose>
            <geometry>
               <cylinder>
                  <length>0.2430566</length>
                  <radius>0.0024</radius>
               </cylinder>
            </geometry>
         </visual>
         <collision name="link2_right_2_collision">
            <pose frame="">0 0 0.1215283 0 0 0</pose>
            <geometry>
               <cylinder>
                  <length>0.2430566</length>
                  <radius>0.0024</radius>
               </cylinder>
            </geometry>
         </collision>
         <inertial>
            <pose frame="">0 0 0.1215283 0 0 0</pose>
            <mass>0.02</mass>
            <inertia>
               <ixx>0.000984502554787</ixx>
               <ixy>0</ixy>
               <ixz>0</ixz>
               <iyy>0.000984502554787</iyy>
               <iyz>0</iyz>
               <izz>4.8e-05</izz>
            </inertia>
         </inertial>
      </link>
   </gazebo>
   <gazebo>
      <link name="delta/delta_link2_left_2">
         <pose>-0.107866908664 -0.205830966261 0.073 0 -0.9824450951 4.18879020479</pose>
         <visual name="link2_left_2_visual">
            <pose frame="">0 0 0.1215283 0 0 0</pose>
            <geometry>
               <cylinder>
                  <length>0.2430566</length>
                  <radius>0.0024</radius>
               </cylinder>
            </geometry>
         </visual>
         <collision name="link2_left_2_collision">
            <pose frame="">0 0 0.1215283 0 0 0</pose>
            <geometry>
               <cylinder>
                  <length>0.2430566</length>
                  <radius>0.0024</radius>
               </cylinder>
            </geometry>
         </collision>
         <inertial>
            <pose frame="">0 0 0.1215283 0 0 0</pose>
            <mass>0.02</mass>
            <inertia>
               <ixx>0.000984502554787</ixx>
               <ixy>0</ixy>
               <ixz>0</ixz>
               <iyy>0.000984502554787</iyy>
               <iyz>0</iyz>
               <izz>4.8e-05</izz>
            </inertia>
         </inertial>
      </link>
   </gazebo>
   <gazebo>
      <joint name="delta/delta_joint_middle_right_2" type="universal">
         <child>delta/delta_link2_right_2</child>
         <parent>delta/delta_link1_2</parent>
         <axis>
            <xyz>0.866025403785 -0.5 0</xyz>
            <limit>
               <lower>-1e+16</lower>
               <upper>1e+16</upper>
            </limit>
            <dynamics>
               <damping>0.001</damping>
               <friction>0.001</friction>
               <spring_reference>0</spring_reference>
               <spring_stiffness>0</spring_stiffness>
            </dynamics>
            <use_parent_model_frame>1</use_parent_model_frame>
         </axis>
      </joint>
   </gazebo>
   <gazebo>
      <joint name="delta/delta_joint_middle_left_2" type="universal">
         <child>delta/delta_link2_left_2</child>
         <parent>delta/delta_link1_2</parent>
         <axis>
            <xyz>0.866025403785 -0.5 0</xyz>
            <limit>
               <lower>-1e+16</lower>
               <upper>1e+16</upper>
            </limit>
            <dynamics>
               <damping>0.001</damping>
               <friction>0.001</friction>
               <spring_reference>0</spring_reference>
               <spring_stiffness>0</spring_stiffness>
            </dynamics>
            <use_parent_model_frame>1</use_parent_model_frame>
         </axis>
      </joint>
   </gazebo>
   <gazebo>
      <joint name="delta/delta_joint_lower_right_2" type="universal">
         <child>delta/delta_link2_right_2</child>
         <parent>delta/delta_tool_plate</parent>
         <pose>0 0 0.2430566 0 0 0</pose>
         <axis>
            <xyz>0.866025403785 -0.5 0</xyz>
            <limit>
               <lower>-1e+16</lower>
               <upper>1e+16</upper>
            </limit>
            <dynamics>
               <damping>0.001</damping>
               <friction>0.001</friction>
               <spring_reference>0</spring_reference>
               <spring_stiffness>0</spring_stiffness>
            </dynamics>
            <use_parent_model_frame>1</use_parent_model_frame>
         </axis>
      </joint>
   </gazebo>
   <gazebo>
      <joint name="delta/delta_joint_lower_left_2" type="universal">
         <child>delta/delta_link2_left_2</child>
         <parent>delta/delta_tool_plate</parent>
         <pose>0 0 0.2430566 0 0 0</pose>
         <axis>
            <xyz>0.866025403785 -0.5 0</xyz>
            <limit>
               <lower>-1e+16</lower>
               <upper>1e+16</upper>
            </limit>
            <dynamics>
               <damping>0.001</damping>
               <friction>0.001</friction>
               <spring_reference>0</spring_reference>
               <spring_stiffness>0</spring_stiffness>
            </dynamics>
            <use_parent_model_frame>1</use_parent_model_frame>
         </axis>
      </joint>
   </gazebo>
   <gazebo>
      <link name="delta/delta_tool_plate">
         <pose>0.03 -0.0095 0.209122181888 0 0 0</pose>
         <visual name="tool_plate_visual">
            <pose frame="">-0.03 0.0095 0 0 0 0</pose>
            <geometry>
               <cylinder>
                  <length>0.01</length>
                  <radius>0.03</radius>
               </cylinder>
            </geometry>
         </visual>
         <collision name="tool_plate_collision">
            <pose frame="">-0.03 0.0095 0 0 0 0</pose>
            <geometry>
               <cylinder>
                  <length>0.01</length>
                  <radius>0.03</radius>
               </cylinder>
            </geometry>
         </collision>
         <inertial>
            <pose frame="">-0.03 0.0095 0 0 0 0</pose>
            <mass>0.0233</mass>
            <inertia>
               <ixx>5.434492e-05</ixx>
               <ixy>0</ixy>
               <ixz>0</ixz>
               <iyy>5.434492e-05</iyy>
               <iyz>0</iyz>
               <izz>0.000699</izz>
            </inertia>
         </inertial>
      </link>
   </gazebo>  --></robot>